2025-05-08 14:22:26,827 - app - INFO - [app.py:17] - Création de l'application Flask
2025-05-08 14:23:01,879 - app - INFO - [app.py:17] - Création de l'application Flask
2025-05-08 14:23:02,493 - app - INFO - [app.py:193] - Application Flask configurée avec succès
2025-05-08 14:23:02,493 - app - INFO - [app.py:204] - Démarrage de l'application sur 0.0.0.0:5000 (debug: False)
2025-05-08 14:36:25,556 - app - INFO - [app.py:159] - Téléchargement du rapport: report_vuln_scan_20250508_143321.html
2025-05-08 14:48:03,126 - app - INFO - [app.py:159] - Téléchargement du rapport: report_vuln_scan_20250508_144719.html
2025-05-08 14:56:51,086 - app - INFO - [app.py:17] - Création de l'application Flask
2025-05-08 14:56:51,607 - app - INFO - [app.py:193] - Application Flask configurée avec succès
2025-05-08 14:56:51,608 - app - INFO - [app.py:204] - Démarrage de l'application sur 0.0.0.0:5000 (debug: False)
2025-05-08 14:58:18,357 - app - INFO - [app.py:17] - Création de l'application Flask
2025-05-08 14:58:18,859 - app - INFO - [app.py:193] - Application Flask configurée avec succès
2025-05-08 14:58:18,859 - app - INFO - [app.py:204] - Démarrage de l'application sur 0.0.0.0:5000 (debug: False)
2025-05-08 15:15:35,558 - app - INFO - [app.py:135] - Accès à la page des rapports
2025-05-08 15:15:53,824 - app - INFO - [app.py:159] - Téléchargement du rapport: report_vuln_scan_20250508_151512.html
2025-05-08 15:23:02,959 - app - INFO - [app.py:86] - Accès à la page d'exploitation
2025-05-08 15:23:02,959 - app - INFO - [app.py:106] - Préparation de l'exploitation de http-vuln-cve2014-3704 sur 192.168.217.139:443
2025-05-08 15:23:49,917 - app - INFO - [app.py:86] - Accès à la page d'exploitation
2025-05-08 15:23:49,918 - app - INFO - [app.py:106] - Préparation de l'exploitation de http-slowloris-check sur 192.168.217.139:80
2025-05-08 15:23:58,259 - app - INFO - [app.py:86] - Accès à la page d'exploitation
2025-05-08 15:23:58,260 - app - INFO - [app.py:106] - Préparation de l'exploitation de http-vuln-cve2014-3704 sur 192.168.217.139:443
2025-05-08 15:24:01,192 - app - INFO - [app.py:86] - Accès à la page d'exploitation
2025-05-08 15:24:01,193 - app - INFO - [app.py:106] - Préparation de l'exploitation de ssl-ccs-injection sur 192.168.217.139:443
2025-05-08 15:24:04,211 - app - INFO - [app.py:86] - Accès à la page d'exploitation
2025-05-08 15:24:04,211 - app - INFO - [app.py:106] - Préparation de l'exploitation de http-slowloris-check sur 192.168.217.139:80
2025-05-08 15:24:16,871 - app - INFO - [app.py:159] - Téléchargement du rapport: report_vuln_scan_20250508_152142.html
2025-05-08 15:24:35,433 - app - INFO - [app.py:86] - Accès à la page d'exploitation
2025-05-08 15:24:35,433 - app - INFO - [app.py:106] - Préparation de l'exploitation de ssl-ccs-injection sur 192.168.217.139:443
2025-05-08 17:00:37,852 - app - INFO - [app.py:17] - Création de l'application Flask
2025-05-08 17:00:38,559 - app - INFO - [app.py:193] - Application Flask configurée avec succès
2025-05-08 17:00:38,559 - app - INFO - [app.py:204] - Démarrage de l'application sur 0.0.0.0:5000 (debug: False)
2025-05-08 17:07:54,870 - app - INFO - [app.py:86] - Accès à la page d'exploitation
2025-05-08 17:07:54,870 - app - INFO - [app.py:106] - Préparation de l'exploitation de http-slowloris-check sur 192.168.217.139:80
2025-05-08 17:08:04,530 - app - INFO - [app.py:86] - Accès à la page d'exploitation
2025-05-08 17:08:04,530 - app - INFO - [app.py:106] - Préparation de l'exploitation de ssl-ccs-injection sur 192.168.217.139:443
2025-05-08 17:08:13,632 - app - INFO - [app.py:86] - Accès à la page d'exploitation
2025-05-08 17:08:13,632 - app - INFO - [app.py:106] - Préparation de l'exploitation de http-vuln-cve2014-3704 sur 192.168.217.139:443
2025-05-08 17:08:37,174 - app - INFO - [app.py:86] - Accès à la page d'exploitation
2025-05-08 17:08:37,174 - app - INFO - [app.py:106] - Préparation de l'exploitation de http-slowloris-check sur 192.168.217.139:80
2025-05-08 17:08:43,043 - app - INFO - [app.py:86] - Accès à la page d'exploitation
2025-05-08 17:08:43,043 - app - INFO - [app.py:106] - Préparation de l'exploitation de ssl-ccs-injection sur 192.168.217.139:443
2025-05-08 17:11:13,285 - app - INFO - [app.py:86] - Accès à la page d'exploitation
2025-05-08 17:11:13,286 - app - INFO - [app.py:106] - Préparation de l'exploitation de ssl-ccs-injection sur 192.168.217.139:443
2025-05-08 17:19:22,380 - app - INFO - [app.py:86] - Accès à la page d'exploitation
2025-05-08 17:19:22,381 - app - INFO - [app.py:106] - Préparation de l'exploitation de http-vuln-cve2014-3704 sur 192.168.217.139:443
2025-05-08 17:29:22,279 - app - INFO - [app.py:17] - Création de l'application Flask
2025-05-08 17:32:36,104 - app - INFO - [app.py:17] - Création de l'application Flask
2025-05-08 17:32:36,621 - app - INFO - [app.py:193] - Application Flask configurée avec succès
2025-05-08 17:32:36,622 - app - INFO - [app.py:204] - Démarrage de l'application sur 0.0.0.0:5000 (debug: False)
2025-05-08 17:38:43,710 - app - INFO - [app.py:86] - Accès à la page d'exploitation
2025-05-08 17:38:43,711 - app - INFO - [app.py:106] - Préparation de l'exploitation de ssl-ccs-injection sur 192.168.217.139:443
2025-05-08 17:38:43,742 - app - WARNING - [app.py:185] - Page non trouvée: /api/network/local-ip
2025-05-08 17:38:43,753 - app - ERROR - [app.py:875] - Exception on /api/network/local-ip [GET]
Traceback (most recent call last):
  File "/usr/local/lib/python3.11/dist-packages/flask/app.py", line 917, in full_dispatch_request
    rv = self.dispatch_request()
         ^^^^^^^^^^^^^^^^^^^^^^^
  File "/usr/local/lib/python3.11/dist-packages/flask/app.py", line 891, in dispatch_request
    self.raise_routing_exception(req)
  File "/usr/local/lib/python3.11/dist-packages/flask/app.py", line 500, in raise_routing_exception
    raise request.routing_exception  # type: ignore[misc]
    ^^^^^^^^^^^^^^^^^^^^^^^^^^^^^^^
  File "/usr/local/lib/python3.11/dist-packages/flask/ctx.py", line 362, in match_request
    result = self.url_adapter.match(return_rule=True)  # type: ignore
             ^^^^^^^^^^^^^^^^^^^^^^^^^^^^^^^^^^^^^^^^
  File "/usr/local/lib/python3.11/dist-packages/werkzeug/routing/map.py", line 629, in match
    raise NotFound() from None
werkzeug.exceptions.NotFound: 404 Not Found: The requested URL was not found on the server. If you entered the URL manually please check your spelling and try again.

During handling of the above exception, another exception occurred:

Traceback (most recent call last):
  File "/usr/local/lib/python3.11/dist-packages/flask/app.py", line 1511, in wsgi_app
    response = self.full_dispatch_request()
               ^^^^^^^^^^^^^^^^^^^^^^^^^^^^
  File "/usr/local/lib/python3.11/dist-packages/flask/app.py", line 919, in full_dispatch_request
    rv = self.handle_user_exception(e)
         ^^^^^^^^^^^^^^^^^^^^^^^^^^^^^
  File "/usr/local/lib/python3.11/dist-packages/flask/app.py", line 802, in handle_user_exception
    return self.handle_http_exception(e)
           ^^^^^^^^^^^^^^^^^^^^^^^^^^^^^
  File "/usr/local/lib/python3.11/dist-packages/flask/app.py", line 777, in handle_http_exception
    return self.ensure_sync(handler)(e)  # type: ignore[no-any-return]
           ^^^^^^^^^^^^^^^^^^^^^^^^^^^^
  File "/home/oebn/toolbox/app.py", line 186, in page_not_found
    return render_template('404.html'), 404
           ^^^^^^^^^^^^^^^^^^^^^^^^^^^
  File "/usr/local/lib/python3.11/dist-packages/flask/templating.py", line 149, in render_template
    template = app.jinja_env.get_or_select_template(template_name_or_list)
               ^^^^^^^^^^^^^^^^^^^^^^^^^^^^^^^^^^^^^^^^^^^^^^^^^^^^^^^^^^^
  File "/usr/local/lib/python3.11/dist-packages/jinja2/environment.py", line 1087, in get_or_select_template
    return self.get_template(template_name_or_list, parent, globals)
           ^^^^^^^^^^^^^^^^^^^^^^^^^^^^^^^^^^^^^^^^^^^^^^^^^^^^^^^^^
  File "/usr/local/lib/python3.11/dist-packages/jinja2/environment.py", line 1016, in get_template
    return self._load_template(name, globals)
           ^^^^^^^^^^^^^^^^^^^^^^^^^^^^^^^^^^
  File "/usr/local/lib/python3.11/dist-packages/jinja2/environment.py", line 975, in _load_template
    template = self.loader.load(self, name, self.make_globals(globals))
               ^^^^^^^^^^^^^^^^^^^^^^^^^^^^^^^^^^^^^^^^^^^^^^^^^^^^^^^^
  File "/usr/local/lib/python3.11/dist-packages/jinja2/loaders.py", line 126, in load
    source, filename, uptodate = self.get_source(environment, name)
                                 ^^^^^^^^^^^^^^^^^^^^^^^^^^^^^^^^^^
  File "/usr/local/lib/python3.11/dist-packages/flask/templating.py", line 65, in get_source
    return self._get_source_fast(environment, template)
           ^^^^^^^^^^^^^^^^^^^^^^^^^^^^^^^^^^^^^^^^^^^^
  File "/usr/local/lib/python3.11/dist-packages/flask/templating.py", line 99, in _get_source_fast
    raise TemplateNotFound(template)
jinja2.exceptions.TemplateNotFound: 404.html
2025-05-08 17:38:43,783 - app - ERROR - [app.py:190] - Erreur serveur: 500 Internal Server Error: The server encountered an internal error and was unable to complete your request. Either the server is overloaded or there is an error in the application.
2025-05-08 17:43:14,548 - app - INFO - [app.py:159] - Téléchargement du rapport: report_vuln_scan_20250508_173828.html
2025-05-08 17:43:42,420 - app - INFO - [app.py:86] - Accès à la page d'exploitation
2025-05-08 17:43:42,420 - app - INFO - [app.py:106] - Préparation de l'exploitation de http-slowloris-check sur 192.168.217.139:80
2025-05-08 17:43:42,455 - app - WARNING - [app.py:185] - Page non trouvée: /api/network/local-ip
2025-05-08 17:43:42,456 - app - ERROR - [app.py:875] - Exception on /api/network/local-ip [GET]
Traceback (most recent call last):
  File "/usr/local/lib/python3.11/dist-packages/flask/app.py", line 917, in full_dispatch_request
    rv = self.dispatch_request()
         ^^^^^^^^^^^^^^^^^^^^^^^
  File "/usr/local/lib/python3.11/dist-packages/flask/app.py", line 891, in dispatch_request
    self.raise_routing_exception(req)
  File "/usr/local/lib/python3.11/dist-packages/flask/app.py", line 500, in raise_routing_exception
    raise request.routing_exception  # type: ignore[misc]
    ^^^^^^^^^^^^^^^^^^^^^^^^^^^^^^^
  File "/usr/local/lib/python3.11/dist-packages/flask/ctx.py", line 362, in match_request
    result = self.url_adapter.match(return_rule=True)  # type: ignore
             ^^^^^^^^^^^^^^^^^^^^^^^^^^^^^^^^^^^^^^^^
  File "/usr/local/lib/python3.11/dist-packages/werkzeug/routing/map.py", line 629, in match
    raise NotFound() from None
werkzeug.exceptions.NotFound: 404 Not Found: The requested URL was not found on the server. If you entered the URL manually please check your spelling and try again.

During handling of the above exception, another exception occurred:

Traceback (most recent call last):
  File "/usr/local/lib/python3.11/dist-packages/flask/app.py", line 1511, in wsgi_app
    response = self.full_dispatch_request()
               ^^^^^^^^^^^^^^^^^^^^^^^^^^^^
  File "/usr/local/lib/python3.11/dist-packages/flask/app.py", line 919, in full_dispatch_request
    rv = self.handle_user_exception(e)
         ^^^^^^^^^^^^^^^^^^^^^^^^^^^^^
  File "/usr/local/lib/python3.11/dist-packages/flask/app.py", line 802, in handle_user_exception
    return self.handle_http_exception(e)
           ^^^^^^^^^^^^^^^^^^^^^^^^^^^^^
  File "/usr/local/lib/python3.11/dist-packages/flask/app.py", line 777, in handle_http_exception
    return self.ensure_sync(handler)(e)  # type: ignore[no-any-return]
           ^^^^^^^^^^^^^^^^^^^^^^^^^^^^
  File "/home/oebn/toolbox/app.py", line 186, in page_not_found
    return render_template('404.html'), 404
           ^^^^^^^^^^^^^^^^^^^^^^^^^^^
  File "/usr/local/lib/python3.11/dist-packages/flask/templating.py", line 149, in render_template
    template = app.jinja_env.get_or_select_template(template_name_or_list)
               ^^^^^^^^^^^^^^^^^^^^^^^^^^^^^^^^^^^^^^^^^^^^^^^^^^^^^^^^^^^
  File "/usr/local/lib/python3.11/dist-packages/jinja2/environment.py", line 1087, in get_or_select_template
    return self.get_template(template_name_or_list, parent, globals)
           ^^^^^^^^^^^^^^^^^^^^^^^^^^^^^^^^^^^^^^^^^^^^^^^^^^^^^^^^^
  File "/usr/local/lib/python3.11/dist-packages/jinja2/environment.py", line 1016, in get_template
    return self._load_template(name, globals)
           ^^^^^^^^^^^^^^^^^^^^^^^^^^^^^^^^^^
  File "/usr/local/lib/python3.11/dist-packages/jinja2/environment.py", line 975, in _load_template
    template = self.loader.load(self, name, self.make_globals(globals))
               ^^^^^^^^^^^^^^^^^^^^^^^^^^^^^^^^^^^^^^^^^^^^^^^^^^^^^^^^
  File "/usr/local/lib/python3.11/dist-packages/jinja2/loaders.py", line 126, in load
    source, filename, uptodate = self.get_source(environment, name)
                                 ^^^^^^^^^^^^^^^^^^^^^^^^^^^^^^^^^^
  File "/usr/local/lib/python3.11/dist-packages/flask/templating.py", line 65, in get_source
    return self._get_source_fast(environment, template)
           ^^^^^^^^^^^^^^^^^^^^^^^^^^^^^^^^^^^^^^^^^^^^
  File "/usr/local/lib/python3.11/dist-packages/flask/templating.py", line 99, in _get_source_fast
    raise TemplateNotFound(template)
jinja2.exceptions.TemplateNotFound: 404.html
2025-05-08 17:43:42,459 - app - ERROR - [app.py:190] - Erreur serveur: 500 Internal Server Error: The server encountered an internal error and was unable to complete your request. Either the server is overloaded or there is an error in the application.
2025-05-08 17:43:48,153 - app - INFO - [app.py:86] - Accès à la page d'exploitation
2025-05-08 17:43:48,153 - app - INFO - [app.py:106] - Préparation de l'exploitation de ssl-poodle sur 192.168.217.139:443
2025-05-08 17:43:48,185 - app - WARNING - [app.py:185] - Page non trouvée: /api/network/local-ip
2025-05-08 17:43:48,185 - app - ERROR - [app.py:875] - Exception on /api/network/local-ip [GET]
Traceback (most recent call last):
  File "/usr/local/lib/python3.11/dist-packages/flask/app.py", line 917, in full_dispatch_request
    rv = self.dispatch_request()
         ^^^^^^^^^^^^^^^^^^^^^^^
  File "/usr/local/lib/python3.11/dist-packages/flask/app.py", line 891, in dispatch_request
    self.raise_routing_exception(req)
  File "/usr/local/lib/python3.11/dist-packages/flask/app.py", line 500, in raise_routing_exception
    raise request.routing_exception  # type: ignore[misc]
    ^^^^^^^^^^^^^^^^^^^^^^^^^^^^^^^
  File "/usr/local/lib/python3.11/dist-packages/flask/ctx.py", line 362, in match_request
    result = self.url_adapter.match(return_rule=True)  # type: ignore
             ^^^^^^^^^^^^^^^^^^^^^^^^^^^^^^^^^^^^^^^^
  File "/usr/local/lib/python3.11/dist-packages/werkzeug/routing/map.py", line 629, in match
    raise NotFound() from None
werkzeug.exceptions.NotFound: 404 Not Found: The requested URL was not found on the server. If you entered the URL manually please check your spelling and try again.

During handling of the above exception, another exception occurred:

Traceback (most recent call last):
  File "/usr/local/lib/python3.11/dist-packages/flask/app.py", line 1511, in wsgi_app
    response = self.full_dispatch_request()
               ^^^^^^^^^^^^^^^^^^^^^^^^^^^^
  File "/usr/local/lib/python3.11/dist-packages/flask/app.py", line 919, in full_dispatch_request
    rv = self.handle_user_exception(e)
         ^^^^^^^^^^^^^^^^^^^^^^^^^^^^^
  File "/usr/local/lib/python3.11/dist-packages/flask/app.py", line 802, in handle_user_exception
    return self.handle_http_exception(e)
           ^^^^^^^^^^^^^^^^^^^^^^^^^^^^^
  File "/usr/local/lib/python3.11/dist-packages/flask/app.py", line 777, in handle_http_exception
    return self.ensure_sync(handler)(e)  # type: ignore[no-any-return]
           ^^^^^^^^^^^^^^^^^^^^^^^^^^^^
  File "/home/oebn/toolbox/app.py", line 186, in page_not_found
    return render_template('404.html'), 404
           ^^^^^^^^^^^^^^^^^^^^^^^^^^^
  File "/usr/local/lib/python3.11/dist-packages/flask/templating.py", line 149, in render_template
    template = app.jinja_env.get_or_select_template(template_name_or_list)
               ^^^^^^^^^^^^^^^^^^^^^^^^^^^^^^^^^^^^^^^^^^^^^^^^^^^^^^^^^^^
  File "/usr/local/lib/python3.11/dist-packages/jinja2/environment.py", line 1087, in get_or_select_template
    return self.get_template(template_name_or_list, parent, globals)
           ^^^^^^^^^^^^^^^^^^^^^^^^^^^^^^^^^^^^^^^^^^^^^^^^^^^^^^^^^
  File "/usr/local/lib/python3.11/dist-packages/jinja2/environment.py", line 1016, in get_template
    return self._load_template(name, globals)
           ^^^^^^^^^^^^^^^^^^^^^^^^^^^^^^^^^^
  File "/usr/local/lib/python3.11/dist-packages/jinja2/environment.py", line 975, in _load_template
    template = self.loader.load(self, name, self.make_globals(globals))
               ^^^^^^^^^^^^^^^^^^^^^^^^^^^^^^^^^^^^^^^^^^^^^^^^^^^^^^^^
  File "/usr/local/lib/python3.11/dist-packages/jinja2/loaders.py", line 126, in load
    source, filename, uptodate = self.get_source(environment, name)
                                 ^^^^^^^^^^^^^^^^^^^^^^^^^^^^^^^^^^
  File "/usr/local/lib/python3.11/dist-packages/flask/templating.py", line 65, in get_source
    return self._get_source_fast(environment, template)
           ^^^^^^^^^^^^^^^^^^^^^^^^^^^^^^^^^^^^^^^^^^^^
  File "/usr/local/lib/python3.11/dist-packages/flask/templating.py", line 99, in _get_source_fast
    raise TemplateNotFound(template)
jinja2.exceptions.TemplateNotFound: 404.html
2025-05-08 17:43:48,199 - app - ERROR - [app.py:190] - Erreur serveur: 500 Internal Server Error: The server encountered an internal error and was unable to complete your request. Either the server is overloaded or there is an error in the application.
2025-05-08 17:43:51,472 - app - INFO - [app.py:86] - Accès à la page d'exploitation
2025-05-08 17:43:51,472 - app - INFO - [app.py:106] - Préparation de l'exploitation de ssl-dh-params sur 192.168.217.139:443
2025-05-08 17:43:51,501 - app - WARNING - [app.py:185] - Page non trouvée: /api/network/local-ip
2025-05-08 17:43:51,505 - app - ERROR - [app.py:875] - Exception on /api/network/local-ip [GET]
Traceback (most recent call last):
  File "/usr/local/lib/python3.11/dist-packages/flask/app.py", line 917, in full_dispatch_request
    rv = self.dispatch_request()
         ^^^^^^^^^^^^^^^^^^^^^^^
  File "/usr/local/lib/python3.11/dist-packages/flask/app.py", line 891, in dispatch_request
    self.raise_routing_exception(req)
  File "/usr/local/lib/python3.11/dist-packages/flask/app.py", line 500, in raise_routing_exception
    raise request.routing_exception  # type: ignore[misc]
    ^^^^^^^^^^^^^^^^^^^^^^^^^^^^^^^
  File "/usr/local/lib/python3.11/dist-packages/flask/ctx.py", line 362, in match_request
    result = self.url_adapter.match(return_rule=True)  # type: ignore
             ^^^^^^^^^^^^^^^^^^^^^^^^^^^^^^^^^^^^^^^^
  File "/usr/local/lib/python3.11/dist-packages/werkzeug/routing/map.py", line 629, in match
    raise NotFound() from None
werkzeug.exceptions.NotFound: 404 Not Found: The requested URL was not found on the server. If you entered the URL manually please check your spelling and try again.

During handling of the above exception, another exception occurred:

Traceback (most recent call last):
  File "/usr/local/lib/python3.11/dist-packages/flask/app.py", line 1511, in wsgi_app
    response = self.full_dispatch_request()
               ^^^^^^^^^^^^^^^^^^^^^^^^^^^^
  File "/usr/local/lib/python3.11/dist-packages/flask/app.py", line 919, in full_dispatch_request
    rv = self.handle_user_exception(e)
         ^^^^^^^^^^^^^^^^^^^^^^^^^^^^^
  File "/usr/local/lib/python3.11/dist-packages/flask/app.py", line 802, in handle_user_exception
    return self.handle_http_exception(e)
           ^^^^^^^^^^^^^^^^^^^^^^^^^^^^^
  File "/usr/local/lib/python3.11/dist-packages/flask/app.py", line 777, in handle_http_exception
    return self.ensure_sync(handler)(e)  # type: ignore[no-any-return]
           ^^^^^^^^^^^^^^^^^^^^^^^^^^^^
  File "/home/oebn/toolbox/app.py", line 186, in page_not_found
    return render_template('404.html'), 404
           ^^^^^^^^^^^^^^^^^^^^^^^^^^^
  File "/usr/local/lib/python3.11/dist-packages/flask/templating.py", line 149, in render_template
    template = app.jinja_env.get_or_select_template(template_name_or_list)
               ^^^^^^^^^^^^^^^^^^^^^^^^^^^^^^^^^^^^^^^^^^^^^^^^^^^^^^^^^^^
  File "/usr/local/lib/python3.11/dist-packages/jinja2/environment.py", line 1087, in get_or_select_template
    return self.get_template(template_name_or_list, parent, globals)
           ^^^^^^^^^^^^^^^^^^^^^^^^^^^^^^^^^^^^^^^^^^^^^^^^^^^^^^^^^
  File "/usr/local/lib/python3.11/dist-packages/jinja2/environment.py", line 1016, in get_template
    return self._load_template(name, globals)
           ^^^^^^^^^^^^^^^^^^^^^^^^^^^^^^^^^^
  File "/usr/local/lib/python3.11/dist-packages/jinja2/environment.py", line 975, in _load_template
    template = self.loader.load(self, name, self.make_globals(globals))
               ^^^^^^^^^^^^^^^^^^^^^^^^^^^^^^^^^^^^^^^^^^^^^^^^^^^^^^^^
  File "/usr/local/lib/python3.11/dist-packages/jinja2/loaders.py", line 126, in load
    source, filename, uptodate = self.get_source(environment, name)
                                 ^^^^^^^^^^^^^^^^^^^^^^^^^^^^^^^^^^
  File "/usr/local/lib/python3.11/dist-packages/flask/templating.py", line 65, in get_source
    return self._get_source_fast(environment, template)
           ^^^^^^^^^^^^^^^^^^^^^^^^^^^^^^^^^^^^^^^^^^^^
  File "/usr/local/lib/python3.11/dist-packages/flask/templating.py", line 99, in _get_source_fast
    raise TemplateNotFound(template)
jinja2.exceptions.TemplateNotFound: 404.html
2025-05-08 17:43:51,520 - app - ERROR - [app.py:190] - Erreur serveur: 500 Internal Server Error: The server encountered an internal error and was unable to complete your request. Either the server is overloaded or there is an error in the application.
2025-05-08 17:43:54,102 - app - INFO - [app.py:86] - Accès à la page d'exploitation
2025-05-08 17:43:54,102 - app - INFO - [app.py:106] - Préparation de l'exploitation de ssl-ccs-injection sur 192.168.217.139:443
2025-05-08 17:43:54,136 - app - WARNING - [app.py:185] - Page non trouvée: /api/network/local-ip
2025-05-08 17:43:54,137 - app - ERROR - [app.py:875] - Exception on /api/network/local-ip [GET]
Traceback (most recent call last):
  File "/usr/local/lib/python3.11/dist-packages/flask/app.py", line 917, in full_dispatch_request
    rv = self.dispatch_request()
         ^^^^^^^^^^^^^^^^^^^^^^^
  File "/usr/local/lib/python3.11/dist-packages/flask/app.py", line 891, in dispatch_request
    self.raise_routing_exception(req)
  File "/usr/local/lib/python3.11/dist-packages/flask/app.py", line 500, in raise_routing_exception
    raise request.routing_exception  # type: ignore[misc]
    ^^^^^^^^^^^^^^^^^^^^^^^^^^^^^^^
  File "/usr/local/lib/python3.11/dist-packages/flask/ctx.py", line 362, in match_request
    result = self.url_adapter.match(return_rule=True)  # type: ignore
             ^^^^^^^^^^^^^^^^^^^^^^^^^^^^^^^^^^^^^^^^
  File "/usr/local/lib/python3.11/dist-packages/werkzeug/routing/map.py", line 629, in match
    raise NotFound() from None
werkzeug.exceptions.NotFound: 404 Not Found: The requested URL was not found on the server. If you entered the URL manually please check your spelling and try again.

During handling of the above exception, another exception occurred:

Traceback (most recent call last):
  File "/usr/local/lib/python3.11/dist-packages/flask/app.py", line 1511, in wsgi_app
    response = self.full_dispatch_request()
               ^^^^^^^^^^^^^^^^^^^^^^^^^^^^
  File "/usr/local/lib/python3.11/dist-packages/flask/app.py", line 919, in full_dispatch_request
    rv = self.handle_user_exception(e)
         ^^^^^^^^^^^^^^^^^^^^^^^^^^^^^
  File "/usr/local/lib/python3.11/dist-packages/flask/app.py", line 802, in handle_user_exception
    return self.handle_http_exception(e)
           ^^^^^^^^^^^^^^^^^^^^^^^^^^^^^
  File "/usr/local/lib/python3.11/dist-packages/flask/app.py", line 777, in handle_http_exception
    return self.ensure_sync(handler)(e)  # type: ignore[no-any-return]
           ^^^^^^^^^^^^^^^^^^^^^^^^^^^^
  File "/home/oebn/toolbox/app.py", line 186, in page_not_found
    return render_template('404.html'), 404
           ^^^^^^^^^^^^^^^^^^^^^^^^^^^
  File "/usr/local/lib/python3.11/dist-packages/flask/templating.py", line 149, in render_template
    template = app.jinja_env.get_or_select_template(template_name_or_list)
               ^^^^^^^^^^^^^^^^^^^^^^^^^^^^^^^^^^^^^^^^^^^^^^^^^^^^^^^^^^^
  File "/usr/local/lib/python3.11/dist-packages/jinja2/environment.py", line 1087, in get_or_select_template
    return self.get_template(template_name_or_list, parent, globals)
           ^^^^^^^^^^^^^^^^^^^^^^^^^^^^^^^^^^^^^^^^^^^^^^^^^^^^^^^^^
  File "/usr/local/lib/python3.11/dist-packages/jinja2/environment.py", line 1016, in get_template
    return self._load_template(name, globals)
           ^^^^^^^^^^^^^^^^^^^^^^^^^^^^^^^^^^
  File "/usr/local/lib/python3.11/dist-packages/jinja2/environment.py", line 975, in _load_template
    template = self.loader.load(self, name, self.make_globals(globals))
               ^^^^^^^^^^^^^^^^^^^^^^^^^^^^^^^^^^^^^^^^^^^^^^^^^^^^^^^^
  File "/usr/local/lib/python3.11/dist-packages/jinja2/loaders.py", line 126, in load
    source, filename, uptodate = self.get_source(environment, name)
                                 ^^^^^^^^^^^^^^^^^^^^^^^^^^^^^^^^^^
  File "/usr/local/lib/python3.11/dist-packages/flask/templating.py", line 65, in get_source
    return self._get_source_fast(environment, template)
           ^^^^^^^^^^^^^^^^^^^^^^^^^^^^^^^^^^^^^^^^^^^^
  File "/usr/local/lib/python3.11/dist-packages/flask/templating.py", line 99, in _get_source_fast
    raise TemplateNotFound(template)
jinja2.exceptions.TemplateNotFound: 404.html
2025-05-08 17:43:54,141 - app - ERROR - [app.py:190] - Erreur serveur: 500 Internal Server Error: The server encountered an internal error and was unable to complete your request. Either the server is overloaded or there is an error in the application.
2025-05-08 17:43:56,630 - app - INFO - [app.py:86] - Accès à la page d'exploitation
2025-05-08 17:43:56,631 - app - INFO - [app.py:106] - Préparation de l'exploitation de http-vuln-cve2014-3704 sur 192.168.217.139:443
2025-05-08 17:43:56,657 - app - WARNING - [app.py:185] - Page non trouvée: /api/network/local-ip
2025-05-08 17:43:56,658 - app - ERROR - [app.py:875] - Exception on /api/network/local-ip [GET]
Traceback (most recent call last):
  File "/usr/local/lib/python3.11/dist-packages/flask/app.py", line 917, in full_dispatch_request
    rv = self.dispatch_request()
         ^^^^^^^^^^^^^^^^^^^^^^^
  File "/usr/local/lib/python3.11/dist-packages/flask/app.py", line 891, in dispatch_request
    self.raise_routing_exception(req)
  File "/usr/local/lib/python3.11/dist-packages/flask/app.py", line 500, in raise_routing_exception
    raise request.routing_exception  # type: ignore[misc]
    ^^^^^^^^^^^^^^^^^^^^^^^^^^^^^^^
  File "/usr/local/lib/python3.11/dist-packages/flask/ctx.py", line 362, in match_request
    result = self.url_adapter.match(return_rule=True)  # type: ignore
             ^^^^^^^^^^^^^^^^^^^^^^^^^^^^^^^^^^^^^^^^
  File "/usr/local/lib/python3.11/dist-packages/werkzeug/routing/map.py", line 629, in match
    raise NotFound() from None
werkzeug.exceptions.NotFound: 404 Not Found: The requested URL was not found on the server. If you entered the URL manually please check your spelling and try again.

During handling of the above exception, another exception occurred:

Traceback (most recent call last):
  File "/usr/local/lib/python3.11/dist-packages/flask/app.py", line 1511, in wsgi_app
    response = self.full_dispatch_request()
               ^^^^^^^^^^^^^^^^^^^^^^^^^^^^
  File "/usr/local/lib/python3.11/dist-packages/flask/app.py", line 919, in full_dispatch_request
    rv = self.handle_user_exception(e)
         ^^^^^^^^^^^^^^^^^^^^^^^^^^^^^
  File "/usr/local/lib/python3.11/dist-packages/flask/app.py", line 802, in handle_user_exception
    return self.handle_http_exception(e)
           ^^^^^^^^^^^^^^^^^^^^^^^^^^^^^
  File "/usr/local/lib/python3.11/dist-packages/flask/app.py", line 777, in handle_http_exception
    return self.ensure_sync(handler)(e)  # type: ignore[no-any-return]
           ^^^^^^^^^^^^^^^^^^^^^^^^^^^^
  File "/home/oebn/toolbox/app.py", line 186, in page_not_found
    return render_template('404.html'), 404
           ^^^^^^^^^^^^^^^^^^^^^^^^^^^
  File "/usr/local/lib/python3.11/dist-packages/flask/templating.py", line 149, in render_template
    template = app.jinja_env.get_or_select_template(template_name_or_list)
               ^^^^^^^^^^^^^^^^^^^^^^^^^^^^^^^^^^^^^^^^^^^^^^^^^^^^^^^^^^^
  File "/usr/local/lib/python3.11/dist-packages/jinja2/environment.py", line 1087, in get_or_select_template
    return self.get_template(template_name_or_list, parent, globals)
           ^^^^^^^^^^^^^^^^^^^^^^^^^^^^^^^^^^^^^^^^^^^^^^^^^^^^^^^^^
  File "/usr/local/lib/python3.11/dist-packages/jinja2/environment.py", line 1016, in get_template
    return self._load_template(name, globals)
           ^^^^^^^^^^^^^^^^^^^^^^^^^^^^^^^^^^
  File "/usr/local/lib/python3.11/dist-packages/jinja2/environment.py", line 975, in _load_template
    template = self.loader.load(self, name, self.make_globals(globals))
               ^^^^^^^^^^^^^^^^^^^^^^^^^^^^^^^^^^^^^^^^^^^^^^^^^^^^^^^^
  File "/usr/local/lib/python3.11/dist-packages/jinja2/loaders.py", line 126, in load
    source, filename, uptodate = self.get_source(environment, name)
                                 ^^^^^^^^^^^^^^^^^^^^^^^^^^^^^^^^^^
  File "/usr/local/lib/python3.11/dist-packages/flask/templating.py", line 65, in get_source
    return self._get_source_fast(environment, template)
           ^^^^^^^^^^^^^^^^^^^^^^^^^^^^^^^^^^^^^^^^^^^^
  File "/usr/local/lib/python3.11/dist-packages/flask/templating.py", line 99, in _get_source_fast
    raise TemplateNotFound(template)
jinja2.exceptions.TemplateNotFound: 404.html
2025-05-08 17:43:56,665 - app - ERROR - [app.py:190] - Erreur serveur: 500 Internal Server Error: The server encountered an internal error and was unable to complete your request. Either the server is overloaded or there is an error in the application.
2025-05-08 17:44:47,391 - app - INFO - [app.py:86] - Accès à la page d'exploitation
2025-05-08 17:44:47,391 - app - INFO - [app.py:106] - Préparation de l'exploitation de ssl-dh-params sur 192.168.217.139:443
2025-05-08 17:44:47,421 - app - WARNING - [app.py:185] - Page non trouvée: /api/network/local-ip
2025-05-08 17:44:47,422 - app - ERROR - [app.py:875] - Exception on /api/network/local-ip [GET]
Traceback (most recent call last):
  File "/usr/local/lib/python3.11/dist-packages/flask/app.py", line 917, in full_dispatch_request
    rv = self.dispatch_request()
         ^^^^^^^^^^^^^^^^^^^^^^^
  File "/usr/local/lib/python3.11/dist-packages/flask/app.py", line 891, in dispatch_request
    self.raise_routing_exception(req)
  File "/usr/local/lib/python3.11/dist-packages/flask/app.py", line 500, in raise_routing_exception
    raise request.routing_exception  # type: ignore[misc]
    ^^^^^^^^^^^^^^^^^^^^^^^^^^^^^^^
  File "/usr/local/lib/python3.11/dist-packages/flask/ctx.py", line 362, in match_request
    result = self.url_adapter.match(return_rule=True)  # type: ignore
             ^^^^^^^^^^^^^^^^^^^^^^^^^^^^^^^^^^^^^^^^
  File "/usr/local/lib/python3.11/dist-packages/werkzeug/routing/map.py", line 629, in match
    raise NotFound() from None
werkzeug.exceptions.NotFound: 404 Not Found: The requested URL was not found on the server. If you entered the URL manually please check your spelling and try again.

During handling of the above exception, another exception occurred:

Traceback (most recent call last):
  File "/usr/local/lib/python3.11/dist-packages/flask/app.py", line 1511, in wsgi_app
    response = self.full_dispatch_request()
               ^^^^^^^^^^^^^^^^^^^^^^^^^^^^
  File "/usr/local/lib/python3.11/dist-packages/flask/app.py", line 919, in full_dispatch_request
    rv = self.handle_user_exception(e)
         ^^^^^^^^^^^^^^^^^^^^^^^^^^^^^
  File "/usr/local/lib/python3.11/dist-packages/flask/app.py", line 802, in handle_user_exception
    return self.handle_http_exception(e)
           ^^^^^^^^^^^^^^^^^^^^^^^^^^^^^
  File "/usr/local/lib/python3.11/dist-packages/flask/app.py", line 777, in handle_http_exception
    return self.ensure_sync(handler)(e)  # type: ignore[no-any-return]
           ^^^^^^^^^^^^^^^^^^^^^^^^^^^^
  File "/home/oebn/toolbox/app.py", line 186, in page_not_found
    return render_template('404.html'), 404
           ^^^^^^^^^^^^^^^^^^^^^^^^^^^
  File "/usr/local/lib/python3.11/dist-packages/flask/templating.py", line 149, in render_template
    template = app.jinja_env.get_or_select_template(template_name_or_list)
               ^^^^^^^^^^^^^^^^^^^^^^^^^^^^^^^^^^^^^^^^^^^^^^^^^^^^^^^^^^^
  File "/usr/local/lib/python3.11/dist-packages/jinja2/environment.py", line 1087, in get_or_select_template
    return self.get_template(template_name_or_list, parent, globals)
           ^^^^^^^^^^^^^^^^^^^^^^^^^^^^^^^^^^^^^^^^^^^^^^^^^^^^^^^^^
  File "/usr/local/lib/python3.11/dist-packages/jinja2/environment.py", line 1016, in get_template
    return self._load_template(name, globals)
           ^^^^^^^^^^^^^^^^^^^^^^^^^^^^^^^^^^
  File "/usr/local/lib/python3.11/dist-packages/jinja2/environment.py", line 975, in _load_template
    template = self.loader.load(self, name, self.make_globals(globals))
               ^^^^^^^^^^^^^^^^^^^^^^^^^^^^^^^^^^^^^^^^^^^^^^^^^^^^^^^^
  File "/usr/local/lib/python3.11/dist-packages/jinja2/loaders.py", line 126, in load
    source, filename, uptodate = self.get_source(environment, name)
                                 ^^^^^^^^^^^^^^^^^^^^^^^^^^^^^^^^^^
  File "/usr/local/lib/python3.11/dist-packages/flask/templating.py", line 65, in get_source
    return self._get_source_fast(environment, template)
           ^^^^^^^^^^^^^^^^^^^^^^^^^^^^^^^^^^^^^^^^^^^^
  File "/usr/local/lib/python3.11/dist-packages/flask/templating.py", line 99, in _get_source_fast
    raise TemplateNotFound(template)
jinja2.exceptions.TemplateNotFound: 404.html
2025-05-08 17:44:47,427 - app - ERROR - [app.py:190] - Erreur serveur: 500 Internal Server Error: The server encountered an internal error and was unable to complete your request. Either the server is overloaded or there is an error in the application.
2025-05-09 10:07:12,929 - app - INFO - [app.py:17] - Création de l'application Flask
2025-05-09 10:07:13,660 - app - INFO - [app.py:193] - Application Flask configurée avec succès
2025-05-09 10:07:13,660 - app - INFO - [app.py:204] - Démarrage de l'application sur 0.0.0.0:5000 (debug: False)
2025-05-09 10:07:22,879 - app - WARNING - [app.py:185] - Page non trouvée: /favicon.ico
2025-05-09 10:07:22,880 - app - ERROR - [app.py:875] - Exception on /favicon.ico [GET]
Traceback (most recent call last):
  File "/usr/local/lib/python3.11/dist-packages/flask/app.py", line 917, in full_dispatch_request
    rv = self.dispatch_request()
         ^^^^^^^^^^^^^^^^^^^^^^^
  File "/usr/local/lib/python3.11/dist-packages/flask/app.py", line 891, in dispatch_request
    self.raise_routing_exception(req)
  File "/usr/local/lib/python3.11/dist-packages/flask/app.py", line 500, in raise_routing_exception
    raise request.routing_exception  # type: ignore[misc]
    ^^^^^^^^^^^^^^^^^^^^^^^^^^^^^^^
  File "/usr/local/lib/python3.11/dist-packages/flask/ctx.py", line 362, in match_request
    result = self.url_adapter.match(return_rule=True)  # type: ignore
             ^^^^^^^^^^^^^^^^^^^^^^^^^^^^^^^^^^^^^^^^
  File "/usr/local/lib/python3.11/dist-packages/werkzeug/routing/map.py", line 629, in match
    raise NotFound() from None
werkzeug.exceptions.NotFound: 404 Not Found: The requested URL was not found on the server. If you entered the URL manually please check your spelling and try again.

During handling of the above exception, another exception occurred:

Traceback (most recent call last):
  File "/usr/local/lib/python3.11/dist-packages/flask/app.py", line 1511, in wsgi_app
    response = self.full_dispatch_request()
               ^^^^^^^^^^^^^^^^^^^^^^^^^^^^
  File "/usr/local/lib/python3.11/dist-packages/flask/app.py", line 919, in full_dispatch_request
    rv = self.handle_user_exception(e)
         ^^^^^^^^^^^^^^^^^^^^^^^^^^^^^
  File "/usr/local/lib/python3.11/dist-packages/flask/app.py", line 802, in handle_user_exception
    return self.handle_http_exception(e)
           ^^^^^^^^^^^^^^^^^^^^^^^^^^^^^
  File "/usr/local/lib/python3.11/dist-packages/flask/app.py", line 777, in handle_http_exception
    return self.ensure_sync(handler)(e)  # type: ignore[no-any-return]
           ^^^^^^^^^^^^^^^^^^^^^^^^^^^^
  File "/home/oebn/toolbox-pers/app.py", line 186, in page_not_found
    return render_template('404.html'), 404
           ^^^^^^^^^^^^^^^^^^^^^^^^^^^
  File "/usr/local/lib/python3.11/dist-packages/flask/templating.py", line 149, in render_template
    template = app.jinja_env.get_or_select_template(template_name_or_list)
               ^^^^^^^^^^^^^^^^^^^^^^^^^^^^^^^^^^^^^^^^^^^^^^^^^^^^^^^^^^^
  File "/usr/local/lib/python3.11/dist-packages/jinja2/environment.py", line 1087, in get_or_select_template
    return self.get_template(template_name_or_list, parent, globals)
           ^^^^^^^^^^^^^^^^^^^^^^^^^^^^^^^^^^^^^^^^^^^^^^^^^^^^^^^^^
  File "/usr/local/lib/python3.11/dist-packages/jinja2/environment.py", line 1016, in get_template
    return self._load_template(name, globals)
           ^^^^^^^^^^^^^^^^^^^^^^^^^^^^^^^^^^
  File "/usr/local/lib/python3.11/dist-packages/jinja2/environment.py", line 975, in _load_template
    template = self.loader.load(self, name, self.make_globals(globals))
               ^^^^^^^^^^^^^^^^^^^^^^^^^^^^^^^^^^^^^^^^^^^^^^^^^^^^^^^^
  File "/usr/local/lib/python3.11/dist-packages/jinja2/loaders.py", line 126, in load
    source, filename, uptodate = self.get_source(environment, name)
                                 ^^^^^^^^^^^^^^^^^^^^^^^^^^^^^^^^^^
  File "/usr/local/lib/python3.11/dist-packages/flask/templating.py", line 65, in get_source
    return self._get_source_fast(environment, template)
           ^^^^^^^^^^^^^^^^^^^^^^^^^^^^^^^^^^^^^^^^^^^^
  File "/usr/local/lib/python3.11/dist-packages/flask/templating.py", line 99, in _get_source_fast
    raise TemplateNotFound(template)
jinja2.exceptions.TemplateNotFound: 404.html
2025-05-09 10:07:22,923 - app - ERROR - [app.py:190] - Erreur serveur: 500 Internal Server Error: The server encountered an internal error and was unable to complete your request. Either the server is overloaded or there is an error in the application.
2025-05-09 10:07:27,375 - app - WARNING - [app.py:185] - Page non trouvée: /favicon.ico
2025-05-09 10:07:27,376 - app - ERROR - [app.py:875] - Exception on /favicon.ico [GET]
Traceback (most recent call last):
  File "/usr/local/lib/python3.11/dist-packages/flask/app.py", line 917, in full_dispatch_request
    rv = self.dispatch_request()
         ^^^^^^^^^^^^^^^^^^^^^^^
  File "/usr/local/lib/python3.11/dist-packages/flask/app.py", line 891, in dispatch_request
    self.raise_routing_exception(req)
  File "/usr/local/lib/python3.11/dist-packages/flask/app.py", line 500, in raise_routing_exception
    raise request.routing_exception  # type: ignore[misc]
    ^^^^^^^^^^^^^^^^^^^^^^^^^^^^^^^
  File "/usr/local/lib/python3.11/dist-packages/flask/ctx.py", line 362, in match_request
    result = self.url_adapter.match(return_rule=True)  # type: ignore
             ^^^^^^^^^^^^^^^^^^^^^^^^^^^^^^^^^^^^^^^^
  File "/usr/local/lib/python3.11/dist-packages/werkzeug/routing/map.py", line 629, in match
    raise NotFound() from None
werkzeug.exceptions.NotFound: 404 Not Found: The requested URL was not found on the server. If you entered the URL manually please check your spelling and try again.

During handling of the above exception, another exception occurred:

Traceback (most recent call last):
  File "/usr/local/lib/python3.11/dist-packages/flask/app.py", line 1511, in wsgi_app
    response = self.full_dispatch_request()
               ^^^^^^^^^^^^^^^^^^^^^^^^^^^^
  File "/usr/local/lib/python3.11/dist-packages/flask/app.py", line 919, in full_dispatch_request
    rv = self.handle_user_exception(e)
         ^^^^^^^^^^^^^^^^^^^^^^^^^^^^^
  File "/usr/local/lib/python3.11/dist-packages/flask/app.py", line 802, in handle_user_exception
    return self.handle_http_exception(e)
           ^^^^^^^^^^^^^^^^^^^^^^^^^^^^^
  File "/usr/local/lib/python3.11/dist-packages/flask/app.py", line 777, in handle_http_exception
    return self.ensure_sync(handler)(e)  # type: ignore[no-any-return]
           ^^^^^^^^^^^^^^^^^^^^^^^^^^^^
  File "/home/oebn/toolbox-pers/app.py", line 186, in page_not_found
    return render_template('404.html'), 404
           ^^^^^^^^^^^^^^^^^^^^^^^^^^^
  File "/usr/local/lib/python3.11/dist-packages/flask/templating.py", line 149, in render_template
    template = app.jinja_env.get_or_select_template(template_name_or_list)
               ^^^^^^^^^^^^^^^^^^^^^^^^^^^^^^^^^^^^^^^^^^^^^^^^^^^^^^^^^^^
  File "/usr/local/lib/python3.11/dist-packages/jinja2/environment.py", line 1087, in get_or_select_template
    return self.get_template(template_name_or_list, parent, globals)
           ^^^^^^^^^^^^^^^^^^^^^^^^^^^^^^^^^^^^^^^^^^^^^^^^^^^^^^^^^
  File "/usr/local/lib/python3.11/dist-packages/jinja2/environment.py", line 1016, in get_template
    return self._load_template(name, globals)
           ^^^^^^^^^^^^^^^^^^^^^^^^^^^^^^^^^^
  File "/usr/local/lib/python3.11/dist-packages/jinja2/environment.py", line 975, in _load_template
    template = self.loader.load(self, name, self.make_globals(globals))
               ^^^^^^^^^^^^^^^^^^^^^^^^^^^^^^^^^^^^^^^^^^^^^^^^^^^^^^^^
  File "/usr/local/lib/python3.11/dist-packages/jinja2/loaders.py", line 126, in load
    source, filename, uptodate = self.get_source(environment, name)
                                 ^^^^^^^^^^^^^^^^^^^^^^^^^^^^^^^^^^
  File "/usr/local/lib/python3.11/dist-packages/flask/templating.py", line 65, in get_source
    return self._get_source_fast(environment, template)
           ^^^^^^^^^^^^^^^^^^^^^^^^^^^^^^^^^^^^^^^^^^^^
  File "/usr/local/lib/python3.11/dist-packages/flask/templating.py", line 99, in _get_source_fast
    raise TemplateNotFound(template)
jinja2.exceptions.TemplateNotFound: 404.html
2025-05-09 10:07:27,378 - app - ERROR - [app.py:190] - Erreur serveur: 500 Internal Server Error: The server encountered an internal error and was unable to complete your request. Either the server is overloaded or there is an error in the application.
2025-05-09 10:07:28,860 - app - WARNING - [app.py:185] - Page non trouvée: /favicon.ico
2025-05-09 10:07:28,860 - app - ERROR - [app.py:875] - Exception on /favicon.ico [GET]
Traceback (most recent call last):
  File "/usr/local/lib/python3.11/dist-packages/flask/app.py", line 917, in full_dispatch_request
    rv = self.dispatch_request()
         ^^^^^^^^^^^^^^^^^^^^^^^
  File "/usr/local/lib/python3.11/dist-packages/flask/app.py", line 891, in dispatch_request
    self.raise_routing_exception(req)
  File "/usr/local/lib/python3.11/dist-packages/flask/app.py", line 500, in raise_routing_exception
    raise request.routing_exception  # type: ignore[misc]
    ^^^^^^^^^^^^^^^^^^^^^^^^^^^^^^^
  File "/usr/local/lib/python3.11/dist-packages/flask/ctx.py", line 362, in match_request
    result = self.url_adapter.match(return_rule=True)  # type: ignore
             ^^^^^^^^^^^^^^^^^^^^^^^^^^^^^^^^^^^^^^^^
  File "/usr/local/lib/python3.11/dist-packages/werkzeug/routing/map.py", line 629, in match
    raise NotFound() from None
werkzeug.exceptions.NotFound: 404 Not Found: The requested URL was not found on the server. If you entered the URL manually please check your spelling and try again.

During handling of the above exception, another exception occurred:

Traceback (most recent call last):
  File "/usr/local/lib/python3.11/dist-packages/flask/app.py", line 1511, in wsgi_app
    response = self.full_dispatch_request()
               ^^^^^^^^^^^^^^^^^^^^^^^^^^^^
  File "/usr/local/lib/python3.11/dist-packages/flask/app.py", line 919, in full_dispatch_request
    rv = self.handle_user_exception(e)
         ^^^^^^^^^^^^^^^^^^^^^^^^^^^^^
  File "/usr/local/lib/python3.11/dist-packages/flask/app.py", line 802, in handle_user_exception
    return self.handle_http_exception(e)
           ^^^^^^^^^^^^^^^^^^^^^^^^^^^^^
  File "/usr/local/lib/python3.11/dist-packages/flask/app.py", line 777, in handle_http_exception
    return self.ensure_sync(handler)(e)  # type: ignore[no-any-return]
           ^^^^^^^^^^^^^^^^^^^^^^^^^^^^
  File "/home/oebn/toolbox-pers/app.py", line 186, in page_not_found
    return render_template('404.html'), 404
           ^^^^^^^^^^^^^^^^^^^^^^^^^^^
  File "/usr/local/lib/python3.11/dist-packages/flask/templating.py", line 149, in render_template
    template = app.jinja_env.get_or_select_template(template_name_or_list)
               ^^^^^^^^^^^^^^^^^^^^^^^^^^^^^^^^^^^^^^^^^^^^^^^^^^^^^^^^^^^
  File "/usr/local/lib/python3.11/dist-packages/jinja2/environment.py", line 1087, in get_or_select_template
    return self.get_template(template_name_or_list, parent, globals)
           ^^^^^^^^^^^^^^^^^^^^^^^^^^^^^^^^^^^^^^^^^^^^^^^^^^^^^^^^^
  File "/usr/local/lib/python3.11/dist-packages/jinja2/environment.py", line 1016, in get_template
    return self._load_template(name, globals)
           ^^^^^^^^^^^^^^^^^^^^^^^^^^^^^^^^^^
  File "/usr/local/lib/python3.11/dist-packages/jinja2/environment.py", line 975, in _load_template
    template = self.loader.load(self, name, self.make_globals(globals))
               ^^^^^^^^^^^^^^^^^^^^^^^^^^^^^^^^^^^^^^^^^^^^^^^^^^^^^^^^
  File "/usr/local/lib/python3.11/dist-packages/jinja2/loaders.py", line 126, in load
    source, filename, uptodate = self.get_source(environment, name)
                                 ^^^^^^^^^^^^^^^^^^^^^^^^^^^^^^^^^^
  File "/usr/local/lib/python3.11/dist-packages/flask/templating.py", line 65, in get_source
    return self._get_source_fast(environment, template)
           ^^^^^^^^^^^^^^^^^^^^^^^^^^^^^^^^^^^^^^^^^^^^
  File "/usr/local/lib/python3.11/dist-packages/flask/templating.py", line 99, in _get_source_fast
    raise TemplateNotFound(template)
jinja2.exceptions.TemplateNotFound: 404.html
2025-05-09 10:07:28,862 - app - ERROR - [app.py:190] - Erreur serveur: 500 Internal Server Error: The server encountered an internal error and was unable to complete your request. Either the server is overloaded or there is an error in the application.
2025-05-09 10:07:33,436 - app - WARNING - [app.py:185] - Page non trouvée: /favicon.ico
2025-05-09 10:07:33,436 - app - ERROR - [app.py:875] - Exception on /favicon.ico [GET]
Traceback (most recent call last):
  File "/usr/local/lib/python3.11/dist-packages/flask/app.py", line 917, in full_dispatch_request
    rv = self.dispatch_request()
         ^^^^^^^^^^^^^^^^^^^^^^^
  File "/usr/local/lib/python3.11/dist-packages/flask/app.py", line 891, in dispatch_request
    self.raise_routing_exception(req)
  File "/usr/local/lib/python3.11/dist-packages/flask/app.py", line 500, in raise_routing_exception
    raise request.routing_exception  # type: ignore[misc]
    ^^^^^^^^^^^^^^^^^^^^^^^^^^^^^^^
  File "/usr/local/lib/python3.11/dist-packages/flask/ctx.py", line 362, in match_request
    result = self.url_adapter.match(return_rule=True)  # type: ignore
             ^^^^^^^^^^^^^^^^^^^^^^^^^^^^^^^^^^^^^^^^
  File "/usr/local/lib/python3.11/dist-packages/werkzeug/routing/map.py", line 629, in match
    raise NotFound() from None
werkzeug.exceptions.NotFound: 404 Not Found: The requested URL was not found on the server. If you entered the URL manually please check your spelling and try again.

During handling of the above exception, another exception occurred:

Traceback (most recent call last):
  File "/usr/local/lib/python3.11/dist-packages/flask/app.py", line 1511, in wsgi_app
    response = self.full_dispatch_request()
               ^^^^^^^^^^^^^^^^^^^^^^^^^^^^
  File "/usr/local/lib/python3.11/dist-packages/flask/app.py", line 919, in full_dispatch_request
    rv = self.handle_user_exception(e)
         ^^^^^^^^^^^^^^^^^^^^^^^^^^^^^
  File "/usr/local/lib/python3.11/dist-packages/flask/app.py", line 802, in handle_user_exception
    return self.handle_http_exception(e)
           ^^^^^^^^^^^^^^^^^^^^^^^^^^^^^
  File "/usr/local/lib/python3.11/dist-packages/flask/app.py", line 777, in handle_http_exception
    return self.ensure_sync(handler)(e)  # type: ignore[no-any-return]
           ^^^^^^^^^^^^^^^^^^^^^^^^^^^^
  File "/home/oebn/toolbox-pers/app.py", line 186, in page_not_found
    return render_template('404.html'), 404
           ^^^^^^^^^^^^^^^^^^^^^^^^^^^
  File "/usr/local/lib/python3.11/dist-packages/flask/templating.py", line 149, in render_template
    template = app.jinja_env.get_or_select_template(template_name_or_list)
               ^^^^^^^^^^^^^^^^^^^^^^^^^^^^^^^^^^^^^^^^^^^^^^^^^^^^^^^^^^^
  File "/usr/local/lib/python3.11/dist-packages/jinja2/environment.py", line 1087, in get_or_select_template
    return self.get_template(template_name_or_list, parent, globals)
           ^^^^^^^^^^^^^^^^^^^^^^^^^^^^^^^^^^^^^^^^^^^^^^^^^^^^^^^^^
  File "/usr/local/lib/python3.11/dist-packages/jinja2/environment.py", line 1016, in get_template
    return self._load_template(name, globals)
           ^^^^^^^^^^^^^^^^^^^^^^^^^^^^^^^^^^
  File "/usr/local/lib/python3.11/dist-packages/jinja2/environment.py", line 975, in _load_template
    template = self.loader.load(self, name, self.make_globals(globals))
               ^^^^^^^^^^^^^^^^^^^^^^^^^^^^^^^^^^^^^^^^^^^^^^^^^^^^^^^^
  File "/usr/local/lib/python3.11/dist-packages/jinja2/loaders.py", line 126, in load
    source, filename, uptodate = self.get_source(environment, name)
                                 ^^^^^^^^^^^^^^^^^^^^^^^^^^^^^^^^^^
  File "/usr/local/lib/python3.11/dist-packages/flask/templating.py", line 65, in get_source
    return self._get_source_fast(environment, template)
           ^^^^^^^^^^^^^^^^^^^^^^^^^^^^^^^^^^^^^^^^^^^^
  File "/usr/local/lib/python3.11/dist-packages/flask/templating.py", line 99, in _get_source_fast
    raise TemplateNotFound(template)
jinja2.exceptions.TemplateNotFound: 404.html
2025-05-09 10:07:33,439 - app - ERROR - [app.py:190] - Erreur serveur: 500 Internal Server Error: The server encountered an internal error and was unable to complete your request. Either the server is overloaded or there is an error in the application.
2025-05-09 10:07:34,064 - app - WARNING - [app.py:185] - Page non trouvée: /favicon.ico
2025-05-09 10:07:34,064 - app - ERROR - [app.py:875] - Exception on /favicon.ico [GET]
Traceback (most recent call last):
  File "/usr/local/lib/python3.11/dist-packages/flask/app.py", line 917, in full_dispatch_request
    rv = self.dispatch_request()
         ^^^^^^^^^^^^^^^^^^^^^^^
  File "/usr/local/lib/python3.11/dist-packages/flask/app.py", line 891, in dispatch_request
    self.raise_routing_exception(req)
  File "/usr/local/lib/python3.11/dist-packages/flask/app.py", line 500, in raise_routing_exception
    raise request.routing_exception  # type: ignore[misc]
    ^^^^^^^^^^^^^^^^^^^^^^^^^^^^^^^
  File "/usr/local/lib/python3.11/dist-packages/flask/ctx.py", line 362, in match_request
    result = self.url_adapter.match(return_rule=True)  # type: ignore
             ^^^^^^^^^^^^^^^^^^^^^^^^^^^^^^^^^^^^^^^^
  File "/usr/local/lib/python3.11/dist-packages/werkzeug/routing/map.py", line 629, in match
    raise NotFound() from None
werkzeug.exceptions.NotFound: 404 Not Found: The requested URL was not found on the server. If you entered the URL manually please check your spelling and try again.

During handling of the above exception, another exception occurred:

Traceback (most recent call last):
  File "/usr/local/lib/python3.11/dist-packages/flask/app.py", line 1511, in wsgi_app
    response = self.full_dispatch_request()
               ^^^^^^^^^^^^^^^^^^^^^^^^^^^^
  File "/usr/local/lib/python3.11/dist-packages/flask/app.py", line 919, in full_dispatch_request
    rv = self.handle_user_exception(e)
         ^^^^^^^^^^^^^^^^^^^^^^^^^^^^^
  File "/usr/local/lib/python3.11/dist-packages/flask/app.py", line 802, in handle_user_exception
    return self.handle_http_exception(e)
           ^^^^^^^^^^^^^^^^^^^^^^^^^^^^^
  File "/usr/local/lib/python3.11/dist-packages/flask/app.py", line 777, in handle_http_exception
    return self.ensure_sync(handler)(e)  # type: ignore[no-any-return]
           ^^^^^^^^^^^^^^^^^^^^^^^^^^^^
  File "/home/oebn/toolbox-pers/app.py", line 186, in page_not_found
    return render_template('404.html'), 404
           ^^^^^^^^^^^^^^^^^^^^^^^^^^^
  File "/usr/local/lib/python3.11/dist-packages/flask/templating.py", line 149, in render_template
    template = app.jinja_env.get_or_select_template(template_name_or_list)
               ^^^^^^^^^^^^^^^^^^^^^^^^^^^^^^^^^^^^^^^^^^^^^^^^^^^^^^^^^^^
  File "/usr/local/lib/python3.11/dist-packages/jinja2/environment.py", line 1087, in get_or_select_template
    return self.get_template(template_name_or_list, parent, globals)
           ^^^^^^^^^^^^^^^^^^^^^^^^^^^^^^^^^^^^^^^^^^^^^^^^^^^^^^^^^
  File "/usr/local/lib/python3.11/dist-packages/jinja2/environment.py", line 1016, in get_template
    return self._load_template(name, globals)
           ^^^^^^^^^^^^^^^^^^^^^^^^^^^^^^^^^^
  File "/usr/local/lib/python3.11/dist-packages/jinja2/environment.py", line 975, in _load_template
    template = self.loader.load(self, name, self.make_globals(globals))
               ^^^^^^^^^^^^^^^^^^^^^^^^^^^^^^^^^^^^^^^^^^^^^^^^^^^^^^^^
  File "/usr/local/lib/python3.11/dist-packages/jinja2/loaders.py", line 126, in load
    source, filename, uptodate = self.get_source(environment, name)
                                 ^^^^^^^^^^^^^^^^^^^^^^^^^^^^^^^^^^
  File "/usr/local/lib/python3.11/dist-packages/flask/templating.py", line 65, in get_source
    return self._get_source_fast(environment, template)
           ^^^^^^^^^^^^^^^^^^^^^^^^^^^^^^^^^^^^^^^^^^^^
  File "/usr/local/lib/python3.11/dist-packages/flask/templating.py", line 99, in _get_source_fast
    raise TemplateNotFound(template)
jinja2.exceptions.TemplateNotFound: 404.html
2025-05-09 10:07:34,067 - app - ERROR - [app.py:190] - Erreur serveur: 500 Internal Server Error: The server encountered an internal error and was unable to complete your request. Either the server is overloaded or there is an error in the application.
2025-05-09 10:08:18,478 - app - INFO - [app.py:17] - Création de l'application Flask
2025-05-09 10:08:19,052 - app - INFO - [app.py:193] - Application Flask configurée avec succès
2025-05-09 10:08:19,079 - app - INFO - [app.py:204] - Démarrage de l'application sur 0.0.0.0:5000 (debug: False)
2025-05-09 10:08:20,486 - app - WARNING - [app.py:185] - Page non trouvée: /favicon.ico
2025-05-09 10:08:20,486 - app - ERROR - [app.py:875] - Exception on /favicon.ico [GET]
Traceback (most recent call last):
  File "/usr/local/lib/python3.11/dist-packages/flask/app.py", line 917, in full_dispatch_request
    rv = self.dispatch_request()
         ^^^^^^^^^^^^^^^^^^^^^^^
  File "/usr/local/lib/python3.11/dist-packages/flask/app.py", line 891, in dispatch_request
    self.raise_routing_exception(req)
  File "/usr/local/lib/python3.11/dist-packages/flask/app.py", line 500, in raise_routing_exception
    raise request.routing_exception  # type: ignore[misc]
    ^^^^^^^^^^^^^^^^^^^^^^^^^^^^^^^
  File "/usr/local/lib/python3.11/dist-packages/flask/ctx.py", line 362, in match_request
    result = self.url_adapter.match(return_rule=True)  # type: ignore
             ^^^^^^^^^^^^^^^^^^^^^^^^^^^^^^^^^^^^^^^^
  File "/usr/local/lib/python3.11/dist-packages/werkzeug/routing/map.py", line 629, in match
    raise NotFound() from None
werkzeug.exceptions.NotFound: 404 Not Found: The requested URL was not found on the server. If you entered the URL manually please check your spelling and try again.

During handling of the above exception, another exception occurred:

Traceback (most recent call last):
  File "/usr/local/lib/python3.11/dist-packages/flask/app.py", line 1511, in wsgi_app
    response = self.full_dispatch_request()
               ^^^^^^^^^^^^^^^^^^^^^^^^^^^^
  File "/usr/local/lib/python3.11/dist-packages/flask/app.py", line 919, in full_dispatch_request
    rv = self.handle_user_exception(e)
         ^^^^^^^^^^^^^^^^^^^^^^^^^^^^^
  File "/usr/local/lib/python3.11/dist-packages/flask/app.py", line 802, in handle_user_exception
    return self.handle_http_exception(e)
           ^^^^^^^^^^^^^^^^^^^^^^^^^^^^^
  File "/usr/local/lib/python3.11/dist-packages/flask/app.py", line 777, in handle_http_exception
    return self.ensure_sync(handler)(e)  # type: ignore[no-any-return]
           ^^^^^^^^^^^^^^^^^^^^^^^^^^^^
  File "/home/oebn/toolbox-pers/app.py", line 186, in page_not_found
    return render_template('404.html'), 404
           ^^^^^^^^^^^^^^^^^^^^^^^^^^^
  File "/usr/local/lib/python3.11/dist-packages/flask/templating.py", line 149, in render_template
    template = app.jinja_env.get_or_select_template(template_name_or_list)
               ^^^^^^^^^^^^^^^^^^^^^^^^^^^^^^^^^^^^^^^^^^^^^^^^^^^^^^^^^^^
  File "/usr/local/lib/python3.11/dist-packages/jinja2/environment.py", line 1087, in get_or_select_template
    return self.get_template(template_name_or_list, parent, globals)
           ^^^^^^^^^^^^^^^^^^^^^^^^^^^^^^^^^^^^^^^^^^^^^^^^^^^^^^^^^
  File "/usr/local/lib/python3.11/dist-packages/jinja2/environment.py", line 1016, in get_template
    return self._load_template(name, globals)
           ^^^^^^^^^^^^^^^^^^^^^^^^^^^^^^^^^^
  File "/usr/local/lib/python3.11/dist-packages/jinja2/environment.py", line 975, in _load_template
    template = self.loader.load(self, name, self.make_globals(globals))
               ^^^^^^^^^^^^^^^^^^^^^^^^^^^^^^^^^^^^^^^^^^^^^^^^^^^^^^^^
  File "/usr/local/lib/python3.11/dist-packages/jinja2/loaders.py", line 126, in load
    source, filename, uptodate = self.get_source(environment, name)
                                 ^^^^^^^^^^^^^^^^^^^^^^^^^^^^^^^^^^
  File "/usr/local/lib/python3.11/dist-packages/flask/templating.py", line 65, in get_source
    return self._get_source_fast(environment, template)
           ^^^^^^^^^^^^^^^^^^^^^^^^^^^^^^^^^^^^^^^^^^^^
  File "/usr/local/lib/python3.11/dist-packages/flask/templating.py", line 99, in _get_source_fast
    raise TemplateNotFound(template)
jinja2.exceptions.TemplateNotFound: 404.html
2025-05-09 10:08:20,489 - app - ERROR - [app.py:190] - Erreur serveur: 500 Internal Server Error: The server encountered an internal error and was unable to complete your request. Either the server is overloaded or there is an error in the application.
2025-05-09 10:08:22,716 - app - WARNING - [app.py:185] - Page non trouvée: /favicon.ico
2025-05-09 10:08:22,716 - app - ERROR - [app.py:875] - Exception on /favicon.ico [GET]
Traceback (most recent call last):
  File "/usr/local/lib/python3.11/dist-packages/flask/app.py", line 917, in full_dispatch_request
    rv = self.dispatch_request()
         ^^^^^^^^^^^^^^^^^^^^^^^
  File "/usr/local/lib/python3.11/dist-packages/flask/app.py", line 891, in dispatch_request
    self.raise_routing_exception(req)
  File "/usr/local/lib/python3.11/dist-packages/flask/app.py", line 500, in raise_routing_exception
    raise request.routing_exception  # type: ignore[misc]
    ^^^^^^^^^^^^^^^^^^^^^^^^^^^^^^^
  File "/usr/local/lib/python3.11/dist-packages/flask/ctx.py", line 362, in match_request
    result = self.url_adapter.match(return_rule=True)  # type: ignore
             ^^^^^^^^^^^^^^^^^^^^^^^^^^^^^^^^^^^^^^^^
  File "/usr/local/lib/python3.11/dist-packages/werkzeug/routing/map.py", line 629, in match
    raise NotFound() from None
werkzeug.exceptions.NotFound: 404 Not Found: The requested URL was not found on the server. If you entered the URL manually please check your spelling and try again.

During handling of the above exception, another exception occurred:

Traceback (most recent call last):
  File "/usr/local/lib/python3.11/dist-packages/flask/app.py", line 1511, in wsgi_app
    response = self.full_dispatch_request()
               ^^^^^^^^^^^^^^^^^^^^^^^^^^^^
  File "/usr/local/lib/python3.11/dist-packages/flask/app.py", line 919, in full_dispatch_request
    rv = self.handle_user_exception(e)
         ^^^^^^^^^^^^^^^^^^^^^^^^^^^^^
  File "/usr/local/lib/python3.11/dist-packages/flask/app.py", line 802, in handle_user_exception
    return self.handle_http_exception(e)
           ^^^^^^^^^^^^^^^^^^^^^^^^^^^^^
  File "/usr/local/lib/python3.11/dist-packages/flask/app.py", line 777, in handle_http_exception
    return self.ensure_sync(handler)(e)  # type: ignore[no-any-return]
           ^^^^^^^^^^^^^^^^^^^^^^^^^^^^
  File "/home/oebn/toolbox-pers/app.py", line 186, in page_not_found
    return render_template('404.html'), 404
           ^^^^^^^^^^^^^^^^^^^^^^^^^^^
  File "/usr/local/lib/python3.11/dist-packages/flask/templating.py", line 149, in render_template
    template = app.jinja_env.get_or_select_template(template_name_or_list)
               ^^^^^^^^^^^^^^^^^^^^^^^^^^^^^^^^^^^^^^^^^^^^^^^^^^^^^^^^^^^
  File "/usr/local/lib/python3.11/dist-packages/jinja2/environment.py", line 1087, in get_or_select_template
    return self.get_template(template_name_or_list, parent, globals)
           ^^^^^^^^^^^^^^^^^^^^^^^^^^^^^^^^^^^^^^^^^^^^^^^^^^^^^^^^^
  File "/usr/local/lib/python3.11/dist-packages/jinja2/environment.py", line 1016, in get_template
    return self._load_template(name, globals)
           ^^^^^^^^^^^^^^^^^^^^^^^^^^^^^^^^^^
  File "/usr/local/lib/python3.11/dist-packages/jinja2/environment.py", line 975, in _load_template
    template = self.loader.load(self, name, self.make_globals(globals))
               ^^^^^^^^^^^^^^^^^^^^^^^^^^^^^^^^^^^^^^^^^^^^^^^^^^^^^^^^
  File "/usr/local/lib/python3.11/dist-packages/jinja2/loaders.py", line 126, in load
    source, filename, uptodate = self.get_source(environment, name)
                                 ^^^^^^^^^^^^^^^^^^^^^^^^^^^^^^^^^^
  File "/usr/local/lib/python3.11/dist-packages/flask/templating.py", line 65, in get_source
    return self._get_source_fast(environment, template)
           ^^^^^^^^^^^^^^^^^^^^^^^^^^^^^^^^^^^^^^^^^^^^
  File "/usr/local/lib/python3.11/dist-packages/flask/templating.py", line 99, in _get_source_fast
    raise TemplateNotFound(template)
jinja2.exceptions.TemplateNotFound: 404.html
2025-05-09 10:08:22,717 - app - ERROR - [app.py:190] - Erreur serveur: 500 Internal Server Error: The server encountered an internal error and was unable to complete your request. Either the server is overloaded or there is an error in the application.
2025-05-09 10:08:32,662 - app - WARNING - [app.py:185] - Page non trouvée: /favicon.ico
2025-05-09 10:08:32,663 - app - ERROR - [app.py:875] - Exception on /favicon.ico [GET]
Traceback (most recent call last):
  File "/usr/local/lib/python3.11/dist-packages/flask/app.py", line 917, in full_dispatch_request
    rv = self.dispatch_request()
         ^^^^^^^^^^^^^^^^^^^^^^^
  File "/usr/local/lib/python3.11/dist-packages/flask/app.py", line 891, in dispatch_request
    self.raise_routing_exception(req)
  File "/usr/local/lib/python3.11/dist-packages/flask/app.py", line 500, in raise_routing_exception
    raise request.routing_exception  # type: ignore[misc]
    ^^^^^^^^^^^^^^^^^^^^^^^^^^^^^^^
  File "/usr/local/lib/python3.11/dist-packages/flask/ctx.py", line 362, in match_request
    result = self.url_adapter.match(return_rule=True)  # type: ignore
             ^^^^^^^^^^^^^^^^^^^^^^^^^^^^^^^^^^^^^^^^
  File "/usr/local/lib/python3.11/dist-packages/werkzeug/routing/map.py", line 629, in match
    raise NotFound() from None
werkzeug.exceptions.NotFound: 404 Not Found: The requested URL was not found on the server. If you entered the URL manually please check your spelling and try again.

During handling of the above exception, another exception occurred:

Traceback (most recent call last):
  File "/usr/local/lib/python3.11/dist-packages/flask/app.py", line 1511, in wsgi_app
    response = self.full_dispatch_request()
               ^^^^^^^^^^^^^^^^^^^^^^^^^^^^
  File "/usr/local/lib/python3.11/dist-packages/flask/app.py", line 919, in full_dispatch_request
    rv = self.handle_user_exception(e)
         ^^^^^^^^^^^^^^^^^^^^^^^^^^^^^
  File "/usr/local/lib/python3.11/dist-packages/flask/app.py", line 802, in handle_user_exception
    return self.handle_http_exception(e)
           ^^^^^^^^^^^^^^^^^^^^^^^^^^^^^
  File "/usr/local/lib/python3.11/dist-packages/flask/app.py", line 777, in handle_http_exception
    return self.ensure_sync(handler)(e)  # type: ignore[no-any-return]
           ^^^^^^^^^^^^^^^^^^^^^^^^^^^^
  File "/home/oebn/toolbox-pers/app.py", line 186, in page_not_found
    return render_template('404.html'), 404
           ^^^^^^^^^^^^^^^^^^^^^^^^^^^
  File "/usr/local/lib/python3.11/dist-packages/flask/templating.py", line 149, in render_template
    template = app.jinja_env.get_or_select_template(template_name_or_list)
               ^^^^^^^^^^^^^^^^^^^^^^^^^^^^^^^^^^^^^^^^^^^^^^^^^^^^^^^^^^^
  File "/usr/local/lib/python3.11/dist-packages/jinja2/environment.py", line 1087, in get_or_select_template
    return self.get_template(template_name_or_list, parent, globals)
           ^^^^^^^^^^^^^^^^^^^^^^^^^^^^^^^^^^^^^^^^^^^^^^^^^^^^^^^^^
  File "/usr/local/lib/python3.11/dist-packages/jinja2/environment.py", line 1016, in get_template
    return self._load_template(name, globals)
           ^^^^^^^^^^^^^^^^^^^^^^^^^^^^^^^^^^
  File "/usr/local/lib/python3.11/dist-packages/jinja2/environment.py", line 975, in _load_template
    template = self.loader.load(self, name, self.make_globals(globals))
               ^^^^^^^^^^^^^^^^^^^^^^^^^^^^^^^^^^^^^^^^^^^^^^^^^^^^^^^^
  File "/usr/local/lib/python3.11/dist-packages/jinja2/loaders.py", line 126, in load
    source, filename, uptodate = self.get_source(environment, name)
                                 ^^^^^^^^^^^^^^^^^^^^^^^^^^^^^^^^^^
  File "/usr/local/lib/python3.11/dist-packages/flask/templating.py", line 65, in get_source
    return self._get_source_fast(environment, template)
           ^^^^^^^^^^^^^^^^^^^^^^^^^^^^^^^^^^^^^^^^^^^^
  File "/usr/local/lib/python3.11/dist-packages/flask/templating.py", line 99, in _get_source_fast
    raise TemplateNotFound(template)
jinja2.exceptions.TemplateNotFound: 404.html
2025-05-09 10:08:32,665 - app - ERROR - [app.py:190] - Erreur serveur: 500 Internal Server Error: The server encountered an internal error and was unable to complete your request. Either the server is overloaded or there is an error in the application.
2025-05-09 10:08:33,668 - app - WARNING - [app.py:185] - Page non trouvée: /favicon.ico
2025-05-09 10:08:33,668 - app - ERROR - [app.py:875] - Exception on /favicon.ico [GET]
Traceback (most recent call last):
  File "/usr/local/lib/python3.11/dist-packages/flask/app.py", line 917, in full_dispatch_request
    rv = self.dispatch_request()
         ^^^^^^^^^^^^^^^^^^^^^^^
  File "/usr/local/lib/python3.11/dist-packages/flask/app.py", line 891, in dispatch_request
    self.raise_routing_exception(req)
  File "/usr/local/lib/python3.11/dist-packages/flask/app.py", line 500, in raise_routing_exception
    raise request.routing_exception  # type: ignore[misc]
    ^^^^^^^^^^^^^^^^^^^^^^^^^^^^^^^
  File "/usr/local/lib/python3.11/dist-packages/flask/ctx.py", line 362, in match_request
    result = self.url_adapter.match(return_rule=True)  # type: ignore
             ^^^^^^^^^^^^^^^^^^^^^^^^^^^^^^^^^^^^^^^^
  File "/usr/local/lib/python3.11/dist-packages/werkzeug/routing/map.py", line 629, in match
    raise NotFound() from None
werkzeug.exceptions.NotFound: 404 Not Found: The requested URL was not found on the server. If you entered the URL manually please check your spelling and try again.

During handling of the above exception, another exception occurred:

Traceback (most recent call last):
  File "/usr/local/lib/python3.11/dist-packages/flask/app.py", line 1511, in wsgi_app
    response = self.full_dispatch_request()
               ^^^^^^^^^^^^^^^^^^^^^^^^^^^^
  File "/usr/local/lib/python3.11/dist-packages/flask/app.py", line 919, in full_dispatch_request
    rv = self.handle_user_exception(e)
         ^^^^^^^^^^^^^^^^^^^^^^^^^^^^^
  File "/usr/local/lib/python3.11/dist-packages/flask/app.py", line 802, in handle_user_exception
    return self.handle_http_exception(e)
           ^^^^^^^^^^^^^^^^^^^^^^^^^^^^^
  File "/usr/local/lib/python3.11/dist-packages/flask/app.py", line 777, in handle_http_exception
    return self.ensure_sync(handler)(e)  # type: ignore[no-any-return]
           ^^^^^^^^^^^^^^^^^^^^^^^^^^^^
  File "/home/oebn/toolbox-pers/app.py", line 186, in page_not_found
    return render_template('404.html'), 404
           ^^^^^^^^^^^^^^^^^^^^^^^^^^^
  File "/usr/local/lib/python3.11/dist-packages/flask/templating.py", line 149, in render_template
    template = app.jinja_env.get_or_select_template(template_name_or_list)
               ^^^^^^^^^^^^^^^^^^^^^^^^^^^^^^^^^^^^^^^^^^^^^^^^^^^^^^^^^^^
  File "/usr/local/lib/python3.11/dist-packages/jinja2/environment.py", line 1087, in get_or_select_template
    return self.get_template(template_name_or_list, parent, globals)
           ^^^^^^^^^^^^^^^^^^^^^^^^^^^^^^^^^^^^^^^^^^^^^^^^^^^^^^^^^
  File "/usr/local/lib/python3.11/dist-packages/jinja2/environment.py", line 1016, in get_template
    return self._load_template(name, globals)
           ^^^^^^^^^^^^^^^^^^^^^^^^^^^^^^^^^^
  File "/usr/local/lib/python3.11/dist-packages/jinja2/environment.py", line 975, in _load_template
    template = self.loader.load(self, name, self.make_globals(globals))
               ^^^^^^^^^^^^^^^^^^^^^^^^^^^^^^^^^^^^^^^^^^^^^^^^^^^^^^^^
  File "/usr/local/lib/python3.11/dist-packages/jinja2/loaders.py", line 126, in load
    source, filename, uptodate = self.get_source(environment, name)
                                 ^^^^^^^^^^^^^^^^^^^^^^^^^^^^^^^^^^
  File "/usr/local/lib/python3.11/dist-packages/flask/templating.py", line 65, in get_source
    return self._get_source_fast(environment, template)
           ^^^^^^^^^^^^^^^^^^^^^^^^^^^^^^^^^^^^^^^^^^^^
  File "/usr/local/lib/python3.11/dist-packages/flask/templating.py", line 99, in _get_source_fast
    raise TemplateNotFound(template)
jinja2.exceptions.TemplateNotFound: 404.html
2025-05-09 10:08:33,669 - app - ERROR - [app.py:190] - Erreur serveur: 500 Internal Server Error: The server encountered an internal error and was unable to complete your request. Either the server is overloaded or there is an error in the application.
2025-05-09 10:24:06,532 - app - INFO - [app.py:43] - Création de l'application Flask
2025-05-09 10:24:06,550 - app - INFO - [app.py:192] - 🚀 Application démarrée sur http://0.0.0.0:5000
2025-05-09 10:24:18,404 - app - WARNING - [app.py:61] - ⛔ Accès bloqué : 192.168.217.1
2025-05-09 10:24:20,159 - app - WARNING - [app.py:61] - ⛔ Accès bloqué : 192.168.217.1
2025-05-09 10:24:20,219 - app - WARNING - [app.py:61] - ⛔ Accès bloqué : 192.168.217.1
2025-05-09 10:28:27,793 - app - INFO - [app.py:43] - Création de l'application Flask
2025-05-09 10:29:03,046 - app - INFO - [app.py:43] - Création de l'application Flask
2025-05-09 10:29:03,057 - app - INFO - [app.py:192] - 🚀 Application démarrée sur http://0.0.0.0:5000
2025-05-09 10:29:42,054 - app - ERROR - [app.py:875] - Exception on /api/forensics/ [GET]
Traceback (most recent call last):
  File "/usr/local/lib/python3.11/dist-packages/flask/app.py", line 1511, in wsgi_app
    response = self.full_dispatch_request()
               ^^^^^^^^^^^^^^^^^^^^^^^^^^^^
  File "/usr/local/lib/python3.11/dist-packages/flask/app.py", line 919, in full_dispatch_request
    rv = self.handle_user_exception(e)
         ^^^^^^^^^^^^^^^^^^^^^^^^^^^^^
  File "/usr/local/lib/python3.11/dist-packages/flask/app.py", line 917, in full_dispatch_request
    rv = self.dispatch_request()
         ^^^^^^^^^^^^^^^^^^^^^^^
  File "/usr/local/lib/python3.11/dist-packages/flask/app.py", line 902, in dispatch_request
    return self.ensure_sync(self.view_functions[rule.endpoint])(**view_args)  # type: ignore[no-any-return]
           ^^^^^^^^^^^^^^^^^^^^^^^^^^^^^^^^^^^^^^^^^^^^^^^^^^^^^^^^^^^^^^^^^
  File "/home/oebn/Projet-Scan/securite/auth.py", line 60, in wrapper
    return f(*args, **kwargs)
           ^^^^^^^^^^^^^^^^^^
  File "/home/oebn/Projet-Scan/routes/forensics_routes.py", line 15, in analyser
    shutil.copy("forensics/memory_dump.encrypted", "static/forensics/memory_dump.encrypted")
  File "/usr/lib/python3.11/shutil.py", line 419, in copy
    copyfile(src, dst, follow_symlinks=follow_symlinks)
  File "/usr/lib/python3.11/shutil.py", line 256, in copyfile
    with open(src, 'rb') as fsrc:
         ^^^^^^^^^^^^^^^
FileNotFoundError: [Errno 2] No such file or directory: 'forensics/memory_dump.encrypted'
2025-05-09 10:29:45,024 - app - ERROR - [app.py:875] - Exception on /api/forensics/ [GET]
Traceback (most recent call last):
  File "/usr/local/lib/python3.11/dist-packages/flask/app.py", line 1511, in wsgi_app
    response = self.full_dispatch_request()
               ^^^^^^^^^^^^^^^^^^^^^^^^^^^^
  File "/usr/local/lib/python3.11/dist-packages/flask/app.py", line 919, in full_dispatch_request
    rv = self.handle_user_exception(e)
         ^^^^^^^^^^^^^^^^^^^^^^^^^^^^^
  File "/usr/local/lib/python3.11/dist-packages/flask/app.py", line 917, in full_dispatch_request
    rv = self.dispatch_request()
         ^^^^^^^^^^^^^^^^^^^^^^^
  File "/usr/local/lib/python3.11/dist-packages/flask/app.py", line 902, in dispatch_request
    return self.ensure_sync(self.view_functions[rule.endpoint])(**view_args)  # type: ignore[no-any-return]
           ^^^^^^^^^^^^^^^^^^^^^^^^^^^^^^^^^^^^^^^^^^^^^^^^^^^^^^^^^^^^^^^^^
  File "/home/oebn/Projet-Scan/securite/auth.py", line 60, in wrapper
    return f(*args, **kwargs)
           ^^^^^^^^^^^^^^^^^^
  File "/home/oebn/Projet-Scan/routes/forensics_routes.py", line 15, in analyser
    shutil.copy("forensics/memory_dump.encrypted", "static/forensics/memory_dump.encrypted")
  File "/usr/lib/python3.11/shutil.py", line 419, in copy
    copyfile(src, dst, follow_symlinks=follow_symlinks)
  File "/usr/lib/python3.11/shutil.py", line 256, in copyfile
    with open(src, 'rb') as fsrc:
         ^^^^^^^^^^^^^^^
FileNotFoundError: [Errno 2] No such file or directory: 'forensics/memory_dump.encrypted'
2025-05-09 10:44:53,565 - app - INFO - [app.py:43] - Création de l'application Flask
2025-05-09 10:44:53,580 - app - INFO - [app.py:240] - 🚀 Application démarrée sur http://0.0.0.0:5000
2025-05-09 10:44:55,627 - app - INFO - [app.py:153] - Accès à la page d'exploitation
2025-05-09 10:44:55,628 - app - INFO - [app.py:173] - Préparation de l'exploitation de ssl-dh-params sur 192.168.217.139:443
2025-05-09 10:45:04,226 - app - INFO - [app.py:153] - Accès à la page d'exploitation
2025-05-09 10:45:04,226 - app - INFO - [app.py:173] - Préparation de l'exploitation de http-slowloris-check sur 192.168.217.139:443
2025-05-09 11:16:51,077 - app - INFO - [app.py:43] - Création de l'application Flask
2025-05-09 11:16:51,101 - app - INFO - [app.py:240] - 🚀 Application démarrée sur http://0.0.0.0:5000
2025-05-09 11:24:21,478 - app - INFO - [app.py:153] - Accès à la page d'exploitation
2025-05-09 11:24:21,478 - app - INFO - [app.py:173] - Préparation de l'exploitation de ssl-ccs-injection sur 192.168.217.139:443
2025-05-09 11:34:49,842 - app - INFO - [app.py:43] - Création de l'application Flask
2025-05-09 11:34:49,869 - app - INFO - [app.py:240] - 🚀 Application démarrée sur http://0.0.0.0:5000
2025-05-15 20:46:45,073 - app - INFO - [app.py:43] - Création de l'application Flask
2025-05-15 20:46:45,098 - app - INFO - [app.py:240] - 🚀 Application démarrée sur http://0.0.0.0:5000
2025-05-15 21:18:34,624 - app - INFO - [app.py:43] - Création de l'application Flask
2025-05-15 21:18:34,652 - app - INFO - [app.py:265] - 🚀 Application démarrée sur http://0.0.0.0:5000
2025-05-15 21:22:34,950 - app - INFO - [app.py:43] - Création de l'application Flask
2025-05-15 21:22:34,963 - app - INFO - [app.py:265] - 🚀 Application démarrée sur http://0.0.0.0:5000
2025-05-15 21:32:30,321 - app - INFO - [app.py:153] - Accès à la page d'exploitation
2025-05-15 21:32:30,328 - app - INFO - [app.py:173] - Préparation de l'exploitation de ftp-vsftpd-backdoor sur 192.168.217.140:21
2025-05-15 21:42:47,903 - app - INFO - [app.py:43] - Création de l'application Flask
2025-05-15 21:42:47,921 - app - INFO - [app.py:265] - 🚀 Application démarrée sur http://0.0.0.0:5000
2025-05-15 21:46:12,664 - app - INFO - [app.py:43] - Création de l'application Flask
2025-05-15 21:46:12,686 - app - INFO - [app.py:265] - 🚀 Application démarrée sur http://0.0.0.0:5000
2025-05-15 21:49:43,358 - app - ERROR - [app.py:875] - Exception on /api/forensics/ [GET]
Traceback (most recent call last):
  File "/home/oebn/Projet-Scan/venv/lib/python3.11/site-packages/flask/app.py", line 1511, in wsgi_app
    response = self.full_dispatch_request()
               ^^^^^^^^^^^^^^^^^^^^^^^^^^^^
  File "/home/oebn/Projet-Scan/venv/lib/python3.11/site-packages/flask/app.py", line 919, in full_dispatch_request
    rv = self.handle_user_exception(e)
         ^^^^^^^^^^^^^^^^^^^^^^^^^^^^^
  File "/home/oebn/Projet-Scan/venv/lib/python3.11/site-packages/flask/app.py", line 917, in full_dispatch_request
    rv = self.dispatch_request()
         ^^^^^^^^^^^^^^^^^^^^^^^
  File "/home/oebn/Projet-Scan/venv/lib/python3.11/site-packages/flask/app.py", line 902, in dispatch_request
    return self.ensure_sync(self.view_functions[rule.endpoint])(**view_args)  # type: ignore[no-any-return]
           ^^^^^^^^^^^^^^^^^^^^^^^^^^^^^^^^^^^^^^^^^^^^^^^^^^^^^^^^^^^^^^^^^
  File "/home/oebn/Projet-Scan/securite/auth.py", line 60, in wrapper
    return f(*args, **kwargs)
           ^^^^^^^^^^^^^^^^^^
  File "/home/oebn/Projet-Scan/routes/forensics_routes.py", line 15, in analyser
    shutil.copy("forensics/memory_dump.encrypted", "static/forensics/memory_dump.encrypted")
  File "/usr/lib/python3.11/shutil.py", line 419, in copy
    copyfile(src, dst, follow_symlinks=follow_symlinks)
  File "/usr/lib/python3.11/shutil.py", line 256, in copyfile
    with open(src, 'rb') as fsrc:
         ^^^^^^^^^^^^^^^
FileNotFoundError: [Errno 2] No such file or directory: 'forensics/memory_dump.encrypted'
2025-05-15 21:53:38,559 - app - INFO - [app.py:43] - Création de l'application Flask
2025-05-15 21:53:38,597 - app - INFO - [app.py:265] - 🚀 Application démarrée sur http://0.0.0.0:5000
2025-05-15 21:58:12,882 - app - INFO - [app.py:43] - Création de l'application Flask
2025-05-15 21:58:12,907 - app - INFO - [app.py:265] - 🚀 Application démarrée sur http://0.0.0.0:5000
2025-05-22 23:48:14,196 - app - INFO - [app.py:47] - Création de l'application Flask
2025-05-22 23:48:14,231 - app - INFO - [app.py:288] - 🚀 Application démarrée sur http://0.0.0.0:5000
2025-05-22 23:51:58,536 - app - INFO - [app.py:47] - Création de l'application Flask
2025-05-22 23:51:58,578 - app - INFO - [app.py:288] - 🚀 Application démarrée sur http://0.0.0.0:5000
2025-05-23 00:01:35,673 - app - INFO - [app.py:159] - Accès à la page d'exploitation
2025-05-23 00:01:35,674 - app - INFO - [app.py:179] - Préparation de l'exploitation de ftp-vsftpd-backdoor sur 192.168.217.140:21
2025-05-23 00:02:36,130 - app - INFO - [app.py:47] - Création de l'application Flask
2025-05-23 00:02:36,149 - app - INFO - [app.py:288] - 🚀 Application démarrée sur http://0.0.0.0:5000
2025-05-23 00:10:49,942 - app - INFO - [app.py:47] - Création de l'application Flask
2025-05-23 00:10:49,967 - app - INFO - [app.py:288] - 🚀 Application démarrée sur http://0.0.0.0:5000
2025-05-23 00:13:55,619 - app - INFO - [app.py:47] - Création de l'application Flask
2025-05-23 00:13:55,639 - app - INFO - [app.py:288] - 🚀 Application démarrée sur http://0.0.0.0:5000
2025-05-27 03:31:59,131 - app - INFO - [app.py:47] - Création de l'application Flask
2025-05-27 03:31:59,140 - app - INFO - [app.py:288] - 🚀 Application démarrée sur http://0.0.0.0:5000
2025-05-27 03:41:59,694 - app - INFO - [app.py:47] - Création de l'application Flask
2025-05-27 03:41:59,705 - app - INFO - [app.py:288] - 🚀 Application démarrée sur http://0.0.0.0:5000
2025-05-27 04:08:47,993 - app - INFO - [app.py:47] - Création de l'application Flask
2025-05-27 04:08:48,005 - app - INFO - [app.py:288] - 🚀 Application démarrée sur http://0.0.0.0:5000
2025-05-27 04:09:21,458 - app - ERROR - [app.py:875] - Exception on /api/forensics/ [GET]
Traceback (most recent call last):
  File "/home/kali/Projet-Scan/venv/lib/python3.13/site-packages/flask/app.py", line 1511, in wsgi_app
    response = self.full_dispatch_request()
  File "/home/kali/Projet-Scan/venv/lib/python3.13/site-packages/flask/app.py", line 919, in full_dispatch_request
    rv = self.handle_user_exception(e)
  File "/home/kali/Projet-Scan/venv/lib/python3.13/site-packages/flask/app.py", line 917, in full_dispatch_request
    rv = self.dispatch_request()
  File "/home/kali/Projet-Scan/venv/lib/python3.13/site-packages/flask/app.py", line 902, in dispatch_request
    return self.ensure_sync(self.view_functions[rule.endpoint])(**view_args)  # type: ignore[no-any-return]
           ~~~~~~~~~~~~~~~~~~~~~~~~~~~~~~~~~~~~~~~~~~~~~~~~~~~~^^^^^^^^^^^^^
  File "/home/kali/Projet-Scan/securite/auth.py", line 60, in wrapper
    return f(*args, **kwargs)
  File "/home/kali/Projet-Scan/routes/forensics_routes.py", line 15, in analyser
    shutil.copy("forensics/memory_dump.encrypted", "static/forensics/memory_dump.encrypted")
    ~~~~~~~~~~~^^^^^^^^^^^^^^^^^^^^^^^^^^^^^^^^^^^^^^^^^^^^^^^^^^^^^^^^^^^^^^^^^^^^^^^^^^^^^
  File "/usr/lib/python3.13/shutil.py", line 428, in copy
    copyfile(src, dst, follow_symlinks=follow_symlinks)
    ~~~~~~~~^^^^^^^^^^^^^^^^^^^^^^^^^^^^^^^^^^^^^^^^^^^
  File "/usr/lib/python3.13/shutil.py", line 260, in copyfile
    with open(src, 'rb') as fsrc:
         ~~~~^^^^^^^^^^^
FileNotFoundError: [Errno 2] No such file or directory: 'forensics/memory_dump.encrypted'
2025-05-27 04:10:06,657 - app - INFO - [app.py:47] - Création de l'application Flask
2025-05-27 04:10:06,669 - app - INFO - [app.py:288] - 🚀 Application démarrée sur http://0.0.0.0:5000
2025-05-27 04:34:50,240 - app - INFO - [app.py:47] - Création de l'application Flask
2025-05-27 04:34:50,254 - app - INFO - [app.py:288] - 🚀 Application démarrée sur http://0.0.0.0:5000
2025-05-27 05:37:02,366 - app - INFO - [app.py:47] - Création de l'application Flask
2025-05-27 05:37:02,412 - app - INFO - [app.py:288] - 🚀 Application démarrée sur http://0.0.0.0:5000
2025-05-27 05:52:08,405 - app - INFO - [app.py:47] - Création de l'application Flask
2025-05-27 05:52:08,420 - app - INFO - [app.py:349] - 🚀 Application démarrée sur http://0.0.0.0:5000
2025-05-27 05:53:00,901 - app - INFO - [app.py:220] - Accès à la page d'exploitation
2025-05-27 05:53:00,903 - app - INFO - [app.py:240] - Préparation de l'exploitation de http-vuln-cve2017-1001000 sur 192.168.36.129:80
2025-05-27 05:58:32,909 - app - INFO - [app.py:220] - Accès à la page d'exploitation
2025-05-27 05:58:37,402 - app - INFO - [app.py:240] - Préparation de l'exploitation de http-vuln-cve2017-1001000 sur 192.168.36.129:80
2025-05-27 06:03:45,820 - app - INFO - [app.py:47] - Création de l'application Flask
2025-05-27 06:03:45,833 - app - INFO - [app.py:349] - 🚀 Application démarrée sur http://0.0.0.0:5000
2025-05-27 06:04:47,001 - app - INFO - [app.py:220] - Accès à la page d'exploitation
2025-05-27 06:04:47,001 - app - INFO - [app.py:240] - Préparation de l'exploitation de http-vuln-cve2017-1001000 sur 192.168.36.129:80
2025-05-27 06:10:31,859 - app - INFO - [app.py:47] - Création de l'application Flask
2025-05-27 06:10:31,872 - app - INFO - [app.py:349] - 🚀 Application démarrée sur http://0.0.0.0:5000
2025-05-27 06:20:45,476 - app - WARNING - [app.py:210] - Résultats de batch non trouvés: null
2025-05-27 06:30:55,560 - app - INFO - [app.py:47] - Création de l'application Flask
2025-05-27 06:30:55,573 - app - INFO - [app.py:369] - 🚀 Application démarrée sur http://0.0.0.0:5000
2025-05-27 06:36:03,263 - app - INFO - [app.py:47] - Création de l'application Flask
2025-05-27 06:36:03,278 - app - INFO - [app.py:369] - 🚀 Application démarrée sur http://0.0.0.0:5000
2025-05-27 06:39:05,821 - app - INFO - [app.py:240] - Accès à la page d'exploitation
2025-05-27 06:39:05,821 - app - INFO - [app.py:260] - Préparation de l'exploitation de http-phpself-xss sur 192.168.36.129:80
2025-05-27 06:52:40,410 - app - INFO - [app.py:47] - Création de l'application Flask
2025-05-27 06:52:40,424 - app - INFO - [app.py:369] - 🚀 Application démarrée sur http://0.0.0.0:5000
2025-05-27 06:55:50,076 - app - INFO - [app.py:47] - Création de l'application Flask
2025-05-27 06:55:50,088 - app - INFO - [app.py:369] - 🚀 Application démarrée sur http://0.0.0.0:5000
2025-05-27 06:55:58,587 - app - ERROR - [app.py:875] - Exception on /api/discover/ [POST]
Traceback (most recent call last):
  File "/home/kali/Projet-Scan/venv/lib/python3.13/site-packages/flask/app.py", line 1511, in wsgi_app
    response = self.full_dispatch_request()
  File "/home/kali/Projet-Scan/venv/lib/python3.13/site-packages/flask/app.py", line 919, in full_dispatch_request
    rv = self.handle_user_exception(e)
  File "/home/kali/Projet-Scan/venv/lib/python3.13/site-packages/flask/app.py", line 917, in full_dispatch_request
    rv = self.dispatch_request()
  File "/home/kali/Projet-Scan/venv/lib/python3.13/site-packages/flask/app.py", line 902, in dispatch_request
    return self.ensure_sync(self.view_functions[rule.endpoint])(**view_args)  # type: ignore[no-any-return]
           ~~~~~~~~~~~~~~~~~~~~~~~~~~~~~~~~~~~~~~~~~~~~~~~~~~~~^^^^^^^^^^^^^
  File "/home/kali/Projet-Scan/routes/discovery_routes.py", line 11, in discover
    return render_template("results.html", title="Découverte Réseau", result=result)
           ~~~~~~~~~~~~~~~^^^^^^^^^^^^^^^^^^^^^^^^^^^^^^^^^^^^^^^^^^^^^^^^^^^^^^^^^^
  File "/home/kali/Projet-Scan/venv/lib/python3.13/site-packages/flask/templating.py", line 149, in render_template
    template = app.jinja_env.get_or_select_template(template_name_or_list)
  File "/home/kali/Projet-Scan/venv/lib/python3.13/site-packages/jinja2/environment.py", line 1087, in get_or_select_template
    return self.get_template(template_name_or_list, parent, globals)
           ~~~~~~~~~~~~~~~~~^^^^^^^^^^^^^^^^^^^^^^^^^^^^^^^^^^^^^^^^
  File "/home/kali/Projet-Scan/venv/lib/python3.13/site-packages/jinja2/environment.py", line 1016, in get_template
    return self._load_template(name, globals)
           ~~~~~~~~~~~~~~~~~~~^^^^^^^^^^^^^^^
  File "/home/kali/Projet-Scan/venv/lib/python3.13/site-packages/jinja2/environment.py", line 975, in _load_template
    template = self.loader.load(self, name, self.make_globals(globals))
  File "/home/kali/Projet-Scan/venv/lib/python3.13/site-packages/jinja2/loaders.py", line 138, in load
    code = environment.compile(source, name, filename)
  File "/home/kali/Projet-Scan/venv/lib/python3.13/site-packages/jinja2/environment.py", line 771, in compile
    self.handle_exception(source=source_hint)
    ~~~~~~~~~~~~~~~~~~~~~^^^^^^^^^^^^^^^^^^^^
  File "/home/kali/Projet-Scan/venv/lib/python3.13/site-packages/jinja2/environment.py", line 942, in handle_exception
    raise rewrite_traceback_stack(source=source)
  File "/home/kali/Projet-Scan/templates/results.html", line 346, in template
    {{ item|safe|enhance_text }}
    ^^^^^^^^^^^^^
jinja2.exceptions.TemplateAssertionError: No filter named 'enhance_text'.
2025-05-27 06:56:37,696 - app - ERROR - [app.py:875] - Exception on /api/scan/ [POST]
Traceback (most recent call last):
  File "/home/kali/Projet-Scan/venv/lib/python3.13/site-packages/flask/app.py", line 1511, in wsgi_app
    response = self.full_dispatch_request()
  File "/home/kali/Projet-Scan/venv/lib/python3.13/site-packages/flask/app.py", line 919, in full_dispatch_request
    rv = self.handle_user_exception(e)
  File "/home/kali/Projet-Scan/venv/lib/python3.13/site-packages/flask/app.py", line 917, in full_dispatch_request
    rv = self.dispatch_request()
  File "/home/kali/Projet-Scan/venv/lib/python3.13/site-packages/flask/app.py", line 902, in dispatch_request
    return self.ensure_sync(self.view_functions[rule.endpoint])(**view_args)  # type: ignore[no-any-return]
           ~~~~~~~~~~~~~~~~~~~~~~~~~~~~~~~~~~~~~~~~~~~~~~~~~~~~^^^^^^^^^^^^^
  File "/home/kali/Projet-Scan/routes/scan_routes.py", line 12, in scan
    return render_template("results.html", title="Scan de Ports", result=result)
  File "/home/kali/Projet-Scan/venv/lib/python3.13/site-packages/flask/templating.py", line 149, in render_template
    template = app.jinja_env.get_or_select_template(template_name_or_list)
  File "/home/kali/Projet-Scan/venv/lib/python3.13/site-packages/jinja2/environment.py", line 1087, in get_or_select_template
    return self.get_template(template_name_or_list, parent, globals)
           ~~~~~~~~~~~~~~~~~^^^^^^^^^^^^^^^^^^^^^^^^^^^^^^^^^^^^^^^^
  File "/home/kali/Projet-Scan/venv/lib/python3.13/site-packages/jinja2/environment.py", line 1016, in get_template
    return self._load_template(name, globals)
           ~~~~~~~~~~~~~~~~~~~^^^^^^^^^^^^^^^
  File "/home/kali/Projet-Scan/venv/lib/python3.13/site-packages/jinja2/environment.py", line 975, in _load_template
    template = self.loader.load(self, name, self.make_globals(globals))
  File "/home/kali/Projet-Scan/venv/lib/python3.13/site-packages/jinja2/loaders.py", line 138, in load
    code = environment.compile(source, name, filename)
  File "/home/kali/Projet-Scan/venv/lib/python3.13/site-packages/jinja2/environment.py", line 771, in compile
    self.handle_exception(source=source_hint)
    ~~~~~~~~~~~~~~~~~~~~~^^^^^^^^^^^^^^^^^^^^
  File "/home/kali/Projet-Scan/venv/lib/python3.13/site-packages/jinja2/environment.py", line 942, in handle_exception
    raise rewrite_traceback_stack(source=source)
  File "/home/kali/Projet-Scan/templates/results.html", line 346, in template
    {{ item|safe|enhance_text }}
    ^^^^^^^^^^^^^
jinja2.exceptions.TemplateAssertionError: No filter named 'enhance_text'.
2025-05-27 06:56:40,757 - app - ERROR - [app.py:875] - Exception on /enumerate [GET]
Traceback (most recent call last):
  File "/home/kali/Projet-Scan/venv/lib/python3.13/site-packages/flask/app.py", line 1511, in wsgi_app
    response = self.full_dispatch_request()
  File "/home/kali/Projet-Scan/venv/lib/python3.13/site-packages/flask/app.py", line 919, in full_dispatch_request
    rv = self.handle_user_exception(e)
  File "/home/kali/Projet-Scan/venv/lib/python3.13/site-packages/flask/app.py", line 917, in full_dispatch_request
    rv = self.dispatch_request()
  File "/home/kali/Projet-Scan/venv/lib/python3.13/site-packages/flask/app.py", line 902, in dispatch_request
    return self.ensure_sync(self.view_functions[rule.endpoint])(**view_args)  # type: ignore[no-any-return]
           ~~~~~~~~~~~~~~~~~~~~~~~~~~~~~~~~~~~~~~~~~~~~~~~~~~~~^^^^^^^^^^^^^
  File "/home/kali/Projet-Scan/securite/auth.py", line 60, in wrapper
    return f(*args, **kwargs)
  File "/home/kali/Projet-Scan/app.py", line 133, in enumerate_page
    return render_template("enumerate.html")
  File "/home/kali/Projet-Scan/venv/lib/python3.13/site-packages/flask/templating.py", line 149, in render_template
    template = app.jinja_env.get_or_select_template(template_name_or_list)
  File "/home/kali/Projet-Scan/venv/lib/python3.13/site-packages/jinja2/environment.py", line 1087, in get_or_select_template
    return self.get_template(template_name_or_list, parent, globals)
           ~~~~~~~~~~~~~~~~~^^^^^^^^^^^^^^^^^^^^^^^^^^^^^^^^^^^^^^^^
  File "/home/kali/Projet-Scan/venv/lib/python3.13/site-packages/jinja2/environment.py", line 1016, in get_template
    return self._load_template(name, globals)
           ~~~~~~~~~~~~~~~~~~~^^^^^^^^^^^^^^^
  File "/home/kali/Projet-Scan/venv/lib/python3.13/site-packages/jinja2/environment.py", line 975, in _load_template
    template = self.loader.load(self, name, self.make_globals(globals))
  File "/home/kali/Projet-Scan/venv/lib/python3.13/site-packages/jinja2/loaders.py", line 138, in load
    code = environment.compile(source, name, filename)
  File "/home/kali/Projet-Scan/venv/lib/python3.13/site-packages/jinja2/environment.py", line 771, in compile
    self.handle_exception(source=source_hint)
    ~~~~~~~~~~~~~~~~~~~~~^^^^^^^^^^^^^^^^^^^^
  File "/home/kali/Projet-Scan/venv/lib/python3.13/site-packages/jinja2/environment.py", line 942, in handle_exception
    raise rewrite_traceback_stack(source=source)
  File "/home/kali/Projet-Scan/templates/enumerate.html", line 337, in template
    {% block content %}
jinja2.exceptions.TemplateSyntaxError: Unexpected end of template. Jinja was looking for the following tags: 'endblock'. The innermost block that needs to be closed is 'block'.
2025-05-27 06:56:52,317 - app - ERROR - [app.py:875] - Exception on /enumerate [GET]
Traceback (most recent call last):
  File "/home/kali/Projet-Scan/venv/lib/python3.13/site-packages/flask/app.py", line 1511, in wsgi_app
    response = self.full_dispatch_request()
  File "/home/kali/Projet-Scan/venv/lib/python3.13/site-packages/flask/app.py", line 919, in full_dispatch_request
    rv = self.handle_user_exception(e)
  File "/home/kali/Projet-Scan/venv/lib/python3.13/site-packages/flask/app.py", line 917, in full_dispatch_request
    rv = self.dispatch_request()
  File "/home/kali/Projet-Scan/venv/lib/python3.13/site-packages/flask/app.py", line 902, in dispatch_request
    return self.ensure_sync(self.view_functions[rule.endpoint])(**view_args)  # type: ignore[no-any-return]
           ~~~~~~~~~~~~~~~~~~~~~~~~~~~~~~~~~~~~~~~~~~~~~~~~~~~~^^^^^^^^^^^^^
  File "/home/kali/Projet-Scan/securite/auth.py", line 60, in wrapper
    return f(*args, **kwargs)
  File "/home/kali/Projet-Scan/app.py", line 133, in enumerate_page
    return render_template("enumerate.html")
  File "/home/kali/Projet-Scan/venv/lib/python3.13/site-packages/flask/templating.py", line 149, in render_template
    template = app.jinja_env.get_or_select_template(template_name_or_list)
  File "/home/kali/Projet-Scan/venv/lib/python3.13/site-packages/jinja2/environment.py", line 1087, in get_or_select_template
    return self.get_template(template_name_or_list, parent, globals)
           ~~~~~~~~~~~~~~~~~^^^^^^^^^^^^^^^^^^^^^^^^^^^^^^^^^^^^^^^^
  File "/home/kali/Projet-Scan/venv/lib/python3.13/site-packages/jinja2/environment.py", line 1016, in get_template
    return self._load_template(name, globals)
           ~~~~~~~~~~~~~~~~~~~^^^^^^^^^^^^^^^
  File "/home/kali/Projet-Scan/venv/lib/python3.13/site-packages/jinja2/environment.py", line 975, in _load_template
    template = self.loader.load(self, name, self.make_globals(globals))
  File "/home/kali/Projet-Scan/venv/lib/python3.13/site-packages/jinja2/loaders.py", line 138, in load
    code = environment.compile(source, name, filename)
  File "/home/kali/Projet-Scan/venv/lib/python3.13/site-packages/jinja2/environment.py", line 771, in compile
    self.handle_exception(source=source_hint)
    ~~~~~~~~~~~~~~~~~~~~~^^^^^^^^^^^^^^^^^^^^
  File "/home/kali/Projet-Scan/venv/lib/python3.13/site-packages/jinja2/environment.py", line 942, in handle_exception
    raise rewrite_traceback_stack(source=source)
  File "/home/kali/Projet-Scan/templates/enumerate.html", line 337, in template
    {% block content %}
jinja2.exceptions.TemplateSyntaxError: Unexpected end of template. Jinja was looking for the following tags: 'endblock'. The innermost block that needs to be closed is 'block'.
2025-05-27 06:57:54,982 - app - INFO - [app.py:47] - Création de l'application Flask
2025-05-27 06:57:54,995 - app - INFO - [app.py:369] - 🚀 Application démarrée sur http://0.0.0.0:5000
2025-05-27 06:57:58,178 - app - ERROR - [app.py:875] - Exception on /enumerate [GET]
Traceback (most recent call last):
  File "/home/kali/Projet-Scan/venv/lib/python3.13/site-packages/flask/app.py", line 1511, in wsgi_app
    response = self.full_dispatch_request()
  File "/home/kali/Projet-Scan/venv/lib/python3.13/site-packages/flask/app.py", line 919, in full_dispatch_request
    rv = self.handle_user_exception(e)
  File "/home/kali/Projet-Scan/venv/lib/python3.13/site-packages/flask/app.py", line 917, in full_dispatch_request
    rv = self.dispatch_request()
  File "/home/kali/Projet-Scan/venv/lib/python3.13/site-packages/flask/app.py", line 902, in dispatch_request
    return self.ensure_sync(self.view_functions[rule.endpoint])(**view_args)  # type: ignore[no-any-return]
           ~~~~~~~~~~~~~~~~~~~~~~~~~~~~~~~~~~~~~~~~~~~~~~~~~~~~^^^^^^^^^^^^^
  File "/home/kali/Projet-Scan/securite/auth.py", line 60, in wrapper
    return f(*args, **kwargs)
  File "/home/kali/Projet-Scan/app.py", line 133, in enumerate_page
    return render_template("enumerate.html")
  File "/home/kali/Projet-Scan/venv/lib/python3.13/site-packages/flask/templating.py", line 149, in render_template
    template = app.jinja_env.get_or_select_template(template_name_or_list)
  File "/home/kali/Projet-Scan/venv/lib/python3.13/site-packages/jinja2/environment.py", line 1087, in get_or_select_template
    return self.get_template(template_name_or_list, parent, globals)
           ~~~~~~~~~~~~~~~~~^^^^^^^^^^^^^^^^^^^^^^^^^^^^^^^^^^^^^^^^
  File "/home/kali/Projet-Scan/venv/lib/python3.13/site-packages/jinja2/environment.py", line 1016, in get_template
    return self._load_template(name, globals)
           ~~~~~~~~~~~~~~~~~~~^^^^^^^^^^^^^^^
  File "/home/kali/Projet-Scan/venv/lib/python3.13/site-packages/jinja2/environment.py", line 975, in _load_template
    template = self.loader.load(self, name, self.make_globals(globals))
  File "/home/kali/Projet-Scan/venv/lib/python3.13/site-packages/jinja2/loaders.py", line 138, in load
    code = environment.compile(source, name, filename)
  File "/home/kali/Projet-Scan/venv/lib/python3.13/site-packages/jinja2/environment.py", line 771, in compile
    self.handle_exception(source=source_hint)
    ~~~~~~~~~~~~~~~~~~~~~^^^^^^^^^^^^^^^^^^^^
  File "/home/kali/Projet-Scan/venv/lib/python3.13/site-packages/jinja2/environment.py", line 942, in handle_exception
    raise rewrite_traceback_stack(source=source)
  File "/home/kali/Projet-Scan/templates/enumerate.html", line 337, in template
    {% block content %}
jinja2.exceptions.TemplateSyntaxError: Unexpected end of template. Jinja was looking for the following tags: 'endblock'. The innermost block that needs to be closed is 'block'.
2025-05-27 07:00:12,633 - app - INFO - [app.py:47] - Création de l'application Flask
2025-05-27 07:00:12,646 - app - INFO - [app.py:369] - 🚀 Application démarrée sur http://0.0.0.0:5000
2025-05-27 07:01:19,975 - app - ERROR - [app.py:875] - Exception on /enumerate [GET]
Traceback (most recent call last):
  File "/home/kali/Projet-Scan/venv/lib/python3.13/site-packages/flask/app.py", line 1511, in wsgi_app
    response = self.full_dispatch_request()
  File "/home/kali/Projet-Scan/venv/lib/python3.13/site-packages/flask/app.py", line 919, in full_dispatch_request
    rv = self.handle_user_exception(e)
  File "/home/kali/Projet-Scan/venv/lib/python3.13/site-packages/flask/app.py", line 917, in full_dispatch_request
    rv = self.dispatch_request()
  File "/home/kali/Projet-Scan/venv/lib/python3.13/site-packages/flask/app.py", line 902, in dispatch_request
    return self.ensure_sync(self.view_functions[rule.endpoint])(**view_args)  # type: ignore[no-any-return]
           ~~~~~~~~~~~~~~~~~~~~~~~~~~~~~~~~~~~~~~~~~~~~~~~~~~~~^^^^^^^^^^^^^
  File "/home/kali/Projet-Scan/securite/auth.py", line 60, in wrapper
    return f(*args, **kwargs)
  File "/home/kali/Projet-Scan/app.py", line 133, in enumerate_page
    return render_template("enumerate.html")
  File "/home/kali/Projet-Scan/venv/lib/python3.13/site-packages/flask/templating.py", line 149, in render_template
    template = app.jinja_env.get_or_select_template(template_name_or_list)
  File "/home/kali/Projet-Scan/venv/lib/python3.13/site-packages/jinja2/environment.py", line 1087, in get_or_select_template
    return self.get_template(template_name_or_list, parent, globals)
           ~~~~~~~~~~~~~~~~~^^^^^^^^^^^^^^^^^^^^^^^^^^^^^^^^^^^^^^^^
  File "/home/kali/Projet-Scan/venv/lib/python3.13/site-packages/jinja2/environment.py", line 1016, in get_template
    return self._load_template(name, globals)
           ~~~~~~~~~~~~~~~~~~~^^^^^^^^^^^^^^^
  File "/home/kali/Projet-Scan/venv/lib/python3.13/site-packages/jinja2/environment.py", line 975, in _load_template
    template = self.loader.load(self, name, self.make_globals(globals))
  File "/home/kali/Projet-Scan/venv/lib/python3.13/site-packages/jinja2/loaders.py", line 138, in load
    code = environment.compile(source, name, filename)
  File "/home/kali/Projet-Scan/venv/lib/python3.13/site-packages/jinja2/environment.py", line 771, in compile
    self.handle_exception(source=source_hint)
    ~~~~~~~~~~~~~~~~~~~~~^^^^^^^^^^^^^^^^^^^^
  File "/home/kali/Projet-Scan/venv/lib/python3.13/site-packages/jinja2/environment.py", line 942, in handle_exception
    raise rewrite_traceback_stack(source=source)
  File "/home/kali/Projet-Scan/templates/enumerate.html", line 337, in template
    {% block content %}
jinja2.exceptions.TemplateSyntaxError: Unexpected end of template. Jinja was looking for the following tags: 'endblock'. The innermost block that needs to be closed is 'block'.
2025-05-27 07:01:42,438 - app - ERROR - [app.py:875] - Exception on /enumerate [GET]
Traceback (most recent call last):
  File "/home/kali/Projet-Scan/venv/lib/python3.13/site-packages/flask/app.py", line 1511, in wsgi_app
    response = self.full_dispatch_request()
  File "/home/kali/Projet-Scan/venv/lib/python3.13/site-packages/flask/app.py", line 919, in full_dispatch_request
    rv = self.handle_user_exception(e)
  File "/home/kali/Projet-Scan/venv/lib/python3.13/site-packages/flask/app.py", line 917, in full_dispatch_request
    rv = self.dispatch_request()
  File "/home/kali/Projet-Scan/venv/lib/python3.13/site-packages/flask/app.py", line 902, in dispatch_request
    return self.ensure_sync(self.view_functions[rule.endpoint])(**view_args)  # type: ignore[no-any-return]
           ~~~~~~~~~~~~~~~~~~~~~~~~~~~~~~~~~~~~~~~~~~~~~~~~~~~~^^^^^^^^^^^^^
  File "/home/kali/Projet-Scan/securite/auth.py", line 60, in wrapper
    return f(*args, **kwargs)
  File "/home/kali/Projet-Scan/app.py", line 133, in enumerate_page
    return render_template("enumerate.html")
  File "/home/kali/Projet-Scan/venv/lib/python3.13/site-packages/flask/templating.py", line 149, in render_template
    template = app.jinja_env.get_or_select_template(template_name_or_list)
  File "/home/kali/Projet-Scan/venv/lib/python3.13/site-packages/jinja2/environment.py", line 1087, in get_or_select_template
    return self.get_template(template_name_or_list, parent, globals)
           ~~~~~~~~~~~~~~~~~^^^^^^^^^^^^^^^^^^^^^^^^^^^^^^^^^^^^^^^^
  File "/home/kali/Projet-Scan/venv/lib/python3.13/site-packages/jinja2/environment.py", line 1016, in get_template
    return self._load_template(name, globals)
           ~~~~~~~~~~~~~~~~~~~^^^^^^^^^^^^^^^
  File "/home/kali/Projet-Scan/venv/lib/python3.13/site-packages/jinja2/environment.py", line 975, in _load_template
    template = self.loader.load(self, name, self.make_globals(globals))
  File "/home/kali/Projet-Scan/venv/lib/python3.13/site-packages/jinja2/loaders.py", line 138, in load
    code = environment.compile(source, name, filename)
  File "/home/kali/Projet-Scan/venv/lib/python3.13/site-packages/jinja2/environment.py", line 771, in compile
    self.handle_exception(source=source_hint)
    ~~~~~~~~~~~~~~~~~~~~~^^^^^^^^^^^^^^^^^^^^
  File "/home/kali/Projet-Scan/venv/lib/python3.13/site-packages/jinja2/environment.py", line 942, in handle_exception
    raise rewrite_traceback_stack(source=source)
  File "/home/kali/Projet-Scan/templates/enumerate.html", line 337, in template
    {% block content %}
jinja2.exceptions.TemplateSyntaxError: Unexpected end of template. Jinja was looking for the following tags: 'endblock'. The innermost block that needs to be closed is 'block'.
2025-05-28 09:00:18,399 - app - INFO - [app.py:47] - Création de l'application Flask
2025-05-28 09:00:18,454 - app - INFO - [app.py:369] - 🚀 Application démarrée sur http://0.0.0.0:5000
2025-05-28 09:03:54,068 - app - INFO - [app.py:240] - Accès à la page d'exploitation
2025-05-28 09:03:54,068 - app - INFO - [app.py:260] - Préparation de l'exploitation de ftp-vsftpd-backdoor sur 192.168.36.132:21
2025-05-28 09:05:14,754 - app - INFO - [app.py:47] - Création de l'application Flask
2025-05-28 09:05:14,768 - app - INFO - [app.py:369] - 🚀 Application démarrée sur http://0.0.0.0:5000
2025-05-28 09:07:35,676 - app - INFO - [app.py:47] - Création de l'application Flask
2025-05-28 09:07:35,692 - app - INFO - [app.py:369] - 🚀 Application démarrée sur http://0.0.0.0:5000
2025-05-28 09:07:52,436 - app - INFO - [app.py:47] - Création de l'application Flask
2025-05-28 09:07:52,452 - app - INFO - [app.py:369] - 🚀 Application démarrée sur http://0.0.0.0:5000
2025-05-28 09:09:13,929 - app - INFO - [app.py:47] - Création de l'application Flask
2025-05-28 09:09:13,961 - app - INFO - [app.py:369] - 🚀 Application démarrée sur http://0.0.0.0:5000
2025-05-28 09:24:04,720 - app - INFO - [app.py:47] - Création de l'application Flask
2025-05-28 09:24:04,745 - app - INFO - [app.py:369] - 🚀 Application démarrée sur http://0.0.0.0:5000
2025-05-28 09:27:15,063 - app - INFO - [app.py:47] - Création de l'application Flask
2025-05-28 09:27:15,080 - app - INFO - [app.py:369] - 🚀 Application démarrée sur http://0.0.0.0:5000
2025-05-28 09:32:15,300 - app - INFO - [app.py:240] - Accès à la page d'exploitation
2025-05-28 09:32:15,300 - app - INFO - [app.py:260] - Préparation de l'exploitation de ftp-vsftpd-backdoor sur 192.168.36.132:21
2025-05-28 09:55:06,704 - app - INFO - [app.py:47] - Création de l'application Flask
2025-05-28 09:55:06,719 - app - INFO - [app.py:369] - 🚀 Application démarrée sur http://0.0.0.0:5000
2025-05-28 10:07:09,574 - app - INFO - [app.py:47] - Création de l'application Flask
2025-05-28 10:07:09,590 - app - INFO - [app.py:369] - 🚀 Application démarrée sur http://0.0.0.0:5000
2025-05-28 10:15:43,623 - app - INFO - [app.py:47] - Création de l'application Flask
2025-05-28 10:15:43,640 - app - INFO - [app.py:369] - 🚀 Application démarrée sur http://0.0.0.0:5000
2025-05-28 10:26:28,280 - app - INFO - [app.py:47] - Création de l'application Flask
2025-05-28 10:26:28,298 - app - INFO - [app.py:369] - 🚀 Application démarrée sur http://0.0.0.0:5000
2025-05-30 05:56:39,681 - app - INFO - [app.py:47] - Création de l'application Flask
2025-05-30 05:56:39,696 - app - INFO - [app.py:369] - 🚀 Application démarrée sur http://0.0.0.0:5000
2025-05-30 06:03:01,282 - app - INFO - [app.py:240] - Accès à la page d'exploitation
2025-05-30 06:03:01,282 - app - INFO - [app.py:260] - Préparation de l'exploitation de ftp-vsftpd-backdoor sur 192.168.36.132:21
2025-05-30 06:04:43,241 - app - INFO - [app.py:47] - Création de l'application Flask
2025-05-30 06:04:43,256 - app - INFO - [app.py:369] - 🚀 Application démarrée sur http://0.0.0.0:5000
2025-05-30 06:04:46,032 - app - INFO - [app.py:240] - Accès à la page d'exploitation
2025-05-30 06:04:46,033 - app - INFO - [app.py:260] - Préparation de l'exploitation de ftp-vsftpd-backdoor sur 192.168.36.132:21
2025-05-30 06:07:19,398 - app - INFO - [app.py:47] - Création de l'application Flask
2025-05-30 06:07:19,415 - app - INFO - [app.py:369] - 🚀 Application démarrée sur http://0.0.0.0:5000
2025-05-30 06:07:44,152 - app - INFO - [app.py:240] - Accès à la page d'exploitation
2025-05-30 06:07:44,153 - app - INFO - [app.py:260] - Préparation de l'exploitation de ftp-vsftpd-backdoor sur 192.168.36.132:21
2025-05-30 06:54:19,389 - app - INFO - [app.py:48] - Création de l'application Flask
2025-05-30 06:54:19,520 - app - INFO - [app.py:371] - 🚀 Application démarrée sur http://0.0.0.0:5000
2025-05-30 07:00:53,660 - app - INFO - [app.py:48] - Création de l'application Flask
2025-05-30 07:00:53,678 - app - INFO - [app.py:371] - 🚀 Application démarrée sur http://0.0.0.0:5000
2025-05-30 07:01:01,526 - app - ERROR - [app.py:875] - Exception on /nuclei/ [GET]
Traceback (most recent call last):
  File "/home/kali/Projet-Scan/routes/nuclei_routes.py", line 21, in index
    return render_template(
        'nuclei_simple.html',  # Utiliser le template simplifié
    ...<2 lines>...
        templates=templates
    )
  File "/home/kali/Projet-Scan/venv/lib/python3.13/site-packages/flask/templating.py", line 149, in render_template
    template = app.jinja_env.get_or_select_template(template_name_or_list)
  File "/home/kali/Projet-Scan/venv/lib/python3.13/site-packages/jinja2/environment.py", line 1087, in get_or_select_template
    return self.get_template(template_name_or_list, parent, globals)
           ~~~~~~~~~~~~~~~~~^^^^^^^^^^^^^^^^^^^^^^^^^^^^^^^^^^^^^^^^
  File "/home/kali/Projet-Scan/venv/lib/python3.13/site-packages/jinja2/environment.py", line 1016, in get_template
    return self._load_template(name, globals)
           ~~~~~~~~~~~~~~~~~~~^^^^^^^^^^^^^^^
  File "/home/kali/Projet-Scan/venv/lib/python3.13/site-packages/jinja2/environment.py", line 975, in _load_template
    template = self.loader.load(self, name, self.make_globals(globals))
  File "/home/kali/Projet-Scan/venv/lib/python3.13/site-packages/jinja2/loaders.py", line 126, in load
    source, filename, uptodate = self.get_source(environment, name)
                                 ~~~~~~~~~~~~~~~^^^^^^^^^^^^^^^^^^^
  File "/home/kali/Projet-Scan/venv/lib/python3.13/site-packages/flask/templating.py", line 65, in get_source
    return self._get_source_fast(environment, template)
           ~~~~~~~~~~~~~~~~~~~~~^^^^^^^^^^^^^^^^^^^^^^^
  File "/home/kali/Projet-Scan/venv/lib/python3.13/site-packages/flask/templating.py", line 99, in _get_source_fast
    raise TemplateNotFound(template)
jinja2.exceptions.TemplateNotFound: nuclei_simple.html

During handling of the above exception, another exception occurred:

Traceback (most recent call last):
  File "/home/kali/Projet-Scan/venv/lib/python3.13/site-packages/flask/app.py", line 1511, in wsgi_app
    response = self.full_dispatch_request()
  File "/home/kali/Projet-Scan/venv/lib/python3.13/site-packages/flask/app.py", line 919, in full_dispatch_request
    rv = self.handle_user_exception(e)
  File "/home/kali/Projet-Scan/venv/lib/python3.13/site-packages/flask/app.py", line 917, in full_dispatch_request
    rv = self.dispatch_request()
  File "/home/kali/Projet-Scan/venv/lib/python3.13/site-packages/flask/app.py", line 902, in dispatch_request
    return self.ensure_sync(self.view_functions[rule.endpoint])(**view_args)  # type: ignore[no-any-return]
           ~~~~~~~~~~~~~~~~~~~~~~~~~~~~~~~~~~~~~~~~~~~~~~~~~~~~^^^^^^^^^^^^^
  File "/home/kali/Projet-Scan/routes/nuclei_routes.py", line 30, in index
    return render_template('nuclei_simple.html', nuclei_available=False)
  File "/home/kali/Projet-Scan/venv/lib/python3.13/site-packages/flask/templating.py", line 149, in render_template
    template = app.jinja_env.get_or_select_template(template_name_or_list)
  File "/home/kali/Projet-Scan/venv/lib/python3.13/site-packages/jinja2/environment.py", line 1087, in get_or_select_template
    return self.get_template(template_name_or_list, parent, globals)
           ~~~~~~~~~~~~~~~~~^^^^^^^^^^^^^^^^^^^^^^^^^^^^^^^^^^^^^^^^
  File "/home/kali/Projet-Scan/venv/lib/python3.13/site-packages/jinja2/environment.py", line 1016, in get_template
    return self._load_template(name, globals)
           ~~~~~~~~~~~~~~~~~~~^^^^^^^^^^^^^^^
  File "/home/kali/Projet-Scan/venv/lib/python3.13/site-packages/jinja2/environment.py", line 975, in _load_template
    template = self.loader.load(self, name, self.make_globals(globals))
  File "/home/kali/Projet-Scan/venv/lib/python3.13/site-packages/jinja2/loaders.py", line 126, in load
    source, filename, uptodate = self.get_source(environment, name)
                                 ~~~~~~~~~~~~~~~^^^^^^^^^^^^^^^^^^^
  File "/home/kali/Projet-Scan/venv/lib/python3.13/site-packages/flask/templating.py", line 65, in get_source
    return self._get_source_fast(environment, template)
           ~~~~~~~~~~~~~~~~~~~~~^^^^^^^^^^^^^^^^^^^^^^^
  File "/home/kali/Projet-Scan/venv/lib/python3.13/site-packages/flask/templating.py", line 99, in _get_source_fast
    raise TemplateNotFound(template)
jinja2.exceptions.TemplateNotFound: nuclei_simple.html
2025-05-30 07:03:18,131 - app - INFO - [app.py:48] - Création de l'application Flask
2025-05-30 07:03:18,153 - app - INFO - [app.py:371] - 🚀 Application démarrée sur http://0.0.0.0:5000
2025-05-30 07:04:32,102 - app - INFO - [app.py:48] - Création de l'application Flask
2025-05-30 07:04:32,119 - app - INFO - [app.py:371] - 🚀 Application démarrée sur http://0.0.0.0:5000
2025-05-30 07:05:27,773 - app - INFO - [app.py:48] - Création de l'application Flask
2025-05-30 07:05:27,791 - app - INFO - [app.py:371] - 🚀 Application démarrée sur http://0.0.0.0:5000
2025-05-30 07:17:15,859 - app - INFO - [app.py:48] - Création de l'application Flask
2025-05-30 07:17:15,877 - app - INFO - [app.py:371] - 🚀 Application démarrée sur http://0.0.0.0:5000
2025-05-30 07:24:07,459 - app - INFO - [app.py:48] - Création de l'application Flask
2025-05-30 07:24:07,475 - app - INFO - [app.py:371] - 🚀 Application démarrée sur http://0.0.0.0:5000
2025-05-30 08:37:48,487 - app - INFO - [app.py:48] - Création de l'application Flask
2025-05-30 08:37:48,504 - app - INFO - [app.py:371] - 🚀 Application démarrée sur http://0.0.0.0:5000
2025-05-30 08:38:39,807 - app - INFO - [app.py:48] - Création de l'application Flask
2025-05-30 08:38:39,828 - app - INFO - [app.py:371] - 🚀 Application démarrée sur http://0.0.0.0:5000
2025-05-30 08:44:18,133 - app - INFO - [app.py:48] - Création de l'application Flask
2025-05-30 08:44:18,150 - app - INFO - [app.py:371] - 🚀 Application démarrée sur http://0.0.0.0:5000
2025-05-30 09:01:24,419 - app - INFO - [app.py:48] - Création de l'application Flask
2025-05-30 09:01:24,437 - app - INFO - [app.py:371] - 🚀 Application démarrée sur http://0.0.0.0:5000
2025-05-30 09:05:02,722 - app - INFO - [app.py:48] - Création de l'application Flask
2025-05-30 09:05:02,740 - app - INFO - [app.py:371] - 🚀 Application démarrée sur http://0.0.0.0:5000
2025-05-30 09:11:27,042 - app - INFO - [app.py:48] - Création de l'application Flask
2025-05-30 09:11:27,060 - app - INFO - [app.py:371] - 🚀 Application démarrée sur http://0.0.0.0:5000
2025-05-30 09:12:42,334 - app - INFO - [app.py:48] - Création de l'application Flask
2025-05-30 09:12:42,351 - app - INFO - [app.py:371] - 🚀 Application démarrée sur http://0.0.0.0:5000
2025-05-30 09:17:10,418 - app - INFO - [app.py:48] - Création de l'application Flask
2025-05-30 09:17:10,437 - app - INFO - [app.py:371] - 🚀 Application démarrée sur http://0.0.0.0:5000
2025-05-30 09:34:11,437 - app - INFO - [app.py:48] - Création de l'application Flask
2025-05-30 09:34:11,457 - app - INFO - [app.py:371] - 🚀 Application démarrée sur http://0.0.0.0:5000
2025-05-30 09:39:40,605 - app - INFO - [app.py:48] - Création de l'application Flask
2025-05-30 09:39:40,625 - app - INFO - [app.py:371] - 🚀 Application démarrée sur http://0.0.0.0:5000
