2025-05-08 15:15:32,703 - exploit_routes - ERROR - [exploit_routes.py:80] - Erreur lors de la récupération des rapports: exploit_reports.html
Traceback (most recent call last):
  File "/home/oebn/toolbox/routes/exploit_routes.py", line 78, in list_reports
    return render_template("exploit_reports.html", reports=reports)
           ^^^^^^^^^^^^^^^^^^^^^^^^^^^^^^^^^^^^^^^^^^^^^^^^^^^^^^^^
  File "/usr/local/lib/python3.11/dist-packages/flask/templating.py", line 149, in render_template
    template = app.jinja_env.get_or_select_template(template_name_or_list)
               ^^^^^^^^^^^^^^^^^^^^^^^^^^^^^^^^^^^^^^^^^^^^^^^^^^^^^^^^^^^
  File "/usr/local/lib/python3.11/dist-packages/jinja2/environment.py", line 1087, in get_or_select_template
    return self.get_template(template_name_or_list, parent, globals)
           ^^^^^^^^^^^^^^^^^^^^^^^^^^^^^^^^^^^^^^^^^^^^^^^^^^^^^^^^^
  File "/usr/local/lib/python3.11/dist-packages/jinja2/environment.py", line 1016, in get_template
    return self._load_template(name, globals)
           ^^^^^^^^^^^^^^^^^^^^^^^^^^^^^^^^^^
  File "/usr/local/lib/python3.11/dist-packages/jinja2/environment.py", line 975, in _load_template
    template = self.loader.load(self, name, self.make_globals(globals))
               ^^^^^^^^^^^^^^^^^^^^^^^^^^^^^^^^^^^^^^^^^^^^^^^^^^^^^^^^
  File "/usr/local/lib/python3.11/dist-packages/jinja2/loaders.py", line 126, in load
    source, filename, uptodate = self.get_source(environment, name)
                                 ^^^^^^^^^^^^^^^^^^^^^^^^^^^^^^^^^^
  File "/usr/local/lib/python3.11/dist-packages/flask/templating.py", line 65, in get_source
    return self._get_source_fast(environment, template)
           ^^^^^^^^^^^^^^^^^^^^^^^^^^^^^^^^^^^^^^^^^^^^
  File "/usr/local/lib/python3.11/dist-packages/flask/templating.py", line 99, in _get_source_fast
    raise TemplateNotFound(template)
jinja2.exceptions.TemplateNotFound: exploit_reports.html
2025-05-08 15:15:42,200 - exploit_routes - ERROR - [exploit_routes.py:80] - Erreur lors de la récupération des rapports: exploit_reports.html
Traceback (most recent call last):
  File "/home/oebn/toolbox/routes/exploit_routes.py", line 78, in list_reports
    return render_template("exploit_reports.html", reports=reports)
           ^^^^^^^^^^^^^^^^^^^^^^^^^^^^^^^^^^^^^^^^^^^^^^^^^^^^^^^^
  File "/usr/local/lib/python3.11/dist-packages/flask/templating.py", line 149, in render_template
    template = app.jinja_env.get_or_select_template(template_name_or_list)
               ^^^^^^^^^^^^^^^^^^^^^^^^^^^^^^^^^^^^^^^^^^^^^^^^^^^^^^^^^^^
  File "/usr/local/lib/python3.11/dist-packages/jinja2/environment.py", line 1087, in get_or_select_template
    return self.get_template(template_name_or_list, parent, globals)
           ^^^^^^^^^^^^^^^^^^^^^^^^^^^^^^^^^^^^^^^^^^^^^^^^^^^^^^^^^
  File "/usr/local/lib/python3.11/dist-packages/jinja2/environment.py", line 1016, in get_template
    return self._load_template(name, globals)
           ^^^^^^^^^^^^^^^^^^^^^^^^^^^^^^^^^^
  File "/usr/local/lib/python3.11/dist-packages/jinja2/environment.py", line 975, in _load_template
    template = self.loader.load(self, name, self.make_globals(globals))
               ^^^^^^^^^^^^^^^^^^^^^^^^^^^^^^^^^^^^^^^^^^^^^^^^^^^^^^^^
  File "/usr/local/lib/python3.11/dist-packages/jinja2/loaders.py", line 126, in load
    source, filename, uptodate = self.get_source(environment, name)
                                 ^^^^^^^^^^^^^^^^^^^^^^^^^^^^^^^^^^
  File "/usr/local/lib/python3.11/dist-packages/flask/templating.py", line 65, in get_source
    return self._get_source_fast(environment, template)
           ^^^^^^^^^^^^^^^^^^^^^^^^^^^^^^^^^^^^^^^^^^^^
  File "/usr/local/lib/python3.11/dist-packages/flask/templating.py", line 99, in _get_source_fast
    raise TemplateNotFound(template)
jinja2.exceptions.TemplateNotFound: exploit_reports.html
2025-05-08 17:38:43,740 - exploit_routes - INFO - [exploit_routes.py:153] - Vérification de l'exploitabilité de: ssl-ccs-injection
2025-05-08 17:38:43,743 - exploit_routes - INFO - [exploit_routes.py:160] - Module trouvé pour ssl-ccs-injection: auxiliary/scanner/ssl/openssl_ccs
2025-05-08 17:38:58,371 - exploit_routes - INFO - [exploit_routes.py:23] - Requête reçue pour lancer un exploit
2025-05-08 17:42:57,247 - exploit_routes - INFO - [exploit_routes.py:88] - Accès à la liste des rapports d'exploitation
2025-05-08 17:42:57,257 - exploit_routes - ERROR - [exploit_routes.py:98] - Erreur lors de la récupération des rapports: exploit_reports.html
Traceback (most recent call last):
  File "/home/oebn/toolbox/routes/exploit_routes.py", line 96, in list_reports
    return render_template("exploit_reports.html", reports=reports)
           ^^^^^^^^^^^^^^^^^^^^^^^^^^^^^^^^^^^^^^^^^^^^^^^^^^^^^^^^
  File "/usr/local/lib/python3.11/dist-packages/flask/templating.py", line 149, in render_template
    template = app.jinja_env.get_or_select_template(template_name_or_list)
               ^^^^^^^^^^^^^^^^^^^^^^^^^^^^^^^^^^^^^^^^^^^^^^^^^^^^^^^^^^^
  File "/usr/local/lib/python3.11/dist-packages/jinja2/environment.py", line 1087, in get_or_select_template
    return self.get_template(template_name_or_list, parent, globals)
           ^^^^^^^^^^^^^^^^^^^^^^^^^^^^^^^^^^^^^^^^^^^^^^^^^^^^^^^^^
  File "/usr/local/lib/python3.11/dist-packages/jinja2/environment.py", line 1016, in get_template
    return self._load_template(name, globals)
           ^^^^^^^^^^^^^^^^^^^^^^^^^^^^^^^^^^
  File "/usr/local/lib/python3.11/dist-packages/jinja2/environment.py", line 975, in _load_template
    template = self.loader.load(self, name, self.make_globals(globals))
               ^^^^^^^^^^^^^^^^^^^^^^^^^^^^^^^^^^^^^^^^^^^^^^^^^^^^^^^^
  File "/usr/local/lib/python3.11/dist-packages/jinja2/loaders.py", line 126, in load
    source, filename, uptodate = self.get_source(environment, name)
                                 ^^^^^^^^^^^^^^^^^^^^^^^^^^^^^^^^^^
  File "/usr/local/lib/python3.11/dist-packages/flask/templating.py", line 65, in get_source
    return self._get_source_fast(environment, template)
           ^^^^^^^^^^^^^^^^^^^^^^^^^^^^^^^^^^^^^^^^^^^^
  File "/usr/local/lib/python3.11/dist-packages/flask/templating.py", line 99, in _get_source_fast
    raise TemplateNotFound(template)
jinja2.exceptions.TemplateNotFound: exploit_reports.html
2025-05-08 17:43:42,444 - exploit_routes - INFO - [exploit_routes.py:153] - Vérification de l'exploitabilité de: http-slowloris-check
2025-05-08 17:43:42,455 - exploit_routes - INFO - [exploit_routes.py:160] - Module trouvé pour http-slowloris-check: auxiliary/dos/http/slowloris
2025-05-08 17:43:48,175 - exploit_routes - INFO - [exploit_routes.py:153] - Vérification de l'exploitabilité de: ssl-poodle
2025-05-08 17:43:48,175 - exploit_routes - INFO - [exploit_routes.py:160] - Module trouvé pour ssl-poodle: auxiliary/scanner/ssl/openssl_fallback_check
2025-05-08 17:43:51,493 - exploit_routes - INFO - [exploit_routes.py:153] - Vérification de l'exploitabilité de: ssl-dh-params
2025-05-08 17:43:51,494 - exploit_routes - INFO - [exploit_routes.py:160] - Module trouvé pour ssl-dh-params: auxiliary/scanner/ssl/ssl_version
2025-05-08 17:43:54,129 - exploit_routes - INFO - [exploit_routes.py:153] - Vérification de l'exploitabilité de: ssl-ccs-injection
2025-05-08 17:43:54,129 - exploit_routes - INFO - [exploit_routes.py:160] - Module trouvé pour ssl-ccs-injection: auxiliary/scanner/ssl/openssl_ccs
2025-05-08 17:43:56,655 - exploit_routes - INFO - [exploit_routes.py:153] - Vérification de l'exploitabilité de: http-vuln-cve2014-3704
2025-05-08 17:43:56,655 - exploit_routes - INFO - [exploit_routes.py:160] - Module trouvé pour http-vuln-cve2014-3704: exploit/unix/webapp/drupal_drupalgeddon
2025-05-08 17:44:47,407 - exploit_routes - INFO - [exploit_routes.py:153] - Vérification de l'exploitabilité de: ssl-dh-params
2025-05-08 17:44:47,408 - exploit_routes - INFO - [exploit_routes.py:160] - Module trouvé pour ssl-dh-params: auxiliary/scanner/ssl/ssl_version
2025-05-08 17:45:09,878 - exploit_routes - INFO - [exploit_routes.py:23] - Requête reçue pour lancer un exploit
2025-05-09 10:44:55,690 - exploit_routes - INFO - [exploit_routes.py:153] - Vérification de l'exploitabilité de: ssl-dh-params
2025-05-09 10:44:55,691 - exploit_routes - INFO - [exploit_routes.py:160] - Module trouvé pour ssl-dh-params: auxiliary/scanner/ssl/ssl_version
2025-05-09 10:45:04,254 - exploit_routes - INFO - [exploit_routes.py:153] - Vérification de l'exploitabilité de: http-slowloris-check
2025-05-09 10:45:04,254 - exploit_routes - INFO - [exploit_routes.py:160] - Module trouvé pour http-slowloris-check: auxiliary/dos/http/slowloris
2025-05-09 10:47:08,885 - exploit_routes - INFO - [exploit_routes.py:23] - Requête reçue pour lancer un exploit
2025-05-09 10:47:13,907 - exploit_routes - ERROR - [exploit_routes.py:58] - Metasploit n'est pas disponible sur le système. Veuillez installer Metasploit pour utiliser cette fonctionnalité.
2025-05-09 10:47:21,404 - exploit_routes - INFO - [exploit_routes.py:23] - Requête reçue pour lancer un exploit
2025-05-09 11:24:21,506 - exploit_routes - INFO - [exploit_routes.py:153] - Vérification de l'exploitabilité de: ssl-ccs-injection
2025-05-09 11:24:21,508 - exploit_routes - INFO - [exploit_routes.py:160] - Module trouvé pour ssl-ccs-injection: auxiliary/scanner/ssl/openssl_ccs
2025-05-09 11:24:59,888 - exploit_routes - INFO - [exploit_routes.py:23] - Requête reçue pour lancer un exploit
2025-05-09 11:28:56,584 - exploit_routes - INFO - [exploit_routes.py:88] - Accès à la liste des rapports d'exploitation
2025-05-09 11:28:56,584 - exploit_routes - ERROR - [exploit_routes.py:98] - Erreur lors de la récupération des rapports: exploit_reports.html
Traceback (most recent call last):
  File "/home/oebn/Projet-Scan/routes/exploit_routes.py", line 96, in list_reports
    return render_template("exploit_reports.html", reports=reports)
           ^^^^^^^^^^^^^^^^^^^^^^^^^^^^^^^^^^^^^^^^^^^^^^^^^^^^^^^^
  File "/usr/local/lib/python3.11/dist-packages/flask/templating.py", line 149, in render_template
    template = app.jinja_env.get_or_select_template(template_name_or_list)
               ^^^^^^^^^^^^^^^^^^^^^^^^^^^^^^^^^^^^^^^^^^^^^^^^^^^^^^^^^^^
  File "/usr/local/lib/python3.11/dist-packages/jinja2/environment.py", line 1087, in get_or_select_template
    return self.get_template(template_name_or_list, parent, globals)
           ^^^^^^^^^^^^^^^^^^^^^^^^^^^^^^^^^^^^^^^^^^^^^^^^^^^^^^^^^
  File "/usr/local/lib/python3.11/dist-packages/jinja2/environment.py", line 1016, in get_template
    return self._load_template(name, globals)
           ^^^^^^^^^^^^^^^^^^^^^^^^^^^^^^^^^^
  File "/usr/local/lib/python3.11/dist-packages/jinja2/environment.py", line 975, in _load_template
    template = self.loader.load(self, name, self.make_globals(globals))
               ^^^^^^^^^^^^^^^^^^^^^^^^^^^^^^^^^^^^^^^^^^^^^^^^^^^^^^^^
  File "/usr/local/lib/python3.11/dist-packages/jinja2/loaders.py", line 126, in load
    source, filename, uptodate = self.get_source(environment, name)
                                 ^^^^^^^^^^^^^^^^^^^^^^^^^^^^^^^^^^
  File "/usr/local/lib/python3.11/dist-packages/flask/templating.py", line 65, in get_source
    return self._get_source_fast(environment, template)
           ^^^^^^^^^^^^^^^^^^^^^^^^^^^^^^^^^^^^^^^^^^^^
  File "/usr/local/lib/python3.11/dist-packages/flask/templating.py", line 99, in _get_source_fast
    raise TemplateNotFound(template)
jinja2.exceptions.TemplateNotFound: exploit_reports.html
2025-05-09 11:29:44,075 - exploit_routes - INFO - [exploit_routes.py:88] - Accès à la liste des rapports d'exploitation
2025-05-09 11:29:44,099 - exploit_routes - ERROR - [exploit_routes.py:98] - Erreur lors de la récupération des rapports: 'report' is undefined
Traceback (most recent call last):
  File "/home/oebn/Projet-Scan/routes/exploit_routes.py", line 96, in list_reports
    return render_template("exploit_reports.html", reports=reports)
           ^^^^^^^^^^^^^^^^^^^^^^^^^^^^^^^^^^^^^^^^^^^^^^^^^^^^^^^^
  File "/usr/local/lib/python3.11/dist-packages/flask/templating.py", line 150, in render_template
    return _render(app, template, context)
           ^^^^^^^^^^^^^^^^^^^^^^^^^^^^^^^
  File "/usr/local/lib/python3.11/dist-packages/flask/templating.py", line 131, in _render
    rv = template.render(context)
         ^^^^^^^^^^^^^^^^^^^^^^^^
  File "/usr/local/lib/python3.11/dist-packages/jinja2/environment.py", line 1295, in render
    self.environment.handle_exception()
  File "/usr/local/lib/python3.11/dist-packages/jinja2/environment.py", line 942, in handle_exception
    raise rewrite_traceback_stack(source=source)
  File "/home/oebn/Projet-Scan/templates/exploit_reports.html", line 64, in top-level template code
    <p><strong>Vulnérabilité:</strong> {{ report.vulnerability }}</p>
    ^^^^^^^^^^^^^^^^^^^^^^^^^
  File "/usr/local/lib/python3.11/dist-packages/jinja2/environment.py", line 490, in getattr
    return getattr(obj, attribute)
           ^^^^^^^^^^^^^^^^^^^^^^^
jinja2.exceptions.UndefinedError: 'report' is undefined
2025-05-09 11:30:18,792 - exploit_routes - INFO - [exploit_routes.py:88] - Accès à la liste des rapports d'exploitation
2025-05-09 11:30:18,794 - exploit_routes - ERROR - [exploit_routes.py:98] - Erreur lors de la récupération des rapports: 'report' is undefined
Traceback (most recent call last):
  File "/home/oebn/Projet-Scan/routes/exploit_routes.py", line 96, in list_reports
    return render_template("exploit_reports.html", reports=reports)
           ^^^^^^^^^^^^^^^^^^^^^^^^^^^^^^^^^^^^^^^^^^^^^^^^^^^^^^^^
  File "/usr/local/lib/python3.11/dist-packages/flask/templating.py", line 150, in render_template
    return _render(app, template, context)
           ^^^^^^^^^^^^^^^^^^^^^^^^^^^^^^^
  File "/usr/local/lib/python3.11/dist-packages/flask/templating.py", line 131, in _render
    rv = template.render(context)
         ^^^^^^^^^^^^^^^^^^^^^^^^
  File "/usr/local/lib/python3.11/dist-packages/jinja2/environment.py", line 1295, in render
    self.environment.handle_exception()
  File "/usr/local/lib/python3.11/dist-packages/jinja2/environment.py", line 942, in handle_exception
    raise rewrite_traceback_stack(source=source)
  File "/home/oebn/Projet-Scan/templates/exploit_reports.html", line 64, in top-level template code
    <p><strong>Vulnérabilité:</strong> {{ report.vulnerability }}</p>
    ^^^^^^^^^^^^^^^^^^^^^^^^^
  File "/usr/local/lib/python3.11/dist-packages/jinja2/environment.py", line 490, in getattr
    return getattr(obj, attribute)
           ^^^^^^^^^^^^^^^^^^^^^^^
jinja2.exceptions.UndefinedError: 'report' is undefined
2025-05-09 11:34:38,992 - exploit_routes - INFO - [exploit_routes.py:88] - Accès à la liste des rapports d'exploitation
2025-05-09 11:34:38,993 - exploit_routes - ERROR - [exploit_routes.py:98] - Erreur lors de la récupération des rapports: 'report' is undefined
Traceback (most recent call last):
  File "/home/oebn/Projet-Scan/routes/exploit_routes.py", line 96, in list_reports
    # Debugger le contenu de 'reports' pour s'assurer qu'il est bien formaté
           ^^^^^^^^^^^^^^^^^^^^^^^^^^^^^^^^^^^^^^^^^^^^^^^^^^^^^^^^
  File "/usr/local/lib/python3.11/dist-packages/flask/templating.py", line 150, in render_template
    return _render(app, template, context)
           ^^^^^^^^^^^^^^^^^^^^^^^^^^^^^^^
  File "/usr/local/lib/python3.11/dist-packages/flask/templating.py", line 131, in _render
    rv = template.render(context)
         ^^^^^^^^^^^^^^^^^^^^^^^^
  File "/usr/local/lib/python3.11/dist-packages/jinja2/environment.py", line 1295, in render
    self.environment.handle_exception()
  File "/usr/local/lib/python3.11/dist-packages/jinja2/environment.py", line 942, in handle_exception
    raise rewrite_traceback_stack(source=source)
  File "/home/oebn/Projet-Scan/templates/exploit_reports.html", line 64, in top-level template code
    </tr>
  File "/usr/local/lib/python3.11/dist-packages/jinja2/environment.py", line 490, in getattr
    return getattr(obj, attribute)
           ^^^^^^^^^^^^^^^^^^^^^^^
jinja2.exceptions.UndefinedError: 'report' is undefined
2025-05-09 11:34:40,941 - exploit_routes - INFO - [exploit_routes.py:88] - Accès à la liste des rapports d'exploitation
2025-05-09 11:34:40,951 - exploit_routes - ERROR - [exploit_routes.py:98] - Erreur lors de la récupération des rapports: 'report' is undefined
Traceback (most recent call last):
  File "/home/oebn/Projet-Scan/routes/exploit_routes.py", line 96, in list_reports
    # Debugger le contenu de 'reports' pour s'assurer qu'il est bien formaté
           ^^^^^^^^^^^^^^^^^^^^^^^^^^^^^^^^^^^^^^^^^^^^^^^^^^^^^^^^
  File "/usr/local/lib/python3.11/dist-packages/flask/templating.py", line 150, in render_template
    return _render(app, template, context)
           ^^^^^^^^^^^^^^^^^^^^^^^^^^^^^^^
  File "/usr/local/lib/python3.11/dist-packages/flask/templating.py", line 131, in _render
    rv = template.render(context)
         ^^^^^^^^^^^^^^^^^^^^^^^^
  File "/usr/local/lib/python3.11/dist-packages/jinja2/environment.py", line 1295, in render
    self.environment.handle_exception()
  File "/usr/local/lib/python3.11/dist-packages/jinja2/environment.py", line 942, in handle_exception
    raise rewrite_traceback_stack(source=source)
  File "/home/oebn/Projet-Scan/templates/exploit_reports.html", line 64, in top-level template code
    </tr>
  File "/usr/local/lib/python3.11/dist-packages/jinja2/environment.py", line 490, in getattr
    return getattr(obj, attribute)
           ^^^^^^^^^^^^^^^^^^^^^^^
jinja2.exceptions.UndefinedError: 'report' is undefined
2025-05-09 11:34:41,517 - exploit_routes - INFO - [exploit_routes.py:88] - Accès à la liste des rapports d'exploitation
2025-05-09 11:34:41,517 - exploit_routes - ERROR - [exploit_routes.py:98] - Erreur lors de la récupération des rapports: 'report' is undefined
Traceback (most recent call last):
  File "/home/oebn/Projet-Scan/routes/exploit_routes.py", line 96, in list_reports
    # Debugger le contenu de 'reports' pour s'assurer qu'il est bien formaté
           ^^^^^^^^^^^^^^^^^^^^^^^^^^^^^^^^^^^^^^^^^^^^^^^^^^^^^^^^
  File "/usr/local/lib/python3.11/dist-packages/flask/templating.py", line 150, in render_template
    return _render(app, template, context)
           ^^^^^^^^^^^^^^^^^^^^^^^^^^^^^^^
  File "/usr/local/lib/python3.11/dist-packages/flask/templating.py", line 131, in _render
    rv = template.render(context)
         ^^^^^^^^^^^^^^^^^^^^^^^^
  File "/usr/local/lib/python3.11/dist-packages/jinja2/environment.py", line 1295, in render
    self.environment.handle_exception()
  File "/usr/local/lib/python3.11/dist-packages/jinja2/environment.py", line 942, in handle_exception
    raise rewrite_traceback_stack(source=source)
  File "/home/oebn/Projet-Scan/templates/exploit_reports.html", line 64, in top-level template code
    </tr>
  File "/usr/local/lib/python3.11/dist-packages/jinja2/environment.py", line 490, in getattr
    return getattr(obj, attribute)
           ^^^^^^^^^^^^^^^^^^^^^^^
jinja2.exceptions.UndefinedError: 'report' is undefined
2025-05-09 11:34:41,898 - exploit_routes - INFO - [exploit_routes.py:88] - Accès à la liste des rapports d'exploitation
2025-05-09 11:34:41,898 - exploit_routes - ERROR - [exploit_routes.py:98] - Erreur lors de la récupération des rapports: 'report' is undefined
Traceback (most recent call last):
  File "/home/oebn/Projet-Scan/routes/exploit_routes.py", line 96, in list_reports
    # Debugger le contenu de 'reports' pour s'assurer qu'il est bien formaté
           ^^^^^^^^^^^^^^^^^^^^^^^^^^^^^^^^^^^^^^^^^^^^^^^^^^^^^^^^
  File "/usr/local/lib/python3.11/dist-packages/flask/templating.py", line 150, in render_template
    return _render(app, template, context)
           ^^^^^^^^^^^^^^^^^^^^^^^^^^^^^^^
  File "/usr/local/lib/python3.11/dist-packages/flask/templating.py", line 131, in _render
    rv = template.render(context)
         ^^^^^^^^^^^^^^^^^^^^^^^^
  File "/usr/local/lib/python3.11/dist-packages/jinja2/environment.py", line 1295, in render
    self.environment.handle_exception()
  File "/usr/local/lib/python3.11/dist-packages/jinja2/environment.py", line 942, in handle_exception
    raise rewrite_traceback_stack(source=source)
  File "/home/oebn/Projet-Scan/templates/exploit_reports.html", line 64, in top-level template code
    </tr>
  File "/usr/local/lib/python3.11/dist-packages/jinja2/environment.py", line 490, in getattr
    return getattr(obj, attribute)
           ^^^^^^^^^^^^^^^^^^^^^^^
jinja2.exceptions.UndefinedError: 'report' is undefined
2025-05-09 11:34:42,098 - exploit_routes - INFO - [exploit_routes.py:88] - Accès à la liste des rapports d'exploitation
2025-05-09 11:34:42,098 - exploit_routes - ERROR - [exploit_routes.py:98] - Erreur lors de la récupération des rapports: 'report' is undefined
Traceback (most recent call last):
  File "/home/oebn/Projet-Scan/routes/exploit_routes.py", line 96, in list_reports
    # Debugger le contenu de 'reports' pour s'assurer qu'il est bien formaté
           ^^^^^^^^^^^^^^^^^^^^^^^^^^^^^^^^^^^^^^^^^^^^^^^^^^^^^^^^
  File "/usr/local/lib/python3.11/dist-packages/flask/templating.py", line 150, in render_template
    return _render(app, template, context)
           ^^^^^^^^^^^^^^^^^^^^^^^^^^^^^^^
  File "/usr/local/lib/python3.11/dist-packages/flask/templating.py", line 131, in _render
    rv = template.render(context)
         ^^^^^^^^^^^^^^^^^^^^^^^^
  File "/usr/local/lib/python3.11/dist-packages/jinja2/environment.py", line 1295, in render
    self.environment.handle_exception()
  File "/usr/local/lib/python3.11/dist-packages/jinja2/environment.py", line 942, in handle_exception
    raise rewrite_traceback_stack(source=source)
  File "/home/oebn/Projet-Scan/templates/exploit_reports.html", line 64, in top-level template code
    </tr>
  File "/usr/local/lib/python3.11/dist-packages/jinja2/environment.py", line 490, in getattr
    return getattr(obj, attribute)
           ^^^^^^^^^^^^^^^^^^^^^^^
jinja2.exceptions.UndefinedError: 'report' is undefined
2025-05-09 11:34:42,268 - exploit_routes - INFO - [exploit_routes.py:88] - Accès à la liste des rapports d'exploitation
2025-05-09 11:34:42,268 - exploit_routes - ERROR - [exploit_routes.py:98] - Erreur lors de la récupération des rapports: 'report' is undefined
Traceback (most recent call last):
  File "/home/oebn/Projet-Scan/routes/exploit_routes.py", line 96, in list_reports
    # Debugger le contenu de 'reports' pour s'assurer qu'il est bien formaté
           ^^^^^^^^^^^^^^^^^^^^^^^^^^^^^^^^^^^^^^^^^^^^^^^^^^^^^^^^
  File "/usr/local/lib/python3.11/dist-packages/flask/templating.py", line 150, in render_template
    return _render(app, template, context)
           ^^^^^^^^^^^^^^^^^^^^^^^^^^^^^^^
  File "/usr/local/lib/python3.11/dist-packages/flask/templating.py", line 131, in _render
    rv = template.render(context)
         ^^^^^^^^^^^^^^^^^^^^^^^^
  File "/usr/local/lib/python3.11/dist-packages/jinja2/environment.py", line 1295, in render
    self.environment.handle_exception()
  File "/usr/local/lib/python3.11/dist-packages/jinja2/environment.py", line 942, in handle_exception
    raise rewrite_traceback_stack(source=source)
  File "/home/oebn/Projet-Scan/templates/exploit_reports.html", line 64, in top-level template code
    </tr>
  File "/usr/local/lib/python3.11/dist-packages/jinja2/environment.py", line 490, in getattr
    return getattr(obj, attribute)
           ^^^^^^^^^^^^^^^^^^^^^^^
jinja2.exceptions.UndefinedError: 'report' is undefined
2025-05-09 11:34:42,500 - exploit_routes - INFO - [exploit_routes.py:88] - Accès à la liste des rapports d'exploitation
2025-05-09 11:34:42,500 - exploit_routes - ERROR - [exploit_routes.py:98] - Erreur lors de la récupération des rapports: 'report' is undefined
Traceback (most recent call last):
  File "/home/oebn/Projet-Scan/routes/exploit_routes.py", line 96, in list_reports
    # Debugger le contenu de 'reports' pour s'assurer qu'il est bien formaté
           ^^^^^^^^^^^^^^^^^^^^^^^^^^^^^^^^^^^^^^^^^^^^^^^^^^^^^^^^
  File "/usr/local/lib/python3.11/dist-packages/flask/templating.py", line 150, in render_template
    return _render(app, template, context)
           ^^^^^^^^^^^^^^^^^^^^^^^^^^^^^^^
  File "/usr/local/lib/python3.11/dist-packages/flask/templating.py", line 131, in _render
    rv = template.render(context)
         ^^^^^^^^^^^^^^^^^^^^^^^^
  File "/usr/local/lib/python3.11/dist-packages/jinja2/environment.py", line 1295, in render
    self.environment.handle_exception()
  File "/usr/local/lib/python3.11/dist-packages/jinja2/environment.py", line 942, in handle_exception
    raise rewrite_traceback_stack(source=source)
  File "/home/oebn/Projet-Scan/templates/exploit_reports.html", line 64, in top-level template code
    </tr>
  File "/usr/local/lib/python3.11/dist-packages/jinja2/environment.py", line 490, in getattr
    return getattr(obj, attribute)
           ^^^^^^^^^^^^^^^^^^^^^^^
jinja2.exceptions.UndefinedError: 'report' is undefined
2025-05-09 11:34:42,684 - exploit_routes - INFO - [exploit_routes.py:88] - Accès à la liste des rapports d'exploitation
2025-05-09 11:34:42,685 - exploit_routes - ERROR - [exploit_routes.py:98] - Erreur lors de la récupération des rapports: 'report' is undefined
Traceback (most recent call last):
  File "/home/oebn/Projet-Scan/routes/exploit_routes.py", line 96, in list_reports
    # Debugger le contenu de 'reports' pour s'assurer qu'il est bien formaté
           ^^^^^^^^^^^^^^^^^^^^^^^^^^^^^^^^^^^^^^^^^^^^^^^^^^^^^^^^
  File "/usr/local/lib/python3.11/dist-packages/flask/templating.py", line 150, in render_template
    return _render(app, template, context)
           ^^^^^^^^^^^^^^^^^^^^^^^^^^^^^^^
  File "/usr/local/lib/python3.11/dist-packages/flask/templating.py", line 131, in _render
    rv = template.render(context)
         ^^^^^^^^^^^^^^^^^^^^^^^^
  File "/usr/local/lib/python3.11/dist-packages/jinja2/environment.py", line 1295, in render
    self.environment.handle_exception()
  File "/usr/local/lib/python3.11/dist-packages/jinja2/environment.py", line 942, in handle_exception
    raise rewrite_traceback_stack(source=source)
  File "/home/oebn/Projet-Scan/templates/exploit_reports.html", line 64, in top-level template code
    </tr>
  File "/usr/local/lib/python3.11/dist-packages/jinja2/environment.py", line 490, in getattr
    return getattr(obj, attribute)
           ^^^^^^^^^^^^^^^^^^^^^^^
jinja2.exceptions.UndefinedError: 'report' is undefined
2025-05-09 11:34:42,885 - exploit_routes - INFO - [exploit_routes.py:88] - Accès à la liste des rapports d'exploitation
2025-05-09 11:34:42,885 - exploit_routes - ERROR - [exploit_routes.py:98] - Erreur lors de la récupération des rapports: 'report' is undefined
Traceback (most recent call last):
  File "/home/oebn/Projet-Scan/routes/exploit_routes.py", line 96, in list_reports
    # Debugger le contenu de 'reports' pour s'assurer qu'il est bien formaté
           ^^^^^^^^^^^^^^^^^^^^^^^^^^^^^^^^^^^^^^^^^^^^^^^^^^^^^^^^
  File "/usr/local/lib/python3.11/dist-packages/flask/templating.py", line 150, in render_template
    return _render(app, template, context)
           ^^^^^^^^^^^^^^^^^^^^^^^^^^^^^^^
  File "/usr/local/lib/python3.11/dist-packages/flask/templating.py", line 131, in _render
    rv = template.render(context)
         ^^^^^^^^^^^^^^^^^^^^^^^^
  File "/usr/local/lib/python3.11/dist-packages/jinja2/environment.py", line 1295, in render
    self.environment.handle_exception()
  File "/usr/local/lib/python3.11/dist-packages/jinja2/environment.py", line 942, in handle_exception
    raise rewrite_traceback_stack(source=source)
  File "/home/oebn/Projet-Scan/templates/exploit_reports.html", line 64, in top-level template code
    </tr>
  File "/usr/local/lib/python3.11/dist-packages/jinja2/environment.py", line 490, in getattr
    return getattr(obj, attribute)
           ^^^^^^^^^^^^^^^^^^^^^^^
jinja2.exceptions.UndefinedError: 'report' is undefined
2025-05-09 11:34:43,382 - exploit_routes - INFO - [exploit_routes.py:88] - Accès à la liste des rapports d'exploitation
2025-05-09 11:34:43,383 - exploit_routes - ERROR - [exploit_routes.py:98] - Erreur lors de la récupération des rapports: 'report' is undefined
Traceback (most recent call last):
  File "/home/oebn/Projet-Scan/routes/exploit_routes.py", line 96, in list_reports
    # Debugger le contenu de 'reports' pour s'assurer qu'il est bien formaté
           ^^^^^^^^^^^^^^^^^^^^^^^^^^^^^^^^^^^^^^^^^^^^^^^^^^^^^^^^
  File "/usr/local/lib/python3.11/dist-packages/flask/templating.py", line 150, in render_template
    return _render(app, template, context)
           ^^^^^^^^^^^^^^^^^^^^^^^^^^^^^^^
  File "/usr/local/lib/python3.11/dist-packages/flask/templating.py", line 131, in _render
    rv = template.render(context)
         ^^^^^^^^^^^^^^^^^^^^^^^^
  File "/usr/local/lib/python3.11/dist-packages/jinja2/environment.py", line 1295, in render
    self.environment.handle_exception()
  File "/usr/local/lib/python3.11/dist-packages/jinja2/environment.py", line 942, in handle_exception
    raise rewrite_traceback_stack(source=source)
  File "/home/oebn/Projet-Scan/templates/exploit_reports.html", line 64, in top-level template code
    </tr>
  File "/usr/local/lib/python3.11/dist-packages/jinja2/environment.py", line 490, in getattr
    return getattr(obj, attribute)
           ^^^^^^^^^^^^^^^^^^^^^^^
jinja2.exceptions.UndefinedError: 'report' is undefined
2025-05-09 11:34:43,551 - exploit_routes - INFO - [exploit_routes.py:88] - Accès à la liste des rapports d'exploitation
2025-05-09 11:34:43,552 - exploit_routes - ERROR - [exploit_routes.py:98] - Erreur lors de la récupération des rapports: 'report' is undefined
Traceback (most recent call last):
  File "/home/oebn/Projet-Scan/routes/exploit_routes.py", line 96, in list_reports
    # Debugger le contenu de 'reports' pour s'assurer qu'il est bien formaté
           ^^^^^^^^^^^^^^^^^^^^^^^^^^^^^^^^^^^^^^^^^^^^^^^^^^^^^^^^
  File "/usr/local/lib/python3.11/dist-packages/flask/templating.py", line 150, in render_template
    return _render(app, template, context)
           ^^^^^^^^^^^^^^^^^^^^^^^^^^^^^^^
  File "/usr/local/lib/python3.11/dist-packages/flask/templating.py", line 131, in _render
    rv = template.render(context)
         ^^^^^^^^^^^^^^^^^^^^^^^^
  File "/usr/local/lib/python3.11/dist-packages/jinja2/environment.py", line 1295, in render
    self.environment.handle_exception()
  File "/usr/local/lib/python3.11/dist-packages/jinja2/environment.py", line 942, in handle_exception
    raise rewrite_traceback_stack(source=source)
  File "/home/oebn/Projet-Scan/templates/exploit_reports.html", line 64, in top-level template code
    </tr>
  File "/usr/local/lib/python3.11/dist-packages/jinja2/environment.py", line 490, in getattr
    return getattr(obj, attribute)
           ^^^^^^^^^^^^^^^^^^^^^^^
jinja2.exceptions.UndefinedError: 'report' is undefined
2025-05-09 11:34:43,725 - exploit_routes - INFO - [exploit_routes.py:88] - Accès à la liste des rapports d'exploitation
2025-05-09 11:34:43,726 - exploit_routes - ERROR - [exploit_routes.py:98] - Erreur lors de la récupération des rapports: 'report' is undefined
Traceback (most recent call last):
  File "/home/oebn/Projet-Scan/routes/exploit_routes.py", line 96, in list_reports
    # Debugger le contenu de 'reports' pour s'assurer qu'il est bien formaté
           ^^^^^^^^^^^^^^^^^^^^^^^^^^^^^^^^^^^^^^^^^^^^^^^^^^^^^^^^
  File "/usr/local/lib/python3.11/dist-packages/flask/templating.py", line 150, in render_template
    return _render(app, template, context)
           ^^^^^^^^^^^^^^^^^^^^^^^^^^^^^^^
  File "/usr/local/lib/python3.11/dist-packages/flask/templating.py", line 131, in _render
    rv = template.render(context)
         ^^^^^^^^^^^^^^^^^^^^^^^^
  File "/usr/local/lib/python3.11/dist-packages/jinja2/environment.py", line 1295, in render
    self.environment.handle_exception()
  File "/usr/local/lib/python3.11/dist-packages/jinja2/environment.py", line 942, in handle_exception
    raise rewrite_traceback_stack(source=source)
  File "/home/oebn/Projet-Scan/templates/exploit_reports.html", line 64, in top-level template code
    </tr>
  File "/usr/local/lib/python3.11/dist-packages/jinja2/environment.py", line 490, in getattr
    return getattr(obj, attribute)
           ^^^^^^^^^^^^^^^^^^^^^^^
jinja2.exceptions.UndefinedError: 'report' is undefined
2025-05-09 11:34:51,594 - exploit_routes - INFO - [exploit_routes.py:88] - Accès à la liste des rapports d'exploitation
2025-05-09 11:34:59,280 - exploit_routes - INFO - [exploit_routes.py:88] - Accès à la liste des rapports d'exploitation
2025-05-15 21:32:30,362 - exploit_routes - INFO - [exploit_routes.py:155] - Vérification de l'exploitabilité de: ftp-vsftpd-backdoor
2025-05-15 21:32:30,368 - exploit_routes - INFO - [exploit_routes.py:162] - Module trouvé pour ftp-vsftpd-backdoor: exploit/unix/ftp/vsftpd_234_backdoor
2025-05-15 21:32:33,182 - exploit_routes - INFO - [exploit_routes.py:23] - Requête reçue pour lancer un exploit
2025-05-15 21:32:38,265 - exploit_routes - ERROR - [exploit_routes.py:58] - Metasploit n'est pas disponible sur le système. Veuillez installer Metasploit pour utiliser cette fonctionnalité.
2025-05-15 21:32:50,204 - exploit_routes - INFO - [exploit_routes.py:23] - Requête reçue pour lancer un exploit
2025-05-15 21:36:26,841 - exploit_routes - INFO - [exploit_routes.py:88] - Accès à la liste des rapports d'exploitation
2025-05-15 21:58:44,047 - exploit_routes - INFO - [exploit_routes.py:88] - Accès à la liste des rapports d'exploitation
2025-05-15 21:59:30,112 - exploit_routes - INFO - [exploit_routes.py:88] - Accès à la liste des rapports d'exploitation
2025-05-15 21:59:32,862 - exploit_routes - INFO - [exploit_routes.py:88] - Accès à la liste des rapports d'exploitation
2025-05-15 21:59:34,896 - exploit_routes - INFO - [exploit_routes.py:88] - Accès à la liste des rapports d'exploitation
2025-05-17 17:51:17,163 - exploit_routes - INFO - [exploit_routes.py:88] - Accès à la liste des rapports d'exploitation
2025-05-17 18:02:47,005 - exploit_routes - INFO - [exploit_routes.py:155] - Vérification de l'exploitabilité de: ftp-vsftpd-backdoor
2025-05-17 18:02:47,005 - exploit_routes - INFO - [exploit_routes.py:162] - Module trouvé pour ftp-vsftpd-backdoor: exploit/unix/ftp/vsftpd_234_backdoor
2025-05-17 18:02:50,698 - exploit_routes - INFO - [exploit_routes.py:23] - Requête reçue pour lancer un exploit
2025-05-17 18:02:55,774 - exploit_routes - ERROR - [exploit_routes.py:58] - Metasploit n'est pas disponible sur le système. Veuillez installer Metasploit pour utiliser cette fonctionnalité.
2025-05-17 18:03:04,039 - exploit_routes - INFO - [exploit_routes.py:23] - Requête reçue pour lancer un exploit
2025-05-17 18:03:09,055 - exploit_routes - ERROR - [exploit_routes.py:58] - Metasploit n'est pas disponible sur le système. Veuillez installer Metasploit pour utiliser cette fonctionnalité.
2025-05-17 18:03:59,666 - exploit_routes - INFO - [exploit_routes.py:23] - Requête reçue pour lancer un exploit
2025-05-17 18:07:10,570 - exploit_routes - INFO - [exploit_routes.py:88] - Accès à la liste des rapports d'exploitation
2025-05-17 18:18:08,939 - exploit_routes - INFO - [exploit_routes.py:155] - Vérification de l'exploitabilité de: ftp-vsftpd-backdoor
2025-05-17 18:18:08,942 - exploit_routes - INFO - [exploit_routes.py:162] - Module trouvé pour ftp-vsftpd-backdoor: exploit/unix/ftp/vsftpd_234_backdoor
2025-05-17 18:18:11,520 - exploit_routes - INFO - [exploit_routes.py:23] - Requête reçue pour lancer un exploit
2025-05-17 18:18:57,906 - exploit_routes - INFO - [exploit_routes.py:106] - Accès au rapport d'exploitation: exploit_report_20250517_181850.json
2025-05-17 18:18:57,914 - exploit_routes - ERROR - [exploit_routes.py:130] - Erreur lors de la récupération du rapport: exploit_report.html
Traceback (most recent call last):
  File "/home/oebn/Projet-Scan/routes/exploit_routes.py", line 128, in get_report
    return render_template("exploit_report.html", report=report, filename=filename)
           ^^^^^^^^^^^^^^^^^^^^^^^^^^^^^^^^^^^^^^^^^^^^^^^^^^^^^^^^^^^^^^^^^^^^^^^^
  File "/home/oebn/Projet-Scan/venv/lib/python3.11/site-packages/flask/templating.py", line 149, in render_template
    template = app.jinja_env.get_or_select_template(template_name_or_list)
               ^^^^^^^^^^^^^^^^^^^^^^^^^^^^^^^^^^^^^^^^^^^^^^^^^^^^^^^^^^^
  File "/home/oebn/Projet-Scan/venv/lib/python3.11/site-packages/jinja2/environment.py", line 1087, in get_or_select_template
    return self.get_template(template_name_or_list, parent, globals)
           ^^^^^^^^^^^^^^^^^^^^^^^^^^^^^^^^^^^^^^^^^^^^^^^^^^^^^^^^^
  File "/home/oebn/Projet-Scan/venv/lib/python3.11/site-packages/jinja2/environment.py", line 1016, in get_template
    return self._load_template(name, globals)
           ^^^^^^^^^^^^^^^^^^^^^^^^^^^^^^^^^^
  File "/home/oebn/Projet-Scan/venv/lib/python3.11/site-packages/jinja2/environment.py", line 975, in _load_template
    template = self.loader.load(self, name, self.make_globals(globals))
               ^^^^^^^^^^^^^^^^^^^^^^^^^^^^^^^^^^^^^^^^^^^^^^^^^^^^^^^^
  File "/home/oebn/Projet-Scan/venv/lib/python3.11/site-packages/jinja2/loaders.py", line 126, in load
    source, filename, uptodate = self.get_source(environment, name)
                                 ^^^^^^^^^^^^^^^^^^^^^^^^^^^^^^^^^^
  File "/home/oebn/Projet-Scan/venv/lib/python3.11/site-packages/flask/templating.py", line 65, in get_source
    return self._get_source_fast(environment, template)
           ^^^^^^^^^^^^^^^^^^^^^^^^^^^^^^^^^^^^^^^^^^^^
  File "/home/oebn/Projet-Scan/venv/lib/python3.11/site-packages/flask/templating.py", line 99, in _get_source_fast
    raise TemplateNotFound(template)
jinja2.exceptions.TemplateNotFound: exploit_report.html
2025-05-17 18:19:05,499 - exploit_routes - INFO - [exploit_routes.py:88] - Accès à la liste des rapports d'exploitation
2025-05-17 18:19:11,233 - exploit_routes - INFO - [exploit_routes.py:106] - Accès au rapport d'exploitation: exploit_report_20250517_181850.json
2025-05-17 18:19:11,234 - exploit_routes - ERROR - [exploit_routes.py:130] - Erreur lors de la récupération du rapport: exploit_report.html
Traceback (most recent call last):
  File "/home/oebn/Projet-Scan/routes/exploit_routes.py", line 128, in get_report
    return render_template("exploit_report.html", report=report, filename=filename)
           ^^^^^^^^^^^^^^^^^^^^^^^^^^^^^^^^^^^^^^^^^^^^^^^^^^^^^^^^^^^^^^^^^^^^^^^^
  File "/home/oebn/Projet-Scan/venv/lib/python3.11/site-packages/flask/templating.py", line 149, in render_template
    template = app.jinja_env.get_or_select_template(template_name_or_list)
               ^^^^^^^^^^^^^^^^^^^^^^^^^^^^^^^^^^^^^^^^^^^^^^^^^^^^^^^^^^^
  File "/home/oebn/Projet-Scan/venv/lib/python3.11/site-packages/jinja2/environment.py", line 1087, in get_or_select_template
    return self.get_template(template_name_or_list, parent, globals)
           ^^^^^^^^^^^^^^^^^^^^^^^^^^^^^^^^^^^^^^^^^^^^^^^^^^^^^^^^^
  File "/home/oebn/Projet-Scan/venv/lib/python3.11/site-packages/jinja2/environment.py", line 1016, in get_template
    return self._load_template(name, globals)
           ^^^^^^^^^^^^^^^^^^^^^^^^^^^^^^^^^^
  File "/home/oebn/Projet-Scan/venv/lib/python3.11/site-packages/jinja2/environment.py", line 975, in _load_template
    template = self.loader.load(self, name, self.make_globals(globals))
               ^^^^^^^^^^^^^^^^^^^^^^^^^^^^^^^^^^^^^^^^^^^^^^^^^^^^^^^^
  File "/home/oebn/Projet-Scan/venv/lib/python3.11/site-packages/jinja2/loaders.py", line 126, in load
    source, filename, uptodate = self.get_source(environment, name)
                                 ^^^^^^^^^^^^^^^^^^^^^^^^^^^^^^^^^^
  File "/home/oebn/Projet-Scan/venv/lib/python3.11/site-packages/flask/templating.py", line 65, in get_source
    return self._get_source_fast(environment, template)
           ^^^^^^^^^^^^^^^^^^^^^^^^^^^^^^^^^^^^^^^^^^^^
  File "/home/oebn/Projet-Scan/venv/lib/python3.11/site-packages/flask/templating.py", line 99, in _get_source_fast
    raise TemplateNotFound(template)
jinja2.exceptions.TemplateNotFound: exploit_report.html
2025-05-17 18:19:13,341 - exploit_routes - INFO - [exploit_routes.py:88] - Accès à la liste des rapports d'exploitation
2025-05-17 18:19:15,303 - exploit_routes - INFO - [exploit_routes.py:88] - Accès à la liste des rapports d'exploitation
2025-05-17 18:19:16,144 - exploit_routes - INFO - [exploit_routes.py:106] - Accès au rapport d'exploitation: exploit_report_20250517_181850.json
2025-05-17 18:19:16,155 - exploit_routes - ERROR - [exploit_routes.py:130] - Erreur lors de la récupération du rapport: exploit_report.html
Traceback (most recent call last):
  File "/home/oebn/Projet-Scan/routes/exploit_routes.py", line 128, in get_report
    return render_template("exploit_report.html", report=report, filename=filename)
           ^^^^^^^^^^^^^^^^^^^^^^^^^^^^^^^^^^^^^^^^^^^^^^^^^^^^^^^^^^^^^^^^^^^^^^^^
  File "/home/oebn/Projet-Scan/venv/lib/python3.11/site-packages/flask/templating.py", line 149, in render_template
    template = app.jinja_env.get_or_select_template(template_name_or_list)
               ^^^^^^^^^^^^^^^^^^^^^^^^^^^^^^^^^^^^^^^^^^^^^^^^^^^^^^^^^^^
  File "/home/oebn/Projet-Scan/venv/lib/python3.11/site-packages/jinja2/environment.py", line 1087, in get_or_select_template
    return self.get_template(template_name_or_list, parent, globals)
           ^^^^^^^^^^^^^^^^^^^^^^^^^^^^^^^^^^^^^^^^^^^^^^^^^^^^^^^^^
  File "/home/oebn/Projet-Scan/venv/lib/python3.11/site-packages/jinja2/environment.py", line 1016, in get_template
    return self._load_template(name, globals)
           ^^^^^^^^^^^^^^^^^^^^^^^^^^^^^^^^^^
  File "/home/oebn/Projet-Scan/venv/lib/python3.11/site-packages/jinja2/environment.py", line 975, in _load_template
    template = self.loader.load(self, name, self.make_globals(globals))
               ^^^^^^^^^^^^^^^^^^^^^^^^^^^^^^^^^^^^^^^^^^^^^^^^^^^^^^^^
  File "/home/oebn/Projet-Scan/venv/lib/python3.11/site-packages/jinja2/loaders.py", line 126, in load
    source, filename, uptodate = self.get_source(environment, name)
                                 ^^^^^^^^^^^^^^^^^^^^^^^^^^^^^^^^^^
  File "/home/oebn/Projet-Scan/venv/lib/python3.11/site-packages/flask/templating.py", line 65, in get_source
    return self._get_source_fast(environment, template)
           ^^^^^^^^^^^^^^^^^^^^^^^^^^^^^^^^^^^^^^^^^^^^
  File "/home/oebn/Projet-Scan/venv/lib/python3.11/site-packages/flask/templating.py", line 99, in _get_source_fast
    raise TemplateNotFound(template)
jinja2.exceptions.TemplateNotFound: exploit_report.html
2025-05-17 18:21:43,836 - exploit_routes - INFO - [exploit_routes.py:106] - Accès au rapport d'exploitation: exploit_report_20250517_181850.json
2025-05-17 18:21:43,836 - exploit_routes - ERROR - [exploit_routes.py:130] - Erreur lors de la récupération du rapport: exploit_report.html
Traceback (most recent call last):
  File "/home/oebn/Projet-Scan/routes/exploit_routes.py", line 128, in get_report
    return render_template("exploit_report.html", report=report, filename=filename)
           ^^^^^^^^^^^^^^^^^^^^^^^^^^^^^^^^^^^^^^^^^^^^^^^^^^^^^^^^^^^^^^^^^^^^^^^^
  File "/home/oebn/Projet-Scan/venv/lib/python3.11/site-packages/flask/templating.py", line 149, in render_template
    template = app.jinja_env.get_or_select_template(template_name_or_list)
               ^^^^^^^^^^^^^^^^^^^^^^^^^^^^^^^^^^^^^^^^^^^^^^^^^^^^^^^^^^^
  File "/home/oebn/Projet-Scan/venv/lib/python3.11/site-packages/jinja2/environment.py", line 1087, in get_or_select_template
    return self.get_template(template_name_or_list, parent, globals)
           ^^^^^^^^^^^^^^^^^^^^^^^^^^^^^^^^^^^^^^^^^^^^^^^^^^^^^^^^^
  File "/home/oebn/Projet-Scan/venv/lib/python3.11/site-packages/jinja2/environment.py", line 1016, in get_template
    return self._load_template(name, globals)
           ^^^^^^^^^^^^^^^^^^^^^^^^^^^^^^^^^^
  File "/home/oebn/Projet-Scan/venv/lib/python3.11/site-packages/jinja2/environment.py", line 975, in _load_template
    template = self.loader.load(self, name, self.make_globals(globals))
               ^^^^^^^^^^^^^^^^^^^^^^^^^^^^^^^^^^^^^^^^^^^^^^^^^^^^^^^^
  File "/home/oebn/Projet-Scan/venv/lib/python3.11/site-packages/jinja2/loaders.py", line 126, in load
    source, filename, uptodate = self.get_source(environment, name)
                                 ^^^^^^^^^^^^^^^^^^^^^^^^^^^^^^^^^^
  File "/home/oebn/Projet-Scan/venv/lib/python3.11/site-packages/flask/templating.py", line 65, in get_source
    return self._get_source_fast(environment, template)
           ^^^^^^^^^^^^^^^^^^^^^^^^^^^^^^^^^^^^^^^^^^^^
  File "/home/oebn/Projet-Scan/venv/lib/python3.11/site-packages/flask/templating.py", line 99, in _get_source_fast
    raise TemplateNotFound(template)
jinja2.exceptions.TemplateNotFound: exploit_report.html
2025-05-17 18:21:54,738 - exploit_routes - INFO - [exploit_routes.py:106] - Accès au rapport d'exploitation: exploit_report_20250517_181850.json
2025-05-17 18:21:54,739 - exploit_routes - ERROR - [exploit_routes.py:130] - Erreur lors de la récupération du rapport: exploit_report.html
Traceback (most recent call last):
  File "/home/oebn/Projet-Scan/routes/exploit_routes.py", line 128, in get_report
    return render_template("exploit_report.html", report=report, filename=filename)
           ^^^^^^^^^^^^^^^^^^^^^^^^^^^^^^^^^^^^^^^^^^^^^^^^^^^^^^^^^^^^^^^^^^^^^^^^
  File "/home/oebn/Projet-Scan/venv/lib/python3.11/site-packages/flask/templating.py", line 149, in render_template
    template = app.jinja_env.get_or_select_template(template_name_or_list)
               ^^^^^^^^^^^^^^^^^^^^^^^^^^^^^^^^^^^^^^^^^^^^^^^^^^^^^^^^^^^
  File "/home/oebn/Projet-Scan/venv/lib/python3.11/site-packages/jinja2/environment.py", line 1087, in get_or_select_template
    return self.get_template(template_name_or_list, parent, globals)
           ^^^^^^^^^^^^^^^^^^^^^^^^^^^^^^^^^^^^^^^^^^^^^^^^^^^^^^^^^
  File "/home/oebn/Projet-Scan/venv/lib/python3.11/site-packages/jinja2/environment.py", line 1016, in get_template
    return self._load_template(name, globals)
           ^^^^^^^^^^^^^^^^^^^^^^^^^^^^^^^^^^
  File "/home/oebn/Projet-Scan/venv/lib/python3.11/site-packages/jinja2/environment.py", line 975, in _load_template
    template = self.loader.load(self, name, self.make_globals(globals))
               ^^^^^^^^^^^^^^^^^^^^^^^^^^^^^^^^^^^^^^^^^^^^^^^^^^^^^^^^
  File "/home/oebn/Projet-Scan/venv/lib/python3.11/site-packages/jinja2/loaders.py", line 126, in load
    source, filename, uptodate = self.get_source(environment, name)
                                 ^^^^^^^^^^^^^^^^^^^^^^^^^^^^^^^^^^
  File "/home/oebn/Projet-Scan/venv/lib/python3.11/site-packages/flask/templating.py", line 65, in get_source
    return self._get_source_fast(environment, template)
           ^^^^^^^^^^^^^^^^^^^^^^^^^^^^^^^^^^^^^^^^^^^^
  File "/home/oebn/Projet-Scan/venv/lib/python3.11/site-packages/flask/templating.py", line 99, in _get_source_fast
    raise TemplateNotFound(template)
jinja2.exceptions.TemplateNotFound: exploit_report.html
2025-05-17 18:22:06,149 - exploit_routes - INFO - [exploit_routes.py:106] - Accès au rapport d'exploitation: exploit_report_20250517_181850.json
2025-05-17 18:22:06,150 - exploit_routes - ERROR - [exploit_routes.py:130] - Erreur lors de la récupération du rapport: exploit_report.html
Traceback (most recent call last):
  File "/home/oebn/Projet-Scan/routes/exploit_routes.py", line 128, in get_report
    return render_template("exploit_report.html", report=report, filename=filename)
           ^^^^^^^^^^^^^^^^^^^^^^^^^^^^^^^^^^^^^^^^^^^^^^^^^^^^^^^^^^^^^^^^^^^^^^^^
  File "/home/oebn/Projet-Scan/venv/lib/python3.11/site-packages/flask/templating.py", line 149, in render_template
    template = app.jinja_env.get_or_select_template(template_name_or_list)
               ^^^^^^^^^^^^^^^^^^^^^^^^^^^^^^^^^^^^^^^^^^^^^^^^^^^^^^^^^^^
  File "/home/oebn/Projet-Scan/venv/lib/python3.11/site-packages/jinja2/environment.py", line 1087, in get_or_select_template
    return self.get_template(template_name_or_list, parent, globals)
           ^^^^^^^^^^^^^^^^^^^^^^^^^^^^^^^^^^^^^^^^^^^^^^^^^^^^^^^^^
  File "/home/oebn/Projet-Scan/venv/lib/python3.11/site-packages/jinja2/environment.py", line 1016, in get_template
    return self._load_template(name, globals)
           ^^^^^^^^^^^^^^^^^^^^^^^^^^^^^^^^^^
  File "/home/oebn/Projet-Scan/venv/lib/python3.11/site-packages/jinja2/environment.py", line 975, in _load_template
    template = self.loader.load(self, name, self.make_globals(globals))
               ^^^^^^^^^^^^^^^^^^^^^^^^^^^^^^^^^^^^^^^^^^^^^^^^^^^^^^^^
  File "/home/oebn/Projet-Scan/venv/lib/python3.11/site-packages/jinja2/loaders.py", line 126, in load
    source, filename, uptodate = self.get_source(environment, name)
                                 ^^^^^^^^^^^^^^^^^^^^^^^^^^^^^^^^^^
  File "/home/oebn/Projet-Scan/venv/lib/python3.11/site-packages/flask/templating.py", line 65, in get_source
    return self._get_source_fast(environment, template)
           ^^^^^^^^^^^^^^^^^^^^^^^^^^^^^^^^^^^^^^^^^^^^
  File "/home/oebn/Projet-Scan/venv/lib/python3.11/site-packages/flask/templating.py", line 99, in _get_source_fast
    raise TemplateNotFound(template)
jinja2.exceptions.TemplateNotFound: exploit_report.html
2025-05-17 18:29:35,832 - exploit_routes - INFO - [exploit_routes.py:106] - Accès au rapport d'exploitation: exploit_report_20250517_181850.json
2025-05-17 18:29:35,858 - exploit_routes - ERROR - [exploit_routes.py:130] - Erreur lors de la récupération du rapport: Could not build url for endpoint 'exploit_routes.exploit_reports'. Did you mean 'exploit.list_reports' instead?
Traceback (most recent call last):
  File "/home/oebn/Projet-Scan/routes/exploit_routes.py", line 128, in get_report
    return render_template("exploit_report.html", report=report, filename=filename)
           ^^^^^^^^^^^^^^^^^^^^^^^^^^^^^^^^^^^^^^^^^^^^^^^^^^^^^^^^^^^^^^^^^^^^^^^^
  File "/home/oebn/Projet-Scan/venv/lib/python3.11/site-packages/flask/templating.py", line 150, in render_template
    return _render(app, template, context)
           ^^^^^^^^^^^^^^^^^^^^^^^^^^^^^^^
  File "/home/oebn/Projet-Scan/venv/lib/python3.11/site-packages/flask/templating.py", line 131, in _render
    rv = template.render(context)
         ^^^^^^^^^^^^^^^^^^^^^^^^
  File "/home/oebn/Projet-Scan/venv/lib/python3.11/site-packages/jinja2/environment.py", line 1295, in render
    self.environment.handle_exception()
  File "/home/oebn/Projet-Scan/venv/lib/python3.11/site-packages/jinja2/environment.py", line 942, in handle_exception
    raise rewrite_traceback_stack(source=source)
  File "/home/oebn/Projet-Scan/templates/exploit_report.html", line 1, in top-level template code
    {% extends "base.html" %}
  File "/home/oebn/Projet-Scan/templates/base.html", line 66, in top-level template code
    {% block content %}
  File "/home/oebn/Projet-Scan/templates/exploit_report.html", line 19, in block 'content'
    <a href="{{ url_for('exploit_routes.exploit_reports') }}" class="btn btn-secondary">Retour aux Rapports</a>
    ^^^^^^^^^^^^^^^^^^^^^^^^^
  File "/home/oebn/Projet-Scan/venv/lib/python3.11/site-packages/flask/app.py", line 1121, in url_for
    return self.handle_url_build_error(error, endpoint, values)
           ^^^^^^^^^^^^^^^^^^^^^^^^^^^^^^^^^^^^^^^^^^^^^^^^^^^^
  File "/home/oebn/Projet-Scan/venv/lib/python3.11/site-packages/flask/app.py", line 1110, in url_for
    rv = url_adapter.build(  # type: ignore[union-attr]
         ^^^^^^^^^^^^^^^^^^^^^^^^^^^^^^^^^^^^^^^^^^^^^^
  File "/home/oebn/Projet-Scan/venv/lib/python3.11/site-packages/werkzeug/routing/map.py", line 924, in build
    raise BuildError(endpoint, values, method, self)
werkzeug.routing.exceptions.BuildError: Could not build url for endpoint 'exploit_routes.exploit_reports'. Did you mean 'exploit.list_reports' instead?
2025-05-17 18:29:44,087 - exploit_routes - INFO - [exploit_routes.py:88] - Accès à la liste des rapports d'exploitation
2025-05-17 18:29:45,290 - exploit_routes - INFO - [exploit_routes.py:106] - Accès au rapport d'exploitation: exploit_report_20250517_181850.json
2025-05-17 18:29:45,293 - exploit_routes - ERROR - [exploit_routes.py:130] - Erreur lors de la récupération du rapport: Could not build url for endpoint 'exploit_routes.exploit_reports'. Did you mean 'exploit.list_reports' instead?
Traceback (most recent call last):
  File "/home/oebn/Projet-Scan/routes/exploit_routes.py", line 128, in get_report
    return render_template("exploit_report.html", report=report, filename=filename)
           ^^^^^^^^^^^^^^^^^^^^^^^^^^^^^^^^^^^^^^^^^^^^^^^^^^^^^^^^^^^^^^^^^^^^^^^^
  File "/home/oebn/Projet-Scan/venv/lib/python3.11/site-packages/flask/templating.py", line 150, in render_template
    return _render(app, template, context)
           ^^^^^^^^^^^^^^^^^^^^^^^^^^^^^^^
  File "/home/oebn/Projet-Scan/venv/lib/python3.11/site-packages/flask/templating.py", line 131, in _render
    rv = template.render(context)
         ^^^^^^^^^^^^^^^^^^^^^^^^
  File "/home/oebn/Projet-Scan/venv/lib/python3.11/site-packages/jinja2/environment.py", line 1295, in render
    self.environment.handle_exception()
  File "/home/oebn/Projet-Scan/venv/lib/python3.11/site-packages/jinja2/environment.py", line 942, in handle_exception
    raise rewrite_traceback_stack(source=source)
  File "/home/oebn/Projet-Scan/templates/exploit_report.html", line 1, in top-level template code
    {% extends "base.html" %}
  File "/home/oebn/Projet-Scan/templates/base.html", line 66, in top-level template code
    {% block content %}
  File "/home/oebn/Projet-Scan/templates/exploit_report.html", line 19, in block 'content'
    <a href="{{ url_for('exploit_routes.exploit_reports') }}" class="btn btn-secondary">Retour aux Rapports</a>
    ^^^^^^^^^^^^^^^^^^^^^^^^^
  File "/home/oebn/Projet-Scan/venv/lib/python3.11/site-packages/flask/app.py", line 1121, in url_for
    return self.handle_url_build_error(error, endpoint, values)
           ^^^^^^^^^^^^^^^^^^^^^^^^^^^^^^^^^^^^^^^^^^^^^^^^^^^^
  File "/home/oebn/Projet-Scan/venv/lib/python3.11/site-packages/flask/app.py", line 1110, in url_for
    rv = url_adapter.build(  # type: ignore[union-attr]
         ^^^^^^^^^^^^^^^^^^^^^^^^^^^^^^^^^^^^^^^^^^^^^^
  File "/home/oebn/Projet-Scan/venv/lib/python3.11/site-packages/werkzeug/routing/map.py", line 924, in build
    raise BuildError(endpoint, values, method, self)
werkzeug.routing.exceptions.BuildError: Could not build url for endpoint 'exploit_routes.exploit_reports'. Did you mean 'exploit.list_reports' instead?
2025-05-17 18:29:48,209 - exploit_routes - INFO - [exploit_routes.py:106] - Accès au rapport d'exploitation: exploit_report_20250517_181850.json
2025-05-17 18:29:48,212 - exploit_routes - ERROR - [exploit_routes.py:130] - Erreur lors de la récupération du rapport: Could not build url for endpoint 'exploit_routes.exploit_reports'. Did you mean 'exploit.list_reports' instead?
Traceback (most recent call last):
  File "/home/oebn/Projet-Scan/routes/exploit_routes.py", line 128, in get_report
    return render_template("exploit_report.html", report=report, filename=filename)
           ^^^^^^^^^^^^^^^^^^^^^^^^^^^^^^^^^^^^^^^^^^^^^^^^^^^^^^^^^^^^^^^^^^^^^^^^
  File "/home/oebn/Projet-Scan/venv/lib/python3.11/site-packages/flask/templating.py", line 150, in render_template
    return _render(app, template, context)
           ^^^^^^^^^^^^^^^^^^^^^^^^^^^^^^^
  File "/home/oebn/Projet-Scan/venv/lib/python3.11/site-packages/flask/templating.py", line 131, in _render
    rv = template.render(context)
         ^^^^^^^^^^^^^^^^^^^^^^^^
  File "/home/oebn/Projet-Scan/venv/lib/python3.11/site-packages/jinja2/environment.py", line 1295, in render
    self.environment.handle_exception()
  File "/home/oebn/Projet-Scan/venv/lib/python3.11/site-packages/jinja2/environment.py", line 942, in handle_exception
    raise rewrite_traceback_stack(source=source)
  File "/home/oebn/Projet-Scan/templates/exploit_report.html", line 1, in top-level template code
    {% extends "base.html" %}
  File "/home/oebn/Projet-Scan/templates/base.html", line 66, in top-level template code
    {% block content %}
  File "/home/oebn/Projet-Scan/templates/exploit_report.html", line 19, in block 'content'
    <a href="{{ url_for('exploit_routes.exploit_reports') }}" class="btn btn-secondary">Retour aux Rapports</a>
    ^^^^^^^^^^^^^^^^^^^^^^^^^
  File "/home/oebn/Projet-Scan/venv/lib/python3.11/site-packages/flask/app.py", line 1121, in url_for
    return self.handle_url_build_error(error, endpoint, values)
           ^^^^^^^^^^^^^^^^^^^^^^^^^^^^^^^^^^^^^^^^^^^^^^^^^^^^
  File "/home/oebn/Projet-Scan/venv/lib/python3.11/site-packages/flask/app.py", line 1110, in url_for
    rv = url_adapter.build(  # type: ignore[union-attr]
         ^^^^^^^^^^^^^^^^^^^^^^^^^^^^^^^^^^^^^^^^^^^^^^
  File "/home/oebn/Projet-Scan/venv/lib/python3.11/site-packages/werkzeug/routing/map.py", line 924, in build
    raise BuildError(endpoint, values, method, self)
werkzeug.routing.exceptions.BuildError: Could not build url for endpoint 'exploit_routes.exploit_reports'. Did you mean 'exploit.list_reports' instead?
2025-05-17 18:34:23,647 - exploit_routes - INFO - [exploit_routes.py:106] - Accès au rapport d'exploitation: exploit_report_20250517_181850.json
2025-05-17 18:34:32,567 - exploit_routes - INFO - [exploit_routes.py:88] - Accès à la liste des rapports d'exploitation
2025-05-17 18:34:33,914 - exploit_routes - INFO - [exploit_routes.py:106] - Accès au rapport d'exploitation: exploit_report_20250517_181850.json
2025-05-17 18:35:05,863 - exploit_routes - INFO - [exploit_routes.py:88] - Accès à la liste des rapports d'exploitation
2025-05-17 18:37:02,174 - exploit_routes - INFO - [exploit_routes.py:106] - Accès au rapport d'exploitation: exploit_report_20250517_181850.json
2025-05-17 18:44:42,264 - exploit_routes - INFO - [exploit_routes.py:107] - Accès au rapport d'exploitation: exploit_report_20250517_181850.json
2025-05-17 18:44:42,292 - exploit_routes - ERROR - [exploit_routes.py:137] - Erreur lors de la récupération du rapport: 'now' is undefined
Traceback (most recent call last):
  File "/home/oebn/Projet-Scan/routes/exploit_routes.py", line 132, in get_report
    return render_template("exploit_report.html",
          ^^^^^^^^^^^^^^^^^^^^^^^^^^^^^^^^^^^^^^^
  File "/home/oebn/Projet-Scan/venv/lib/python3.11/site-packages/flask/templating.py", line 150, in render_template
    return _render(app, template, context)
           ^^^^^^^^^^^^^^^^^^^^^^^^^^^^^^^
  File "/home/oebn/Projet-Scan/venv/lib/python3.11/site-packages/flask/templating.py", line 131, in _render
    rv = template.render(context)
         ^^^^^^^^^^^^^^^^^^^^^^^^
  File "/home/oebn/Projet-Scan/venv/lib/python3.11/site-packages/jinja2/environment.py", line 1295, in render
    self.environment.handle_exception()
  File "/home/oebn/Projet-Scan/venv/lib/python3.11/site-packages/jinja2/environment.py", line 942, in handle_exception
    raise rewrite_traceback_stack(source=source)
  File "/home/oebn/Projet-Scan/templates/exploit_report.html", line 1, in top-level template code
    {% extends "base.html" %}
  File "/home/oebn/Projet-Scan/templates/base.html", line 66, in top-level template code
    {% block content %}
  File "/home/oebn/Projet-Scan/templates/exploit_report.html", line 6, in block 'content'
    <div class="timestamp">Généré le : {{ generated_on|default(now().strftime("%d/%m/%Y %H:%M:%S")) }}</div>
    ^^^^^^^^^^^^^^^^^^^^^^^^^
  File "/home/oebn/Projet-Scan/venv/lib/python3.11/site-packages/jinja2/utils.py", line 92, in from_obj
    if hasattr(obj, "jinja_pass_arg"):
       ^^^^^^^^^^^^^^^^^^^^^^^^^^^^^^
jinja2.exceptions.UndefinedError: 'now' is undefined
2025-05-17 18:44:45,302 - exploit_routes - INFO - [exploit_routes.py:89] - Accès à la liste des rapports d'exploitation
2025-05-17 18:44:46,607 - exploit_routes - INFO - [exploit_routes.py:107] - Accès au rapport d'exploitation: exploit_report_20250517_181850.json
2025-05-17 18:44:46,608 - exploit_routes - ERROR - [exploit_routes.py:137] - Erreur lors de la récupération du rapport: 'now' is undefined
Traceback (most recent call last):
  File "/home/oebn/Projet-Scan/routes/exploit_routes.py", line 132, in get_report
    return render_template("exploit_report.html",
          ^^^^^^^^^^^^^^^^^^^^^^^^^^^^^^^^^^^^^^^
  File "/home/oebn/Projet-Scan/venv/lib/python3.11/site-packages/flask/templating.py", line 150, in render_template
    return _render(app, template, context)
           ^^^^^^^^^^^^^^^^^^^^^^^^^^^^^^^
  File "/home/oebn/Projet-Scan/venv/lib/python3.11/site-packages/flask/templating.py", line 131, in _render
    rv = template.render(context)
         ^^^^^^^^^^^^^^^^^^^^^^^^
  File "/home/oebn/Projet-Scan/venv/lib/python3.11/site-packages/jinja2/environment.py", line 1295, in render
    self.environment.handle_exception()
  File "/home/oebn/Projet-Scan/venv/lib/python3.11/site-packages/jinja2/environment.py", line 942, in handle_exception
    raise rewrite_traceback_stack(source=source)
  File "/home/oebn/Projet-Scan/templates/exploit_report.html", line 1, in top-level template code
    {% extends "base.html" %}
  File "/home/oebn/Projet-Scan/templates/base.html", line 66, in top-level template code
    {% block content %}
  File "/home/oebn/Projet-Scan/templates/exploit_report.html", line 6, in block 'content'
    <div class="timestamp">Généré le : {{ generated_on|default(now().strftime("%d/%m/%Y %H:%M:%S")) }}</div>
    ^^^^^^^^^^^^^^^^^^^^^^^^^
  File "/home/oebn/Projet-Scan/venv/lib/python3.11/site-packages/jinja2/utils.py", line 92, in from_obj
    if hasattr(obj, "jinja_pass_arg"):
       ^^^^^^^^^^^^^^^^^^^^^^^^^^^^^^
jinja2.exceptions.UndefinedError: 'now' is undefined
2025-05-17 18:47:17,204 - exploit_routes - INFO - [exploit_routes.py:107] - Accès au rapport d'exploitation: exploit_report_20250517_181850.json
2025-05-17 18:47:25,014 - exploit_routes - INFO - [exploit_routes.py:143] - Génération du rapport PDF pour: exploit_report_20250517_181850.json
2025-05-17 18:47:25,049 - exploit_routes - ERROR - [exploit_routes.py:182] - Erreur lors de la génération du PDF: 'url_for' is undefined
Traceback (most recent call last):
  File "/home/oebn/Projet-Scan/routes/exploit_routes.py", line 174, in get_report_pdf
    pdf_path = generate_report("exploit", report_data, template_name="exploit_report.html", format="pdf")
               ^^^^^^^^^^^^^^^^^^^^^^^^^^^^^^^^^^^^^^^^^^^^^^^^^^^^^^^^^^^^^^^^^^^^^^^^^^^^^^^^^^^^^^^^^^
  File "/home/oebn/Projet-Scan/services/reporting_generator.py", line 64, in generate_report
    rendered = template.render(**data)
               ^^^^^^^^^^^^^^^^^^^^^^^
  File "/home/oebn/Projet-Scan/venv/lib/python3.11/site-packages/jinja2/environment.py", line 1295, in render
    self.environment.handle_exception()
  File "/home/oebn/Projet-Scan/venv/lib/python3.11/site-packages/jinja2/environment.py", line 942, in handle_exception
    raise rewrite_traceback_stack(source=source)
  File "templates/exploit_report.html", line 1, in top-level template code
    {% extends "base.html" %}
  File "templates/base.html", line 66, in top-level template code
    {% block content %}
  File "templates/exploit_report.html", line 154, in block 'content'
    <a href="{{ url_for('exploit.list_reports') }}" class="btn btn-secondary">
    ^^^^^^^^^^^^^^^^^^^^^^^^^
  File "/home/oebn/Projet-Scan/venv/lib/python3.11/site-packages/jinja2/utils.py", line 92, in from_obj
    if hasattr(obj, "jinja_pass_arg"):
       ^^^^^^^^^^^^^^^^^^^^^^^^^^^^^^
jinja2.exceptions.UndefinedError: 'url_for' is undefined
2025-05-17 18:47:34,569 - exploit_routes - INFO - [exploit_routes.py:107] - Accès au rapport d'exploitation: exploit_report_20250517_181850.json
2025-05-17 18:54:23,828 - exploit_routes - INFO - [exploit_routes.py:107] - Accès au rapport d'exploitation: exploit_report_20250517_181850.json
2025-05-17 18:54:27,748 - exploit_routes - INFO - [exploit_routes.py:188] - Génération du rapport PDF pour: exploit_report_20250517_181850.json
2025-05-17 18:54:27,784 - exploit_routes - ERROR - [exploit_routes.py:227] - Erreur lors de la génération du PDF: 'url_for' is undefined
Traceback (most recent call last):
  File "/home/oebn/Projet-Scan/routes/exploit_routes.py", line 219, in get_report_pdf
    pdf_path = generate_report("exploit", report_data, template_name="exploit_report.html", format="pdf")
               ^^^^^^^^^^^^^^^^^^^^^^^^^^^^^^^^^^^^^^^^^^^^^^^^^^^^^^^^^^^^^^^^^^^^^^^^^^^^^^^^^^^^^^^^^^
  File "/home/oebn/Projet-Scan/services/reporting_generator.py", line 64, in generate_report
    rendered = template.render(**data)
               ^^^^^^^^^^^^^^^^^^^^^^^
  File "/home/oebn/Projet-Scan/venv/lib/python3.11/site-packages/jinja2/environment.py", line 1295, in render
    self.environment.handle_exception()
  File "/home/oebn/Projet-Scan/venv/lib/python3.11/site-packages/jinja2/environment.py", line 942, in handle_exception
    raise rewrite_traceback_stack(source=source)
  File "templates/exploit_report.html", line 1, in top-level template code
    {% extends "base.html" %}
  File "templates/base.html", line 66, in top-level template code
    {% block content %}
  File "templates/exploit_report.html", line 154, in block 'content'
    <a href="{{ url_for('exploit.list_reports') }}" class="btn btn-secondary">
    ^^^^^^^^^^^^^^^^^^^^^^^^^
  File "/home/oebn/Projet-Scan/venv/lib/python3.11/site-packages/jinja2/utils.py", line 92, in from_obj
    if hasattr(obj, "jinja_pass_arg"):
       ^^^^^^^^^^^^^^^^^^^^^^^^^^^^^^
jinja2.exceptions.UndefinedError: 'url_for' is undefined
2025-05-17 18:54:29,806 - exploit_routes - INFO - [exploit_routes.py:143] - Téléchargement du rapport HTML pour: exploit_report_20250517_181850.json
2025-05-17 18:54:44,985 - exploit_routes - INFO - [exploit_routes.py:188] - Génération du rapport PDF pour: exploit_report_20250517_181850.json
2025-05-17 18:54:45,015 - exploit_routes - ERROR - [exploit_routes.py:227] - Erreur lors de la génération du PDF: 'url_for' is undefined
Traceback (most recent call last):
  File "/home/oebn/Projet-Scan/routes/exploit_routes.py", line 219, in get_report_pdf
    pdf_path = generate_report("exploit", report_data, template_name="exploit_report.html", format="pdf")
               ^^^^^^^^^^^^^^^^^^^^^^^^^^^^^^^^^^^^^^^^^^^^^^^^^^^^^^^^^^^^^^^^^^^^^^^^^^^^^^^^^^^^^^^^^^
  File "/home/oebn/Projet-Scan/services/reporting_generator.py", line 64, in generate_report
    rendered = template.render(**data)
               ^^^^^^^^^^^^^^^^^^^^^^^
  File "/home/oebn/Projet-Scan/venv/lib/python3.11/site-packages/jinja2/environment.py", line 1295, in render
    self.environment.handle_exception()
  File "/home/oebn/Projet-Scan/venv/lib/python3.11/site-packages/jinja2/environment.py", line 942, in handle_exception
    raise rewrite_traceback_stack(source=source)
  File "templates/exploit_report.html", line 1, in top-level template code
    {% extends "base.html" %}
  File "templates/base.html", line 66, in top-level template code
    {% block content %}
  File "templates/exploit_report.html", line 154, in block 'content'
    <a href="{{ url_for('exploit.list_reports') }}" class="btn btn-secondary">
    ^^^^^^^^^^^^^^^^^^^^^^^^^
  File "/home/oebn/Projet-Scan/venv/lib/python3.11/site-packages/jinja2/utils.py", line 92, in from_obj
    if hasattr(obj, "jinja_pass_arg"):
       ^^^^^^^^^^^^^^^^^^^^^^^^^^^^^^
jinja2.exceptions.UndefinedError: 'url_for' is undefined
2025-05-17 18:59:25,448 - exploit_routes - INFO - [exploit_routes.py:107] - Accès au rapport d'exploitation: exploit_report_20250517_181850.json
2025-05-17 18:59:28,158 - exploit_routes - INFO - [exploit_routes.py:188] - Génération du rapport PDF pour: exploit_report_20250517_181850.json
2025-05-17 19:01:21,762 - exploit_routes - INFO - [exploit_routes.py:257] - Vérification de l'exploitabilité de: ftp-vsftpd-backdoor
2025-05-17 19:01:21,764 - exploit_routes - INFO - [exploit_routes.py:264] - Module trouvé pour ftp-vsftpd-backdoor: exploit/unix/ftp/vsftpd_234_backdoor
2025-05-17 19:01:24,060 - exploit_routes - INFO - [exploit_routes.py:24] - Requête reçue pour lancer un exploit
2025-05-17 19:02:16,679 - exploit_routes - INFO - [exploit_routes.py:188] - Génération du rapport PDF pour: exploit_report_20250517_190204.json
2025-05-17 19:02:36,727 - exploit_routes - INFO - [exploit_routes.py:89] - Accès à la liste des rapports d'exploitation
2025-05-17 19:03:03,322 - exploit_routes - INFO - [exploit_routes.py:107] - Accès au rapport d'exploitation: exploit_report_20250517_181850.json
2025-05-17 20:06:34,939 - exploit_routes - INFO - [exploit_routes.py:257] - Vérification de l'exploitabilité de: ftp-vsftpd-backdoor
2025-05-17 20:06:34,954 - exploit_routes - INFO - [exploit_routes.py:264] - Module trouvé pour ftp-vsftpd-backdoor: exploit/unix/ftp/vsftpd_234_backdoor
2025-05-17 20:06:38,395 - exploit_routes - INFO - [exploit_routes.py:24] - Requête reçue pour lancer un exploit
2025-05-17 20:25:36,497 - exploit_routes - INFO - [exploit_routes.py:257] - Vérification de l'exploitabilité de: ftp-vsftpd-backdoor
2025-05-17 20:25:36,500 - exploit_routes - INFO - [exploit_routes.py:264] - Module trouvé pour ftp-vsftpd-backdoor: exploit/unix/ftp/vsftpd_234_backdoor
2025-05-17 20:37:43,931 - exploit_routes - INFO - [exploit_routes.py:257] - Vérification de l'exploitabilité de: ssl-poodle
2025-05-17 20:37:43,933 - exploit_routes - INFO - [exploit_routes.py:264] - Module trouvé pour ssl-poodle: auxiliary/scanner/ssl/openssl_fallback_check
2025-05-17 20:37:45,725 - exploit_routes - INFO - [exploit_routes.py:24] - Requête reçue pour lancer un exploit
2025-05-17 20:46:34,729 - exploit_routes - INFO - [exploit_routes.py:257] - Vérification de l'exploitabilité de: ftp-vsftpd-backdoor
2025-05-17 20:46:34,731 - exploit_routes - INFO - [exploit_routes.py:264] - Module trouvé pour ftp-vsftpd-backdoor: exploit/unix/ftp/vsftpd_234_backdoor
2025-05-17 20:46:47,002 - exploit_routes - INFO - [exploit_routes.py:24] - Requête reçue pour lancer un exploit
2025-05-17 20:47:49,995 - exploit_routes - INFO - [exploit_routes.py:89] - Accès à la liste des rapports d'exploitation
2025-05-17 20:47:53,341 - exploit_routes - INFO - [exploit_routes.py:107] - Accès au rapport d'exploitation: exploit_report_20250517_204641.json
2025-05-17 20:49:02,634 - exploit_routes - INFO - [exploit_routes.py:89] - Accès à la liste des rapports d'exploitation
2025-05-17 20:50:30,320 - exploit_routes - INFO - [exploit_routes.py:107] - Accès au rapport d'exploitation: exploit_report_20250517_204724.json
2025-05-17 21:00:27,560 - exploit_routes - INFO - [exploit_routes.py:89] - Accès à la liste des rapports d'exploitation
2025-05-17 21:00:37,794 - exploit_routes - INFO - [exploit_routes.py:89] - Accès à la liste des rapports d'exploitation
2025-05-21 06:45:10,304 - exploit_routes - INFO - [exploit_routes.py:89] - Accès à la liste des rapports d'exploitation
2025-05-21 08:35:29,519 - exploit_routes - INFO - [exploit_routes.py:89] - Accès à la liste des rapports d'exploitation
2025-05-21 08:36:22,741 - exploit_routes - INFO - [exploit_routes.py:89] - Accès à la liste des rapports d'exploitation
2025-05-21 08:39:04,072 - exploit_routes - INFO - [exploit_routes.py:89] - Accès à la liste des rapports d'exploitation
2025-05-21 08:39:07,088 - exploit_routes - INFO - [exploit_routes.py:107] - Accès au rapport d'exploitation: exploit_report_20250517_200731.json
