2025-05-08 15:15:32,703 - exploit_routes - ERROR - [exploit_routes.py:80] - Erreur lors de la récupération des rapports: exploit_reports.html
Traceback (most recent call last):
  File "/home/oebn/toolbox/routes/exploit_routes.py", line 78, in list_reports
    return render_template("exploit_reports.html", reports=reports)
           ^^^^^^^^^^^^^^^^^^^^^^^^^^^^^^^^^^^^^^^^^^^^^^^^^^^^^^^^
  File "/usr/local/lib/python3.11/dist-packages/flask/templating.py", line 149, in render_template
    template = app.jinja_env.get_or_select_template(template_name_or_list)
               ^^^^^^^^^^^^^^^^^^^^^^^^^^^^^^^^^^^^^^^^^^^^^^^^^^^^^^^^^^^
  File "/usr/local/lib/python3.11/dist-packages/jinja2/environment.py", line 1087, in get_or_select_template
    return self.get_template(template_name_or_list, parent, globals)
           ^^^^^^^^^^^^^^^^^^^^^^^^^^^^^^^^^^^^^^^^^^^^^^^^^^^^^^^^^
  File "/usr/local/lib/python3.11/dist-packages/jinja2/environment.py", line 1016, in get_template
    return self._load_template(name, globals)
           ^^^^^^^^^^^^^^^^^^^^^^^^^^^^^^^^^^
  File "/usr/local/lib/python3.11/dist-packages/jinja2/environment.py", line 975, in _load_template
    template = self.loader.load(self, name, self.make_globals(globals))
               ^^^^^^^^^^^^^^^^^^^^^^^^^^^^^^^^^^^^^^^^^^^^^^^^^^^^^^^^
  File "/usr/local/lib/python3.11/dist-packages/jinja2/loaders.py", line 126, in load
    source, filename, uptodate = self.get_source(environment, name)
                                 ^^^^^^^^^^^^^^^^^^^^^^^^^^^^^^^^^^
  File "/usr/local/lib/python3.11/dist-packages/flask/templating.py", line 65, in get_source
    return self._get_source_fast(environment, template)
           ^^^^^^^^^^^^^^^^^^^^^^^^^^^^^^^^^^^^^^^^^^^^
  File "/usr/local/lib/python3.11/dist-packages/flask/templating.py", line 99, in _get_source_fast
    raise TemplateNotFound(template)
jinja2.exceptions.TemplateNotFound: exploit_reports.html
2025-05-08 15:15:42,200 - exploit_routes - ERROR - [exploit_routes.py:80] - Erreur lors de la récupération des rapports: exploit_reports.html
Traceback (most recent call last):
  File "/home/oebn/toolbox/routes/exploit_routes.py", line 78, in list_reports
    return render_template("exploit_reports.html", reports=reports)
           ^^^^^^^^^^^^^^^^^^^^^^^^^^^^^^^^^^^^^^^^^^^^^^^^^^^^^^^^
  File "/usr/local/lib/python3.11/dist-packages/flask/templating.py", line 149, in render_template
    template = app.jinja_env.get_or_select_template(template_name_or_list)
               ^^^^^^^^^^^^^^^^^^^^^^^^^^^^^^^^^^^^^^^^^^^^^^^^^^^^^^^^^^^
  File "/usr/local/lib/python3.11/dist-packages/jinja2/environment.py", line 1087, in get_or_select_template
    return self.get_template(template_name_or_list, parent, globals)
           ^^^^^^^^^^^^^^^^^^^^^^^^^^^^^^^^^^^^^^^^^^^^^^^^^^^^^^^^^
  File "/usr/local/lib/python3.11/dist-packages/jinja2/environment.py", line 1016, in get_template
    return self._load_template(name, globals)
           ^^^^^^^^^^^^^^^^^^^^^^^^^^^^^^^^^^
  File "/usr/local/lib/python3.11/dist-packages/jinja2/environment.py", line 975, in _load_template
    template = self.loader.load(self, name, self.make_globals(globals))
               ^^^^^^^^^^^^^^^^^^^^^^^^^^^^^^^^^^^^^^^^^^^^^^^^^^^^^^^^
  File "/usr/local/lib/python3.11/dist-packages/jinja2/loaders.py", line 126, in load
    source, filename, uptodate = self.get_source(environment, name)
                                 ^^^^^^^^^^^^^^^^^^^^^^^^^^^^^^^^^^
  File "/usr/local/lib/python3.11/dist-packages/flask/templating.py", line 65, in get_source
    return self._get_source_fast(environment, template)
           ^^^^^^^^^^^^^^^^^^^^^^^^^^^^^^^^^^^^^^^^^^^^
  File "/usr/local/lib/python3.11/dist-packages/flask/templating.py", line 99, in _get_source_fast
    raise TemplateNotFound(template)
jinja2.exceptions.TemplateNotFound: exploit_reports.html
2025-05-08 17:38:43,740 - exploit_routes - INFO - [exploit_routes.py:153] - Vérification de l'exploitabilité de: ssl-ccs-injection
2025-05-08 17:38:43,743 - exploit_routes - INFO - [exploit_routes.py:160] - Module trouvé pour ssl-ccs-injection: auxiliary/scanner/ssl/openssl_ccs
2025-05-08 17:38:58,371 - exploit_routes - INFO - [exploit_routes.py:23] - Requête reçue pour lancer un exploit
2025-05-08 17:42:57,247 - exploit_routes - INFO - [exploit_routes.py:88] - Accès à la liste des rapports d'exploitation
2025-05-08 17:42:57,257 - exploit_routes - ERROR - [exploit_routes.py:98] - Erreur lors de la récupération des rapports: exploit_reports.html
Traceback (most recent call last):
  File "/home/oebn/toolbox/routes/exploit_routes.py", line 96, in list_reports
    return render_template("exploit_reports.html", reports=reports)
           ^^^^^^^^^^^^^^^^^^^^^^^^^^^^^^^^^^^^^^^^^^^^^^^^^^^^^^^^
  File "/usr/local/lib/python3.11/dist-packages/flask/templating.py", line 149, in render_template
    template = app.jinja_env.get_or_select_template(template_name_or_list)
               ^^^^^^^^^^^^^^^^^^^^^^^^^^^^^^^^^^^^^^^^^^^^^^^^^^^^^^^^^^^
  File "/usr/local/lib/python3.11/dist-packages/jinja2/environment.py", line 1087, in get_or_select_template
    return self.get_template(template_name_or_list, parent, globals)
           ^^^^^^^^^^^^^^^^^^^^^^^^^^^^^^^^^^^^^^^^^^^^^^^^^^^^^^^^^
  File "/usr/local/lib/python3.11/dist-packages/jinja2/environment.py", line 1016, in get_template
    return self._load_template(name, globals)
           ^^^^^^^^^^^^^^^^^^^^^^^^^^^^^^^^^^
  File "/usr/local/lib/python3.11/dist-packages/jinja2/environment.py", line 975, in _load_template
    template = self.loader.load(self, name, self.make_globals(globals))
               ^^^^^^^^^^^^^^^^^^^^^^^^^^^^^^^^^^^^^^^^^^^^^^^^^^^^^^^^
  File "/usr/local/lib/python3.11/dist-packages/jinja2/loaders.py", line 126, in load
    source, filename, uptodate = self.get_source(environment, name)
                                 ^^^^^^^^^^^^^^^^^^^^^^^^^^^^^^^^^^
  File "/usr/local/lib/python3.11/dist-packages/flask/templating.py", line 65, in get_source
    return self._get_source_fast(environment, template)
           ^^^^^^^^^^^^^^^^^^^^^^^^^^^^^^^^^^^^^^^^^^^^
  File "/usr/local/lib/python3.11/dist-packages/flask/templating.py", line 99, in _get_source_fast
    raise TemplateNotFound(template)
jinja2.exceptions.TemplateNotFound: exploit_reports.html
2025-05-08 17:43:42,444 - exploit_routes - INFO - [exploit_routes.py:153] - Vérification de l'exploitabilité de: http-slowloris-check
2025-05-08 17:43:42,455 - exploit_routes - INFO - [exploit_routes.py:160] - Module trouvé pour http-slowloris-check: auxiliary/dos/http/slowloris
2025-05-08 17:43:48,175 - exploit_routes - INFO - [exploit_routes.py:153] - Vérification de l'exploitabilité de: ssl-poodle
2025-05-08 17:43:48,175 - exploit_routes - INFO - [exploit_routes.py:160] - Module trouvé pour ssl-poodle: auxiliary/scanner/ssl/openssl_fallback_check
2025-05-08 17:43:51,493 - exploit_routes - INFO - [exploit_routes.py:153] - Vérification de l'exploitabilité de: ssl-dh-params
2025-05-08 17:43:51,494 - exploit_routes - INFO - [exploit_routes.py:160] - Module trouvé pour ssl-dh-params: auxiliary/scanner/ssl/ssl_version
2025-05-08 17:43:54,129 - exploit_routes - INFO - [exploit_routes.py:153] - Vérification de l'exploitabilité de: ssl-ccs-injection
2025-05-08 17:43:54,129 - exploit_routes - INFO - [exploit_routes.py:160] - Module trouvé pour ssl-ccs-injection: auxiliary/scanner/ssl/openssl_ccs
2025-05-08 17:43:56,655 - exploit_routes - INFO - [exploit_routes.py:153] - Vérification de l'exploitabilité de: http-vuln-cve2014-3704
2025-05-08 17:43:56,655 - exploit_routes - INFO - [exploit_routes.py:160] - Module trouvé pour http-vuln-cve2014-3704: exploit/unix/webapp/drupal_drupalgeddon
2025-05-08 17:44:47,407 - exploit_routes - INFO - [exploit_routes.py:153] - Vérification de l'exploitabilité de: ssl-dh-params
2025-05-08 17:44:47,408 - exploit_routes - INFO - [exploit_routes.py:160] - Module trouvé pour ssl-dh-params: auxiliary/scanner/ssl/ssl_version
2025-05-08 17:45:09,878 - exploit_routes - INFO - [exploit_routes.py:23] - Requête reçue pour lancer un exploit
2025-05-09 10:44:55,690 - exploit_routes - INFO - [exploit_routes.py:153] - Vérification de l'exploitabilité de: ssl-dh-params
2025-05-09 10:44:55,691 - exploit_routes - INFO - [exploit_routes.py:160] - Module trouvé pour ssl-dh-params: auxiliary/scanner/ssl/ssl_version
2025-05-09 10:45:04,254 - exploit_routes - INFO - [exploit_routes.py:153] - Vérification de l'exploitabilité de: http-slowloris-check
2025-05-09 10:45:04,254 - exploit_routes - INFO - [exploit_routes.py:160] - Module trouvé pour http-slowloris-check: auxiliary/dos/http/slowloris
2025-05-09 10:47:08,885 - exploit_routes - INFO - [exploit_routes.py:23] - Requête reçue pour lancer un exploit
2025-05-09 10:47:13,907 - exploit_routes - ERROR - [exploit_routes.py:58] - Metasploit n'est pas disponible sur le système. Veuillez installer Metasploit pour utiliser cette fonctionnalité.
2025-05-09 10:47:21,404 - exploit_routes - INFO - [exploit_routes.py:23] - Requête reçue pour lancer un exploit
2025-05-09 11:24:21,506 - exploit_routes - INFO - [exploit_routes.py:153] - Vérification de l'exploitabilité de: ssl-ccs-injection
2025-05-09 11:24:21,508 - exploit_routes - INFO - [exploit_routes.py:160] - Module trouvé pour ssl-ccs-injection: auxiliary/scanner/ssl/openssl_ccs
2025-05-09 11:24:59,888 - exploit_routes - INFO - [exploit_routes.py:23] - Requête reçue pour lancer un exploit
2025-05-09 11:28:56,584 - exploit_routes - INFO - [exploit_routes.py:88] - Accès à la liste des rapports d'exploitation
2025-05-09 11:28:56,584 - exploit_routes - ERROR - [exploit_routes.py:98] - Erreur lors de la récupération des rapports: exploit_reports.html
Traceback (most recent call last):
  File "/home/oebn/Projet-Scan/routes/exploit_routes.py", line 96, in list_reports
    return render_template("exploit_reports.html", reports=reports)
           ^^^^^^^^^^^^^^^^^^^^^^^^^^^^^^^^^^^^^^^^^^^^^^^^^^^^^^^^
  File "/usr/local/lib/python3.11/dist-packages/flask/templating.py", line 149, in render_template
    template = app.jinja_env.get_or_select_template(template_name_or_list)
               ^^^^^^^^^^^^^^^^^^^^^^^^^^^^^^^^^^^^^^^^^^^^^^^^^^^^^^^^^^^
  File "/usr/local/lib/python3.11/dist-packages/jinja2/environment.py", line 1087, in get_or_select_template
    return self.get_template(template_name_or_list, parent, globals)
           ^^^^^^^^^^^^^^^^^^^^^^^^^^^^^^^^^^^^^^^^^^^^^^^^^^^^^^^^^
  File "/usr/local/lib/python3.11/dist-packages/jinja2/environment.py", line 1016, in get_template
    return self._load_template(name, globals)
           ^^^^^^^^^^^^^^^^^^^^^^^^^^^^^^^^^^
  File "/usr/local/lib/python3.11/dist-packages/jinja2/environment.py", line 975, in _load_template
    template = self.loader.load(self, name, self.make_globals(globals))
               ^^^^^^^^^^^^^^^^^^^^^^^^^^^^^^^^^^^^^^^^^^^^^^^^^^^^^^^^
  File "/usr/local/lib/python3.11/dist-packages/jinja2/loaders.py", line 126, in load
    source, filename, uptodate = self.get_source(environment, name)
                                 ^^^^^^^^^^^^^^^^^^^^^^^^^^^^^^^^^^
  File "/usr/local/lib/python3.11/dist-packages/flask/templating.py", line 65, in get_source
    return self._get_source_fast(environment, template)
           ^^^^^^^^^^^^^^^^^^^^^^^^^^^^^^^^^^^^^^^^^^^^
  File "/usr/local/lib/python3.11/dist-packages/flask/templating.py", line 99, in _get_source_fast
    raise TemplateNotFound(template)
jinja2.exceptions.TemplateNotFound: exploit_reports.html
2025-05-09 11:29:44,075 - exploit_routes - INFO - [exploit_routes.py:88] - Accès à la liste des rapports d'exploitation
2025-05-09 11:29:44,099 - exploit_routes - ERROR - [exploit_routes.py:98] - Erreur lors de la récupération des rapports: 'report' is undefined
Traceback (most recent call last):
  File "/home/oebn/Projet-Scan/routes/exploit_routes.py", line 96, in list_reports
    return render_template("exploit_reports.html", reports=reports)
           ^^^^^^^^^^^^^^^^^^^^^^^^^^^^^^^^^^^^^^^^^^^^^^^^^^^^^^^^
  File "/usr/local/lib/python3.11/dist-packages/flask/templating.py", line 150, in render_template
    return _render(app, template, context)
           ^^^^^^^^^^^^^^^^^^^^^^^^^^^^^^^
  File "/usr/local/lib/python3.11/dist-packages/flask/templating.py", line 131, in _render
    rv = template.render(context)
         ^^^^^^^^^^^^^^^^^^^^^^^^
  File "/usr/local/lib/python3.11/dist-packages/jinja2/environment.py", line 1295, in render
    self.environment.handle_exception()
  File "/usr/local/lib/python3.11/dist-packages/jinja2/environment.py", line 942, in handle_exception
    raise rewrite_traceback_stack(source=source)
  File "/home/oebn/Projet-Scan/templates/exploit_reports.html", line 64, in top-level template code
    <p><strong>Vulnérabilité:</strong> {{ report.vulnerability }}</p>
    ^^^^^^^^^^^^^^^^^^^^^^^^^
  File "/usr/local/lib/python3.11/dist-packages/jinja2/environment.py", line 490, in getattr
    return getattr(obj, attribute)
           ^^^^^^^^^^^^^^^^^^^^^^^
jinja2.exceptions.UndefinedError: 'report' is undefined
2025-05-09 11:30:18,792 - exploit_routes - INFO - [exploit_routes.py:88] - Accès à la liste des rapports d'exploitation
2025-05-09 11:30:18,794 - exploit_routes - ERROR - [exploit_routes.py:98] - Erreur lors de la récupération des rapports: 'report' is undefined
Traceback (most recent call last):
  File "/home/oebn/Projet-Scan/routes/exploit_routes.py", line 96, in list_reports
    return render_template("exploit_reports.html", reports=reports)
           ^^^^^^^^^^^^^^^^^^^^^^^^^^^^^^^^^^^^^^^^^^^^^^^^^^^^^^^^
  File "/usr/local/lib/python3.11/dist-packages/flask/templating.py", line 150, in render_template
    return _render(app, template, context)
           ^^^^^^^^^^^^^^^^^^^^^^^^^^^^^^^
  File "/usr/local/lib/python3.11/dist-packages/flask/templating.py", line 131, in _render
    rv = template.render(context)
         ^^^^^^^^^^^^^^^^^^^^^^^^
  File "/usr/local/lib/python3.11/dist-packages/jinja2/environment.py", line 1295, in render
    self.environment.handle_exception()
  File "/usr/local/lib/python3.11/dist-packages/jinja2/environment.py", line 942, in handle_exception
    raise rewrite_traceback_stack(source=source)
  File "/home/oebn/Projet-Scan/templates/exploit_reports.html", line 64, in top-level template code
    <p><strong>Vulnérabilité:</strong> {{ report.vulnerability }}</p>
    ^^^^^^^^^^^^^^^^^^^^^^^^^
  File "/usr/local/lib/python3.11/dist-packages/jinja2/environment.py", line 490, in getattr
    return getattr(obj, attribute)
           ^^^^^^^^^^^^^^^^^^^^^^^
jinja2.exceptions.UndefinedError: 'report' is undefined
2025-05-09 11:34:38,992 - exploit_routes - INFO - [exploit_routes.py:88] - Accès à la liste des rapports d'exploitation
2025-05-09 11:34:38,993 - exploit_routes - ERROR - [exploit_routes.py:98] - Erreur lors de la récupération des rapports: 'report' is undefined
Traceback (most recent call last):
  File "/home/oebn/Projet-Scan/routes/exploit_routes.py", line 96, in list_reports
    # Debugger le contenu de 'reports' pour s'assurer qu'il est bien formaté
           ^^^^^^^^^^^^^^^^^^^^^^^^^^^^^^^^^^^^^^^^^^^^^^^^^^^^^^^^
  File "/usr/local/lib/python3.11/dist-packages/flask/templating.py", line 150, in render_template
    return _render(app, template, context)
           ^^^^^^^^^^^^^^^^^^^^^^^^^^^^^^^
  File "/usr/local/lib/python3.11/dist-packages/flask/templating.py", line 131, in _render
    rv = template.render(context)
         ^^^^^^^^^^^^^^^^^^^^^^^^
  File "/usr/local/lib/python3.11/dist-packages/jinja2/environment.py", line 1295, in render
    self.environment.handle_exception()
  File "/usr/local/lib/python3.11/dist-packages/jinja2/environment.py", line 942, in handle_exception
    raise rewrite_traceback_stack(source=source)
  File "/home/oebn/Projet-Scan/templates/exploit_reports.html", line 64, in top-level template code
    </tr>
  File "/usr/local/lib/python3.11/dist-packages/jinja2/environment.py", line 490, in getattr
    return getattr(obj, attribute)
           ^^^^^^^^^^^^^^^^^^^^^^^
jinja2.exceptions.UndefinedError: 'report' is undefined
2025-05-09 11:34:40,941 - exploit_routes - INFO - [exploit_routes.py:88] - Accès à la liste des rapports d'exploitation
2025-05-09 11:34:40,951 - exploit_routes - ERROR - [exploit_routes.py:98] - Erreur lors de la récupération des rapports: 'report' is undefined
Traceback (most recent call last):
  File "/home/oebn/Projet-Scan/routes/exploit_routes.py", line 96, in list_reports
    # Debugger le contenu de 'reports' pour s'assurer qu'il est bien formaté
           ^^^^^^^^^^^^^^^^^^^^^^^^^^^^^^^^^^^^^^^^^^^^^^^^^^^^^^^^
  File "/usr/local/lib/python3.11/dist-packages/flask/templating.py", line 150, in render_template
    return _render(app, template, context)
           ^^^^^^^^^^^^^^^^^^^^^^^^^^^^^^^
  File "/usr/local/lib/python3.11/dist-packages/flask/templating.py", line 131, in _render
    rv = template.render(context)
         ^^^^^^^^^^^^^^^^^^^^^^^^
  File "/usr/local/lib/python3.11/dist-packages/jinja2/environment.py", line 1295, in render
    self.environment.handle_exception()
  File "/usr/local/lib/python3.11/dist-packages/jinja2/environment.py", line 942, in handle_exception
    raise rewrite_traceback_stack(source=source)
  File "/home/oebn/Projet-Scan/templates/exploit_reports.html", line 64, in top-level template code
    </tr>
  File "/usr/local/lib/python3.11/dist-packages/jinja2/environment.py", line 490, in getattr
    return getattr(obj, attribute)
           ^^^^^^^^^^^^^^^^^^^^^^^
jinja2.exceptions.UndefinedError: 'report' is undefined
2025-05-09 11:34:41,517 - exploit_routes - INFO - [exploit_routes.py:88] - Accès à la liste des rapports d'exploitation
2025-05-09 11:34:41,517 - exploit_routes - ERROR - [exploit_routes.py:98] - Erreur lors de la récupération des rapports: 'report' is undefined
Traceback (most recent call last):
  File "/home/oebn/Projet-Scan/routes/exploit_routes.py", line 96, in list_reports
    # Debugger le contenu de 'reports' pour s'assurer qu'il est bien formaté
           ^^^^^^^^^^^^^^^^^^^^^^^^^^^^^^^^^^^^^^^^^^^^^^^^^^^^^^^^
  File "/usr/local/lib/python3.11/dist-packages/flask/templating.py", line 150, in render_template
    return _render(app, template, context)
           ^^^^^^^^^^^^^^^^^^^^^^^^^^^^^^^
  File "/usr/local/lib/python3.11/dist-packages/flask/templating.py", line 131, in _render
    rv = template.render(context)
         ^^^^^^^^^^^^^^^^^^^^^^^^
  File "/usr/local/lib/python3.11/dist-packages/jinja2/environment.py", line 1295, in render
    self.environment.handle_exception()
  File "/usr/local/lib/python3.11/dist-packages/jinja2/environment.py", line 942, in handle_exception
    raise rewrite_traceback_stack(source=source)
  File "/home/oebn/Projet-Scan/templates/exploit_reports.html", line 64, in top-level template code
    </tr>
  File "/usr/local/lib/python3.11/dist-packages/jinja2/environment.py", line 490, in getattr
    return getattr(obj, attribute)
           ^^^^^^^^^^^^^^^^^^^^^^^
jinja2.exceptions.UndefinedError: 'report' is undefined
2025-05-09 11:34:41,898 - exploit_routes - INFO - [exploit_routes.py:88] - Accès à la liste des rapports d'exploitation
2025-05-09 11:34:41,898 - exploit_routes - ERROR - [exploit_routes.py:98] - Erreur lors de la récupération des rapports: 'report' is undefined
Traceback (most recent call last):
  File "/home/oebn/Projet-Scan/routes/exploit_routes.py", line 96, in list_reports
    # Debugger le contenu de 'reports' pour s'assurer qu'il est bien formaté
           ^^^^^^^^^^^^^^^^^^^^^^^^^^^^^^^^^^^^^^^^^^^^^^^^^^^^^^^^
  File "/usr/local/lib/python3.11/dist-packages/flask/templating.py", line 150, in render_template
    return _render(app, template, context)
           ^^^^^^^^^^^^^^^^^^^^^^^^^^^^^^^
  File "/usr/local/lib/python3.11/dist-packages/flask/templating.py", line 131, in _render
    rv = template.render(context)
         ^^^^^^^^^^^^^^^^^^^^^^^^
  File "/usr/local/lib/python3.11/dist-packages/jinja2/environment.py", line 1295, in render
    self.environment.handle_exception()
  File "/usr/local/lib/python3.11/dist-packages/jinja2/environment.py", line 942, in handle_exception
    raise rewrite_traceback_stack(source=source)
  File "/home/oebn/Projet-Scan/templates/exploit_reports.html", line 64, in top-level template code
    </tr>
  File "/usr/local/lib/python3.11/dist-packages/jinja2/environment.py", line 490, in getattr
    return getattr(obj, attribute)
           ^^^^^^^^^^^^^^^^^^^^^^^
jinja2.exceptions.UndefinedError: 'report' is undefined
2025-05-09 11:34:42,098 - exploit_routes - INFO - [exploit_routes.py:88] - Accès à la liste des rapports d'exploitation
2025-05-09 11:34:42,098 - exploit_routes - ERROR - [exploit_routes.py:98] - Erreur lors de la récupération des rapports: 'report' is undefined
Traceback (most recent call last):
  File "/home/oebn/Projet-Scan/routes/exploit_routes.py", line 96, in list_reports
    # Debugger le contenu de 'reports' pour s'assurer qu'il est bien formaté
           ^^^^^^^^^^^^^^^^^^^^^^^^^^^^^^^^^^^^^^^^^^^^^^^^^^^^^^^^
  File "/usr/local/lib/python3.11/dist-packages/flask/templating.py", line 150, in render_template
    return _render(app, template, context)
           ^^^^^^^^^^^^^^^^^^^^^^^^^^^^^^^
  File "/usr/local/lib/python3.11/dist-packages/flask/templating.py", line 131, in _render
    rv = template.render(context)
         ^^^^^^^^^^^^^^^^^^^^^^^^
  File "/usr/local/lib/python3.11/dist-packages/jinja2/environment.py", line 1295, in render
    self.environment.handle_exception()
  File "/usr/local/lib/python3.11/dist-packages/jinja2/environment.py", line 942, in handle_exception
    raise rewrite_traceback_stack(source=source)
  File "/home/oebn/Projet-Scan/templates/exploit_reports.html", line 64, in top-level template code
    </tr>
  File "/usr/local/lib/python3.11/dist-packages/jinja2/environment.py", line 490, in getattr
    return getattr(obj, attribute)
           ^^^^^^^^^^^^^^^^^^^^^^^
jinja2.exceptions.UndefinedError: 'report' is undefined
2025-05-09 11:34:42,268 - exploit_routes - INFO - [exploit_routes.py:88] - Accès à la liste des rapports d'exploitation
2025-05-09 11:34:42,268 - exploit_routes - ERROR - [exploit_routes.py:98] - Erreur lors de la récupération des rapports: 'report' is undefined
Traceback (most recent call last):
  File "/home/oebn/Projet-Scan/routes/exploit_routes.py", line 96, in list_reports
    # Debugger le contenu de 'reports' pour s'assurer qu'il est bien formaté
           ^^^^^^^^^^^^^^^^^^^^^^^^^^^^^^^^^^^^^^^^^^^^^^^^^^^^^^^^
  File "/usr/local/lib/python3.11/dist-packages/flask/templating.py", line 150, in render_template
    return _render(app, template, context)
           ^^^^^^^^^^^^^^^^^^^^^^^^^^^^^^^
  File "/usr/local/lib/python3.11/dist-packages/flask/templating.py", line 131, in _render
    rv = template.render(context)
         ^^^^^^^^^^^^^^^^^^^^^^^^
  File "/usr/local/lib/python3.11/dist-packages/jinja2/environment.py", line 1295, in render
    self.environment.handle_exception()
  File "/usr/local/lib/python3.11/dist-packages/jinja2/environment.py", line 942, in handle_exception
    raise rewrite_traceback_stack(source=source)
  File "/home/oebn/Projet-Scan/templates/exploit_reports.html", line 64, in top-level template code
    </tr>
  File "/usr/local/lib/python3.11/dist-packages/jinja2/environment.py", line 490, in getattr
    return getattr(obj, attribute)
           ^^^^^^^^^^^^^^^^^^^^^^^
jinja2.exceptions.UndefinedError: 'report' is undefined
2025-05-09 11:34:42,500 - exploit_routes - INFO - [exploit_routes.py:88] - Accès à la liste des rapports d'exploitation
2025-05-09 11:34:42,500 - exploit_routes - ERROR - [exploit_routes.py:98] - Erreur lors de la récupération des rapports: 'report' is undefined
Traceback (most recent call last):
  File "/home/oebn/Projet-Scan/routes/exploit_routes.py", line 96, in list_reports
    # Debugger le contenu de 'reports' pour s'assurer qu'il est bien formaté
           ^^^^^^^^^^^^^^^^^^^^^^^^^^^^^^^^^^^^^^^^^^^^^^^^^^^^^^^^
  File "/usr/local/lib/python3.11/dist-packages/flask/templating.py", line 150, in render_template
    return _render(app, template, context)
           ^^^^^^^^^^^^^^^^^^^^^^^^^^^^^^^
  File "/usr/local/lib/python3.11/dist-packages/flask/templating.py", line 131, in _render
    rv = template.render(context)
         ^^^^^^^^^^^^^^^^^^^^^^^^
  File "/usr/local/lib/python3.11/dist-packages/jinja2/environment.py", line 1295, in render
    self.environment.handle_exception()
  File "/usr/local/lib/python3.11/dist-packages/jinja2/environment.py", line 942, in handle_exception
    raise rewrite_traceback_stack(source=source)
  File "/home/oebn/Projet-Scan/templates/exploit_reports.html", line 64, in top-level template code
    </tr>
  File "/usr/local/lib/python3.11/dist-packages/jinja2/environment.py", line 490, in getattr
    return getattr(obj, attribute)
           ^^^^^^^^^^^^^^^^^^^^^^^
jinja2.exceptions.UndefinedError: 'report' is undefined
2025-05-09 11:34:42,684 - exploit_routes - INFO - [exploit_routes.py:88] - Accès à la liste des rapports d'exploitation
2025-05-09 11:34:42,685 - exploit_routes - ERROR - [exploit_routes.py:98] - Erreur lors de la récupération des rapports: 'report' is undefined
Traceback (most recent call last):
  File "/home/oebn/Projet-Scan/routes/exploit_routes.py", line 96, in list_reports
    # Debugger le contenu de 'reports' pour s'assurer qu'il est bien formaté
           ^^^^^^^^^^^^^^^^^^^^^^^^^^^^^^^^^^^^^^^^^^^^^^^^^^^^^^^^
  File "/usr/local/lib/python3.11/dist-packages/flask/templating.py", line 150, in render_template
    return _render(app, template, context)
           ^^^^^^^^^^^^^^^^^^^^^^^^^^^^^^^
  File "/usr/local/lib/python3.11/dist-packages/flask/templating.py", line 131, in _render
    rv = template.render(context)
         ^^^^^^^^^^^^^^^^^^^^^^^^
  File "/usr/local/lib/python3.11/dist-packages/jinja2/environment.py", line 1295, in render
    self.environment.handle_exception()
  File "/usr/local/lib/python3.11/dist-packages/jinja2/environment.py", line 942, in handle_exception
    raise rewrite_traceback_stack(source=source)
  File "/home/oebn/Projet-Scan/templates/exploit_reports.html", line 64, in top-level template code
    </tr>
  File "/usr/local/lib/python3.11/dist-packages/jinja2/environment.py", line 490, in getattr
    return getattr(obj, attribute)
           ^^^^^^^^^^^^^^^^^^^^^^^
jinja2.exceptions.UndefinedError: 'report' is undefined
2025-05-09 11:34:42,885 - exploit_routes - INFO - [exploit_routes.py:88] - Accès à la liste des rapports d'exploitation
2025-05-09 11:34:42,885 - exploit_routes - ERROR - [exploit_routes.py:98] - Erreur lors de la récupération des rapports: 'report' is undefined
Traceback (most recent call last):
  File "/home/oebn/Projet-Scan/routes/exploit_routes.py", line 96, in list_reports
    # Debugger le contenu de 'reports' pour s'assurer qu'il est bien formaté
           ^^^^^^^^^^^^^^^^^^^^^^^^^^^^^^^^^^^^^^^^^^^^^^^^^^^^^^^^
  File "/usr/local/lib/python3.11/dist-packages/flask/templating.py", line 150, in render_template
    return _render(app, template, context)
           ^^^^^^^^^^^^^^^^^^^^^^^^^^^^^^^
  File "/usr/local/lib/python3.11/dist-packages/flask/templating.py", line 131, in _render
    rv = template.render(context)
         ^^^^^^^^^^^^^^^^^^^^^^^^
  File "/usr/local/lib/python3.11/dist-packages/jinja2/environment.py", line 1295, in render
    self.environment.handle_exception()
  File "/usr/local/lib/python3.11/dist-packages/jinja2/environment.py", line 942, in handle_exception
    raise rewrite_traceback_stack(source=source)
  File "/home/oebn/Projet-Scan/templates/exploit_reports.html", line 64, in top-level template code
    </tr>
  File "/usr/local/lib/python3.11/dist-packages/jinja2/environment.py", line 490, in getattr
    return getattr(obj, attribute)
           ^^^^^^^^^^^^^^^^^^^^^^^
jinja2.exceptions.UndefinedError: 'report' is undefined
2025-05-09 11:34:43,382 - exploit_routes - INFO - [exploit_routes.py:88] - Accès à la liste des rapports d'exploitation
2025-05-09 11:34:43,383 - exploit_routes - ERROR - [exploit_routes.py:98] - Erreur lors de la récupération des rapports: 'report' is undefined
Traceback (most recent call last):
  File "/home/oebn/Projet-Scan/routes/exploit_routes.py", line 96, in list_reports
    # Debugger le contenu de 'reports' pour s'assurer qu'il est bien formaté
           ^^^^^^^^^^^^^^^^^^^^^^^^^^^^^^^^^^^^^^^^^^^^^^^^^^^^^^^^
  File "/usr/local/lib/python3.11/dist-packages/flask/templating.py", line 150, in render_template
    return _render(app, template, context)
           ^^^^^^^^^^^^^^^^^^^^^^^^^^^^^^^
  File "/usr/local/lib/python3.11/dist-packages/flask/templating.py", line 131, in _render
    rv = template.render(context)
         ^^^^^^^^^^^^^^^^^^^^^^^^
  File "/usr/local/lib/python3.11/dist-packages/jinja2/environment.py", line 1295, in render
    self.environment.handle_exception()
  File "/usr/local/lib/python3.11/dist-packages/jinja2/environment.py", line 942, in handle_exception
    raise rewrite_traceback_stack(source=source)
  File "/home/oebn/Projet-Scan/templates/exploit_reports.html", line 64, in top-level template code
    </tr>
  File "/usr/local/lib/python3.11/dist-packages/jinja2/environment.py", line 490, in getattr
    return getattr(obj, attribute)
           ^^^^^^^^^^^^^^^^^^^^^^^
jinja2.exceptions.UndefinedError: 'report' is undefined
2025-05-09 11:34:43,551 - exploit_routes - INFO - [exploit_routes.py:88] - Accès à la liste des rapports d'exploitation
2025-05-09 11:34:43,552 - exploit_routes - ERROR - [exploit_routes.py:98] - Erreur lors de la récupération des rapports: 'report' is undefined
Traceback (most recent call last):
  File "/home/oebn/Projet-Scan/routes/exploit_routes.py", line 96, in list_reports
    # Debugger le contenu de 'reports' pour s'assurer qu'il est bien formaté
           ^^^^^^^^^^^^^^^^^^^^^^^^^^^^^^^^^^^^^^^^^^^^^^^^^^^^^^^^
  File "/usr/local/lib/python3.11/dist-packages/flask/templating.py", line 150, in render_template
    return _render(app, template, context)
           ^^^^^^^^^^^^^^^^^^^^^^^^^^^^^^^
  File "/usr/local/lib/python3.11/dist-packages/flask/templating.py", line 131, in _render
    rv = template.render(context)
         ^^^^^^^^^^^^^^^^^^^^^^^^
  File "/usr/local/lib/python3.11/dist-packages/jinja2/environment.py", line 1295, in render
    self.environment.handle_exception()
  File "/usr/local/lib/python3.11/dist-packages/jinja2/environment.py", line 942, in handle_exception
    raise rewrite_traceback_stack(source=source)
  File "/home/oebn/Projet-Scan/templates/exploit_reports.html", line 64, in top-level template code
    </tr>
  File "/usr/local/lib/python3.11/dist-packages/jinja2/environment.py", line 490, in getattr
    return getattr(obj, attribute)
           ^^^^^^^^^^^^^^^^^^^^^^^
jinja2.exceptions.UndefinedError: 'report' is undefined
2025-05-09 11:34:43,725 - exploit_routes - INFO - [exploit_routes.py:88] - Accès à la liste des rapports d'exploitation
2025-05-09 11:34:43,726 - exploit_routes - ERROR - [exploit_routes.py:98] - Erreur lors de la récupération des rapports: 'report' is undefined
Traceback (most recent call last):
  File "/home/oebn/Projet-Scan/routes/exploit_routes.py", line 96, in list_reports
    # Debugger le contenu de 'reports' pour s'assurer qu'il est bien formaté
           ^^^^^^^^^^^^^^^^^^^^^^^^^^^^^^^^^^^^^^^^^^^^^^^^^^^^^^^^
  File "/usr/local/lib/python3.11/dist-packages/flask/templating.py", line 150, in render_template
    return _render(app, template, context)
           ^^^^^^^^^^^^^^^^^^^^^^^^^^^^^^^
  File "/usr/local/lib/python3.11/dist-packages/flask/templating.py", line 131, in _render
    rv = template.render(context)
         ^^^^^^^^^^^^^^^^^^^^^^^^
  File "/usr/local/lib/python3.11/dist-packages/jinja2/environment.py", line 1295, in render
    self.environment.handle_exception()
  File "/usr/local/lib/python3.11/dist-packages/jinja2/environment.py", line 942, in handle_exception
    raise rewrite_traceback_stack(source=source)
  File "/home/oebn/Projet-Scan/templates/exploit_reports.html", line 64, in top-level template code
    </tr>
  File "/usr/local/lib/python3.11/dist-packages/jinja2/environment.py", line 490, in getattr
    return getattr(obj, attribute)
           ^^^^^^^^^^^^^^^^^^^^^^^
jinja2.exceptions.UndefinedError: 'report' is undefined
2025-05-09 11:34:51,594 - exploit_routes - INFO - [exploit_routes.py:88] - Accès à la liste des rapports d'exploitation
2025-05-09 11:34:59,280 - exploit_routes - INFO - [exploit_routes.py:88] - Accès à la liste des rapports d'exploitation
2025-05-15 21:32:30,362 - exploit_routes - INFO - [exploit_routes.py:155] - Vérification de l'exploitabilité de: ftp-vsftpd-backdoor
2025-05-15 21:32:30,368 - exploit_routes - INFO - [exploit_routes.py:162] - Module trouvé pour ftp-vsftpd-backdoor: exploit/unix/ftp/vsftpd_234_backdoor
2025-05-15 21:32:33,182 - exploit_routes - INFO - [exploit_routes.py:23] - Requête reçue pour lancer un exploit
2025-05-15 21:32:38,265 - exploit_routes - ERROR - [exploit_routes.py:58] - Metasploit n'est pas disponible sur le système. Veuillez installer Metasploit pour utiliser cette fonctionnalité.
2025-05-15 21:32:50,204 - exploit_routes - INFO - [exploit_routes.py:23] - Requête reçue pour lancer un exploit
2025-05-15 21:36:26,841 - exploit_routes - INFO - [exploit_routes.py:88] - Accès à la liste des rapports d'exploitation
2025-05-15 21:58:44,047 - exploit_routes - INFO - [exploit_routes.py:88] - Accès à la liste des rapports d'exploitation
2025-05-15 21:59:30,112 - exploit_routes - INFO - [exploit_routes.py:88] - Accès à la liste des rapports d'exploitation
2025-05-15 21:59:32,862 - exploit_routes - INFO - [exploit_routes.py:88] - Accès à la liste des rapports d'exploitation
2025-05-15 21:59:34,896 - exploit_routes - INFO - [exploit_routes.py:88] - Accès à la liste des rapports d'exploitation
2025-05-22 23:53:05,604 - exploit_routes - INFO - [exploit_routes.py:89] - Accès à la liste des rapports d'exploitation
2025-05-23 00:01:35,709 - exploit_routes - INFO - [exploit_routes.py:257] - Vérification de l'exploitabilité de: ftp-vsftpd-backdoor
2025-05-23 00:01:35,709 - exploit_routes - INFO - [exploit_routes.py:264] - Module trouvé pour ftp-vsftpd-backdoor: exploit/unix/ftp/vsftpd_234_backdoor
2025-05-23 00:01:42,184 - exploit_routes - INFO - [exploit_routes.py:24] - Requête reçue pour lancer un exploit
2025-05-23 00:01:47,251 - exploit_routes - ERROR - [exploit_routes.py:59] - Metasploit n'est pas disponible sur le système. Veuillez installer Metasploit pour utiliser cette fonctionnalité.
2025-05-23 00:01:51,367 - exploit_routes - INFO - [exploit_routes.py:24] - Requête reçue pour lancer un exploit
2025-05-23 00:01:56,377 - exploit_routes - ERROR - [exploit_routes.py:59] - Metasploit n'est pas disponible sur le système. Veuillez installer Metasploit pour utiliser cette fonctionnalité.
2025-05-23 00:02:38,923 - exploit_routes - INFO - [exploit_routes.py:24] - Requête reçue pour lancer un exploit
2025-05-23 00:02:43,947 - exploit_routes - ERROR - [exploit_routes.py:59] - Metasploit n'est pas disponible sur le système. Veuillez installer Metasploit pour utiliser cette fonctionnalité.
2025-05-23 00:10:52,243 - exploit_routes - INFO - [exploit_routes.py:24] - Requête reçue pour lancer un exploit
2025-05-23 00:12:27,484 - exploit_routes - INFO - [exploit_routes.py:107] - Accès au rapport d'exploitation: exploit_report_20250523_001147.json
2025-05-27 04:09:10,833 - exploit_routes - INFO - [exploit_routes.py:89] - Accès à la liste des rapports d'exploitation
2025-05-27 04:09:13,996 - exploit_routes - INFO - [exploit_routes.py:89] - Accès à la liste des rapports d'exploitation
2025-05-27 04:10:08,526 - exploit_routes - INFO - [exploit_routes.py:89] - Accès à la liste des rapports d'exploitation
2025-05-27 04:10:16,909 - exploit_routes - INFO - [exploit_routes.py:89] - Accès à la liste des rapports d'exploitation
2025-05-27 05:53:00,944 - exploit_routes - INFO - [exploit_routes.py:257] - Vérification de l'exploitabilité de: http-vuln-cve2017-1001000
2025-05-27 05:53:01,036 - exploit_routes - INFO - [exploit_routes.py:264] - Module trouvé pour http-vuln-cve2017-1001000: exploit/multi/http/struts_code_exec_classloader
2025-05-27 05:53:18,097 - exploit_routes - INFO - [exploit_routes.py:89] - Accès à la liste des rapports d'exploitation
2025-05-27 05:53:54,281 - exploit_routes - INFO - [exploit_routes.py:89] - Accès à la liste des rapports d'exploitation
2025-05-27 05:54:09,542 - exploit_routes - INFO - [exploit_routes.py:257] - Vérification de l'exploitabilité de: http-vuln-cve2017-1001000
2025-05-27 05:54:09,542 - exploit_routes - INFO - [exploit_routes.py:264] - Module trouvé pour http-vuln-cve2017-1001000: exploit/multi/http/struts_code_exec_classloader
2025-05-27 06:04:47,044 - exploit_routes - INFO - [exploit_routes.py:257] - Vérification de l'exploitabilité de: http-vuln-cve2017-1001000
2025-05-27 06:04:47,047 - exploit_routes - INFO - [exploit_routes.py:264] - Module trouvé pour http-vuln-cve2017-1001000: exploit/multi/http/struts_code_exec_classloader
2025-05-27 06:39:05,857 - exploit_routes - INFO - [exploit_routes.py:257] - Vérification de l'exploitabilité de: http-phpself-xss
2025-05-28 09:03:54,095 - exploit_routes - INFO - [exploit_routes.py:257] - Vérification de l'exploitabilité de: ftp-vsftpd-backdoor
2025-05-28 09:03:54,212 - exploit_routes - INFO - [exploit_routes.py:264] - Module trouvé pour ftp-vsftpd-backdoor: exploit/unix/ftp/vsftpd_234_backdoor
2025-05-28 09:04:26,244 - exploit_routes - INFO - [exploit_routes.py:24] - Requête reçue pour lancer un exploit
2025-05-28 09:04:31,463 - exploit_routes - ERROR - [exploit_routes.py:59] - Metasploit n'est pas disponible sur le système. Veuillez installer Metasploit pour utiliser cette fonctionnalité.
2025-05-28 09:04:35,753 - exploit_routes - INFO - [exploit_routes.py:24] - Requête reçue pour lancer un exploit
2025-05-28 09:04:40,755 - exploit_routes - ERROR - [exploit_routes.py:59] - Metasploit n'est pas disponible sur le système. Veuillez installer Metasploit pour utiliser cette fonctionnalité.
2025-05-28 09:05:18,802 - exploit_routes - INFO - [exploit_routes.py:24] - Requête reçue pour lancer un exploit
2025-05-28 09:05:23,805 - exploit_routes - ERROR - [exploit_routes.py:59] - Metasploit n'est pas disponible sur le système. Veuillez installer Metasploit pour utiliser cette fonctionnalité.
2025-05-28 09:05:50,086 - exploit_routes - INFO - [exploit_routes.py:24] - Requête reçue pour lancer un exploit
2025-05-28 09:05:55,088 - exploit_routes - ERROR - [exploit_routes.py:59] - Metasploit n'est pas disponible sur le système. Veuillez installer Metasploit pour utiliser cette fonctionnalité.
2025-05-28 09:07:39,059 - exploit_routes - INFO - [exploit_routes.py:24] - Requête reçue pour lancer un exploit
2025-05-28 09:07:44,062 - exploit_routes - ERROR - [exploit_routes.py:59] - Metasploit n'est pas disponible sur le système. Veuillez installer Metasploit pour utiliser cette fonctionnalité.
2025-05-28 09:07:53,541 - exploit_routes - INFO - [exploit_routes.py:24] - Requête reçue pour lancer un exploit
2025-05-28 09:07:54,966 - exploit_routes - INFO - [exploit_routes.py:24] - Requête reçue pour lancer un exploit
2025-05-28 09:07:55,162 - exploit_routes - INFO - [exploit_routes.py:24] - Requête reçue pour lancer un exploit
2025-05-28 09:07:58,545 - exploit_routes - ERROR - [exploit_routes.py:59] - Metasploit n'est pas disponible sur le système. Veuillez installer Metasploit pour utiliser cette fonctionnalité.
2025-05-28 09:07:59,969 - exploit_routes - ERROR - [exploit_routes.py:59] - Metasploit n'est pas disponible sur le système. Veuillez installer Metasploit pour utiliser cette fonctionnalité.
2025-05-28 09:08:00,165 - exploit_routes - ERROR - [exploit_routes.py:59] - Metasploit n'est pas disponible sur le système. Veuillez installer Metasploit pour utiliser cette fonctionnalité.
2025-05-28 09:09:15,592 - exploit_routes - INFO - [exploit_routes.py:24] - Requête reçue pour lancer un exploit
2025-05-28 09:09:20,641 - exploit_routes - ERROR - [exploit_routes.py:59] - Metasploit n'est pas disponible sur le système. Veuillez installer Metasploit pour utiliser cette fonctionnalité.
2025-05-28 09:24:11,541 - exploit_routes - INFO - [exploit_routes.py:257] - Vérification de l'exploitabilité de: ftp-vsftpd-backdoor
2025-05-28 09:24:11,541 - exploit_routes - INFO - [exploit_routes.py:264] - Module trouvé pour ftp-vsftpd-backdoor: exploit/unix/ftp/vsftpd_234_backdoor
2025-05-28 09:24:13,160 - exploit_routes - INFO - [exploit_routes.py:24] - Requête reçue pour lancer un exploit
2025-05-28 09:32:15,360 - exploit_routes - INFO - [exploit_routes.py:257] - Vérification de l'exploitabilité de: ftp-vsftpd-backdoor
2025-05-28 09:32:15,362 - exploit_routes - INFO - [exploit_routes.py:264] - Module trouvé pour ftp-vsftpd-backdoor: exploit/unix/ftp/vsftpd_234_backdoor
2025-05-28 09:32:32,224 - exploit_routes - INFO - [exploit_routes.py:24] - Requête reçue pour lancer un exploit
2025-05-28 09:38:47,757 - exploit_routes - INFO - [exploit_routes.py:107] - Accès au rapport d'exploitation: exploit_report_20250528_093304.json
2025-05-28 09:40:34,035 - exploit_routes - INFO - [exploit_routes.py:89] - Accès à la liste des rapports d'exploitation
2025-05-28 09:40:39,469 - exploit_routes - INFO - [exploit_routes.py:107] - Accès au rapport d'exploitation: exploit_report_20250528_093304.json
