2025-05-08 15:15:32,703 - exploit_routes - ERROR - [exploit_routes.py:80] - Erreur lors de la récupération des rapports: exploit_reports.html
Traceback (most recent call last):
  File "/home/oebn/toolbox/routes/exploit_routes.py", line 78, in list_reports
    return render_template("exploit_reports.html", reports=reports)
           ^^^^^^^^^^^^^^^^^^^^^^^^^^^^^^^^^^^^^^^^^^^^^^^^^^^^^^^^
  File "/usr/local/lib/python3.11/dist-packages/flask/templating.py", line 149, in render_template
    template = app.jinja_env.get_or_select_template(template_name_or_list)
               ^^^^^^^^^^^^^^^^^^^^^^^^^^^^^^^^^^^^^^^^^^^^^^^^^^^^^^^^^^^
  File "/usr/local/lib/python3.11/dist-packages/jinja2/environment.py", line 1087, in get_or_select_template
    return self.get_template(template_name_or_list, parent, globals)
           ^^^^^^^^^^^^^^^^^^^^^^^^^^^^^^^^^^^^^^^^^^^^^^^^^^^^^^^^^
  File "/usr/local/lib/python3.11/dist-packages/jinja2/environment.py", line 1016, in get_template
    return self._load_template(name, globals)
           ^^^^^^^^^^^^^^^^^^^^^^^^^^^^^^^^^^
  File "/usr/local/lib/python3.11/dist-packages/jinja2/environment.py", line 975, in _load_template
    template = self.loader.load(self, name, self.make_globals(globals))
               ^^^^^^^^^^^^^^^^^^^^^^^^^^^^^^^^^^^^^^^^^^^^^^^^^^^^^^^^
  File "/usr/local/lib/python3.11/dist-packages/jinja2/loaders.py", line 126, in load
    source, filename, uptodate = self.get_source(environment, name)
                                 ^^^^^^^^^^^^^^^^^^^^^^^^^^^^^^^^^^
  File "/usr/local/lib/python3.11/dist-packages/flask/templating.py", line 65, in get_source
    return self._get_source_fast(environment, template)
           ^^^^^^^^^^^^^^^^^^^^^^^^^^^^^^^^^^^^^^^^^^^^
  File "/usr/local/lib/python3.11/dist-packages/flask/templating.py", line 99, in _get_source_fast
    raise TemplateNotFound(template)
jinja2.exceptions.TemplateNotFound: exploit_reports.html
2025-05-08 15:15:42,200 - exploit_routes - ERROR - [exploit_routes.py:80] - Erreur lors de la récupération des rapports: exploit_reports.html
Traceback (most recent call last):
  File "/home/oebn/toolbox/routes/exploit_routes.py", line 78, in list_reports
    return render_template("exploit_reports.html", reports=reports)
           ^^^^^^^^^^^^^^^^^^^^^^^^^^^^^^^^^^^^^^^^^^^^^^^^^^^^^^^^
  File "/usr/local/lib/python3.11/dist-packages/flask/templating.py", line 149, in render_template
    template = app.jinja_env.get_or_select_template(template_name_or_list)
               ^^^^^^^^^^^^^^^^^^^^^^^^^^^^^^^^^^^^^^^^^^^^^^^^^^^^^^^^^^^
  File "/usr/local/lib/python3.11/dist-packages/jinja2/environment.py", line 1087, in get_or_select_template
    return self.get_template(template_name_or_list, parent, globals)
           ^^^^^^^^^^^^^^^^^^^^^^^^^^^^^^^^^^^^^^^^^^^^^^^^^^^^^^^^^
  File "/usr/local/lib/python3.11/dist-packages/jinja2/environment.py", line 1016, in get_template
    return self._load_template(name, globals)
           ^^^^^^^^^^^^^^^^^^^^^^^^^^^^^^^^^^
  File "/usr/local/lib/python3.11/dist-packages/jinja2/environment.py", line 975, in _load_template
    template = self.loader.load(self, name, self.make_globals(globals))
               ^^^^^^^^^^^^^^^^^^^^^^^^^^^^^^^^^^^^^^^^^^^^^^^^^^^^^^^^
  File "/usr/local/lib/python3.11/dist-packages/jinja2/loaders.py", line 126, in load
    source, filename, uptodate = self.get_source(environment, name)
                                 ^^^^^^^^^^^^^^^^^^^^^^^^^^^^^^^^^^
  File "/usr/local/lib/python3.11/dist-packages/flask/templating.py", line 65, in get_source
    return self._get_source_fast(environment, template)
           ^^^^^^^^^^^^^^^^^^^^^^^^^^^^^^^^^^^^^^^^^^^^
  File "/usr/local/lib/python3.11/dist-packages/flask/templating.py", line 99, in _get_source_fast
    raise TemplateNotFound(template)
jinja2.exceptions.TemplateNotFound: exploit_reports.html
2025-05-08 17:42:57,257 - exploit_routes - ERROR - [exploit_routes.py:98] - Erreur lors de la récupération des rapports: exploit_reports.html
Traceback (most recent call last):
  File "/home/oebn/toolbox/routes/exploit_routes.py", line 96, in list_reports
    return render_template("exploit_reports.html", reports=reports)
           ^^^^^^^^^^^^^^^^^^^^^^^^^^^^^^^^^^^^^^^^^^^^^^^^^^^^^^^^
  File "/usr/local/lib/python3.11/dist-packages/flask/templating.py", line 149, in render_template
    template = app.jinja_env.get_or_select_template(template_name_or_list)
               ^^^^^^^^^^^^^^^^^^^^^^^^^^^^^^^^^^^^^^^^^^^^^^^^^^^^^^^^^^^
  File "/usr/local/lib/python3.11/dist-packages/jinja2/environment.py", line 1087, in get_or_select_template
    return self.get_template(template_name_or_list, parent, globals)
           ^^^^^^^^^^^^^^^^^^^^^^^^^^^^^^^^^^^^^^^^^^^^^^^^^^^^^^^^^
  File "/usr/local/lib/python3.11/dist-packages/jinja2/environment.py", line 1016, in get_template
    return self._load_template(name, globals)
           ^^^^^^^^^^^^^^^^^^^^^^^^^^^^^^^^^^
  File "/usr/local/lib/python3.11/dist-packages/jinja2/environment.py", line 975, in _load_template
    template = self.loader.load(self, name, self.make_globals(globals))
               ^^^^^^^^^^^^^^^^^^^^^^^^^^^^^^^^^^^^^^^^^^^^^^^^^^^^^^^^
  File "/usr/local/lib/python3.11/dist-packages/jinja2/loaders.py", line 126, in load
    source, filename, uptodate = self.get_source(environment, name)
                                 ^^^^^^^^^^^^^^^^^^^^^^^^^^^^^^^^^^
  File "/usr/local/lib/python3.11/dist-packages/flask/templating.py", line 65, in get_source
    return self._get_source_fast(environment, template)
           ^^^^^^^^^^^^^^^^^^^^^^^^^^^^^^^^^^^^^^^^^^^^
  File "/usr/local/lib/python3.11/dist-packages/flask/templating.py", line 99, in _get_source_fast
    raise TemplateNotFound(template)
jinja2.exceptions.TemplateNotFound: exploit_reports.html
2025-05-09 10:47:13,907 - exploit_routes - ERROR - [exploit_routes.py:58] - Metasploit n'est pas disponible sur le système. Veuillez installer Metasploit pour utiliser cette fonctionnalité.
2025-05-09 11:28:56,584 - exploit_routes - ERROR - [exploit_routes.py:98] - Erreur lors de la récupération des rapports: exploit_reports.html
Traceback (most recent call last):
  File "/home/oebn/Projet-Scan/routes/exploit_routes.py", line 96, in list_reports
    return render_template("exploit_reports.html", reports=reports)
           ^^^^^^^^^^^^^^^^^^^^^^^^^^^^^^^^^^^^^^^^^^^^^^^^^^^^^^^^
  File "/usr/local/lib/python3.11/dist-packages/flask/templating.py", line 149, in render_template
    template = app.jinja_env.get_or_select_template(template_name_or_list)
               ^^^^^^^^^^^^^^^^^^^^^^^^^^^^^^^^^^^^^^^^^^^^^^^^^^^^^^^^^^^
  File "/usr/local/lib/python3.11/dist-packages/jinja2/environment.py", line 1087, in get_or_select_template
    return self.get_template(template_name_or_list, parent, globals)
           ^^^^^^^^^^^^^^^^^^^^^^^^^^^^^^^^^^^^^^^^^^^^^^^^^^^^^^^^^
  File "/usr/local/lib/python3.11/dist-packages/jinja2/environment.py", line 1016, in get_template
    return self._load_template(name, globals)
           ^^^^^^^^^^^^^^^^^^^^^^^^^^^^^^^^^^
  File "/usr/local/lib/python3.11/dist-packages/jinja2/environment.py", line 975, in _load_template
    template = self.loader.load(self, name, self.make_globals(globals))
               ^^^^^^^^^^^^^^^^^^^^^^^^^^^^^^^^^^^^^^^^^^^^^^^^^^^^^^^^
  File "/usr/local/lib/python3.11/dist-packages/jinja2/loaders.py", line 126, in load
    source, filename, uptodate = self.get_source(environment, name)
                                 ^^^^^^^^^^^^^^^^^^^^^^^^^^^^^^^^^^
  File "/usr/local/lib/python3.11/dist-packages/flask/templating.py", line 65, in get_source
    return self._get_source_fast(environment, template)
           ^^^^^^^^^^^^^^^^^^^^^^^^^^^^^^^^^^^^^^^^^^^^
  File "/usr/local/lib/python3.11/dist-packages/flask/templating.py", line 99, in _get_source_fast
    raise TemplateNotFound(template)
jinja2.exceptions.TemplateNotFound: exploit_reports.html
2025-05-09 11:29:44,099 - exploit_routes - ERROR - [exploit_routes.py:98] - Erreur lors de la récupération des rapports: 'report' is undefined
Traceback (most recent call last):
  File "/home/oebn/Projet-Scan/routes/exploit_routes.py", line 96, in list_reports
    return render_template("exploit_reports.html", reports=reports)
           ^^^^^^^^^^^^^^^^^^^^^^^^^^^^^^^^^^^^^^^^^^^^^^^^^^^^^^^^
  File "/usr/local/lib/python3.11/dist-packages/flask/templating.py", line 150, in render_template
    return _render(app, template, context)
           ^^^^^^^^^^^^^^^^^^^^^^^^^^^^^^^
  File "/usr/local/lib/python3.11/dist-packages/flask/templating.py", line 131, in _render
    rv = template.render(context)
         ^^^^^^^^^^^^^^^^^^^^^^^^
  File "/usr/local/lib/python3.11/dist-packages/jinja2/environment.py", line 1295, in render
    self.environment.handle_exception()
  File "/usr/local/lib/python3.11/dist-packages/jinja2/environment.py", line 942, in handle_exception
    raise rewrite_traceback_stack(source=source)
  File "/home/oebn/Projet-Scan/templates/exploit_reports.html", line 64, in top-level template code
    <p><strong>Vulnérabilité:</strong> {{ report.vulnerability }}</p>
    ^^^^^^^^^^^^^^^^^^^^^^^^^
  File "/usr/local/lib/python3.11/dist-packages/jinja2/environment.py", line 490, in getattr
    return getattr(obj, attribute)
           ^^^^^^^^^^^^^^^^^^^^^^^
jinja2.exceptions.UndefinedError: 'report' is undefined
2025-05-09 11:30:18,794 - exploit_routes - ERROR - [exploit_routes.py:98] - Erreur lors de la récupération des rapports: 'report' is undefined
Traceback (most recent call last):
  File "/home/oebn/Projet-Scan/routes/exploit_routes.py", line 96, in list_reports
    return render_template("exploit_reports.html", reports=reports)
           ^^^^^^^^^^^^^^^^^^^^^^^^^^^^^^^^^^^^^^^^^^^^^^^^^^^^^^^^
  File "/usr/local/lib/python3.11/dist-packages/flask/templating.py", line 150, in render_template
    return _render(app, template, context)
           ^^^^^^^^^^^^^^^^^^^^^^^^^^^^^^^
  File "/usr/local/lib/python3.11/dist-packages/flask/templating.py", line 131, in _render
    rv = template.render(context)
         ^^^^^^^^^^^^^^^^^^^^^^^^
  File "/usr/local/lib/python3.11/dist-packages/jinja2/environment.py", line 1295, in render
    self.environment.handle_exception()
  File "/usr/local/lib/python3.11/dist-packages/jinja2/environment.py", line 942, in handle_exception
    raise rewrite_traceback_stack(source=source)
  File "/home/oebn/Projet-Scan/templates/exploit_reports.html", line 64, in top-level template code
    <p><strong>Vulnérabilité:</strong> {{ report.vulnerability }}</p>
    ^^^^^^^^^^^^^^^^^^^^^^^^^
  File "/usr/local/lib/python3.11/dist-packages/jinja2/environment.py", line 490, in getattr
    return getattr(obj, attribute)
           ^^^^^^^^^^^^^^^^^^^^^^^
jinja2.exceptions.UndefinedError: 'report' is undefined
2025-05-09 11:34:38,993 - exploit_routes - ERROR - [exploit_routes.py:98] - Erreur lors de la récupération des rapports: 'report' is undefined
Traceback (most recent call last):
  File "/home/oebn/Projet-Scan/routes/exploit_routes.py", line 96, in list_reports
    # Debugger le contenu de 'reports' pour s'assurer qu'il est bien formaté
           ^^^^^^^^^^^^^^^^^^^^^^^^^^^^^^^^^^^^^^^^^^^^^^^^^^^^^^^^
  File "/usr/local/lib/python3.11/dist-packages/flask/templating.py", line 150, in render_template
    return _render(app, template, context)
           ^^^^^^^^^^^^^^^^^^^^^^^^^^^^^^^
  File "/usr/local/lib/python3.11/dist-packages/flask/templating.py", line 131, in _render
    rv = template.render(context)
         ^^^^^^^^^^^^^^^^^^^^^^^^
  File "/usr/local/lib/python3.11/dist-packages/jinja2/environment.py", line 1295, in render
    self.environment.handle_exception()
  File "/usr/local/lib/python3.11/dist-packages/jinja2/environment.py", line 942, in handle_exception
    raise rewrite_traceback_stack(source=source)
  File "/home/oebn/Projet-Scan/templates/exploit_reports.html", line 64, in top-level template code
    </tr>
  File "/usr/local/lib/python3.11/dist-packages/jinja2/environment.py", line 490, in getattr
    return getattr(obj, attribute)
           ^^^^^^^^^^^^^^^^^^^^^^^
jinja2.exceptions.UndefinedError: 'report' is undefined
2025-05-09 11:34:40,951 - exploit_routes - ERROR - [exploit_routes.py:98] - Erreur lors de la récupération des rapports: 'report' is undefined
Traceback (most recent call last):
  File "/home/oebn/Projet-Scan/routes/exploit_routes.py", line 96, in list_reports
    # Debugger le contenu de 'reports' pour s'assurer qu'il est bien formaté
           ^^^^^^^^^^^^^^^^^^^^^^^^^^^^^^^^^^^^^^^^^^^^^^^^^^^^^^^^
  File "/usr/local/lib/python3.11/dist-packages/flask/templating.py", line 150, in render_template
    return _render(app, template, context)
           ^^^^^^^^^^^^^^^^^^^^^^^^^^^^^^^
  File "/usr/local/lib/python3.11/dist-packages/flask/templating.py", line 131, in _render
    rv = template.render(context)
         ^^^^^^^^^^^^^^^^^^^^^^^^
  File "/usr/local/lib/python3.11/dist-packages/jinja2/environment.py", line 1295, in render
    self.environment.handle_exception()
  File "/usr/local/lib/python3.11/dist-packages/jinja2/environment.py", line 942, in handle_exception
    raise rewrite_traceback_stack(source=source)
  File "/home/oebn/Projet-Scan/templates/exploit_reports.html", line 64, in top-level template code
    </tr>
  File "/usr/local/lib/python3.11/dist-packages/jinja2/environment.py", line 490, in getattr
    return getattr(obj, attribute)
           ^^^^^^^^^^^^^^^^^^^^^^^
jinja2.exceptions.UndefinedError: 'report' is undefined
2025-05-09 11:34:41,517 - exploit_routes - ERROR - [exploit_routes.py:98] - Erreur lors de la récupération des rapports: 'report' is undefined
Traceback (most recent call last):
  File "/home/oebn/Projet-Scan/routes/exploit_routes.py", line 96, in list_reports
    # Debugger le contenu de 'reports' pour s'assurer qu'il est bien formaté
           ^^^^^^^^^^^^^^^^^^^^^^^^^^^^^^^^^^^^^^^^^^^^^^^^^^^^^^^^
  File "/usr/local/lib/python3.11/dist-packages/flask/templating.py", line 150, in render_template
    return _render(app, template, context)
           ^^^^^^^^^^^^^^^^^^^^^^^^^^^^^^^
  File "/usr/local/lib/python3.11/dist-packages/flask/templating.py", line 131, in _render
    rv = template.render(context)
         ^^^^^^^^^^^^^^^^^^^^^^^^
  File "/usr/local/lib/python3.11/dist-packages/jinja2/environment.py", line 1295, in render
    self.environment.handle_exception()
  File "/usr/local/lib/python3.11/dist-packages/jinja2/environment.py", line 942, in handle_exception
    raise rewrite_traceback_stack(source=source)
  File "/home/oebn/Projet-Scan/templates/exploit_reports.html", line 64, in top-level template code
    </tr>
  File "/usr/local/lib/python3.11/dist-packages/jinja2/environment.py", line 490, in getattr
    return getattr(obj, attribute)
           ^^^^^^^^^^^^^^^^^^^^^^^
jinja2.exceptions.UndefinedError: 'report' is undefined
2025-05-09 11:34:41,898 - exploit_routes - ERROR - [exploit_routes.py:98] - Erreur lors de la récupération des rapports: 'report' is undefined
Traceback (most recent call last):
  File "/home/oebn/Projet-Scan/routes/exploit_routes.py", line 96, in list_reports
    # Debugger le contenu de 'reports' pour s'assurer qu'il est bien formaté
           ^^^^^^^^^^^^^^^^^^^^^^^^^^^^^^^^^^^^^^^^^^^^^^^^^^^^^^^^
  File "/usr/local/lib/python3.11/dist-packages/flask/templating.py", line 150, in render_template
    return _render(app, template, context)
           ^^^^^^^^^^^^^^^^^^^^^^^^^^^^^^^
  File "/usr/local/lib/python3.11/dist-packages/flask/templating.py", line 131, in _render
    rv = template.render(context)
         ^^^^^^^^^^^^^^^^^^^^^^^^
  File "/usr/local/lib/python3.11/dist-packages/jinja2/environment.py", line 1295, in render
    self.environment.handle_exception()
  File "/usr/local/lib/python3.11/dist-packages/jinja2/environment.py", line 942, in handle_exception
    raise rewrite_traceback_stack(source=source)
  File "/home/oebn/Projet-Scan/templates/exploit_reports.html", line 64, in top-level template code
    </tr>
  File "/usr/local/lib/python3.11/dist-packages/jinja2/environment.py", line 490, in getattr
    return getattr(obj, attribute)
           ^^^^^^^^^^^^^^^^^^^^^^^
jinja2.exceptions.UndefinedError: 'report' is undefined
2025-05-09 11:34:42,098 - exploit_routes - ERROR - [exploit_routes.py:98] - Erreur lors de la récupération des rapports: 'report' is undefined
Traceback (most recent call last):
  File "/home/oebn/Projet-Scan/routes/exploit_routes.py", line 96, in list_reports
    # Debugger le contenu de 'reports' pour s'assurer qu'il est bien formaté
           ^^^^^^^^^^^^^^^^^^^^^^^^^^^^^^^^^^^^^^^^^^^^^^^^^^^^^^^^
  File "/usr/local/lib/python3.11/dist-packages/flask/templating.py", line 150, in render_template
    return _render(app, template, context)
           ^^^^^^^^^^^^^^^^^^^^^^^^^^^^^^^
  File "/usr/local/lib/python3.11/dist-packages/flask/templating.py", line 131, in _render
    rv = template.render(context)
         ^^^^^^^^^^^^^^^^^^^^^^^^
  File "/usr/local/lib/python3.11/dist-packages/jinja2/environment.py", line 1295, in render
    self.environment.handle_exception()
  File "/usr/local/lib/python3.11/dist-packages/jinja2/environment.py", line 942, in handle_exception
    raise rewrite_traceback_stack(source=source)
  File "/home/oebn/Projet-Scan/templates/exploit_reports.html", line 64, in top-level template code
    </tr>
  File "/usr/local/lib/python3.11/dist-packages/jinja2/environment.py", line 490, in getattr
    return getattr(obj, attribute)
           ^^^^^^^^^^^^^^^^^^^^^^^
jinja2.exceptions.UndefinedError: 'report' is undefined
2025-05-09 11:34:42,268 - exploit_routes - ERROR - [exploit_routes.py:98] - Erreur lors de la récupération des rapports: 'report' is undefined
Traceback (most recent call last):
  File "/home/oebn/Projet-Scan/routes/exploit_routes.py", line 96, in list_reports
    # Debugger le contenu de 'reports' pour s'assurer qu'il est bien formaté
           ^^^^^^^^^^^^^^^^^^^^^^^^^^^^^^^^^^^^^^^^^^^^^^^^^^^^^^^^
  File "/usr/local/lib/python3.11/dist-packages/flask/templating.py", line 150, in render_template
    return _render(app, template, context)
           ^^^^^^^^^^^^^^^^^^^^^^^^^^^^^^^
  File "/usr/local/lib/python3.11/dist-packages/flask/templating.py", line 131, in _render
    rv = template.render(context)
         ^^^^^^^^^^^^^^^^^^^^^^^^
  File "/usr/local/lib/python3.11/dist-packages/jinja2/environment.py", line 1295, in render
    self.environment.handle_exception()
  File "/usr/local/lib/python3.11/dist-packages/jinja2/environment.py", line 942, in handle_exception
    raise rewrite_traceback_stack(source=source)
  File "/home/oebn/Projet-Scan/templates/exploit_reports.html", line 64, in top-level template code
    </tr>
  File "/usr/local/lib/python3.11/dist-packages/jinja2/environment.py", line 490, in getattr
    return getattr(obj, attribute)
           ^^^^^^^^^^^^^^^^^^^^^^^
jinja2.exceptions.UndefinedError: 'report' is undefined
2025-05-09 11:34:42,500 - exploit_routes - ERROR - [exploit_routes.py:98] - Erreur lors de la récupération des rapports: 'report' is undefined
Traceback (most recent call last):
  File "/home/oebn/Projet-Scan/routes/exploit_routes.py", line 96, in list_reports
    # Debugger le contenu de 'reports' pour s'assurer qu'il est bien formaté
           ^^^^^^^^^^^^^^^^^^^^^^^^^^^^^^^^^^^^^^^^^^^^^^^^^^^^^^^^
  File "/usr/local/lib/python3.11/dist-packages/flask/templating.py", line 150, in render_template
    return _render(app, template, context)
           ^^^^^^^^^^^^^^^^^^^^^^^^^^^^^^^
  File "/usr/local/lib/python3.11/dist-packages/flask/templating.py", line 131, in _render
    rv = template.render(context)
         ^^^^^^^^^^^^^^^^^^^^^^^^
  File "/usr/local/lib/python3.11/dist-packages/jinja2/environment.py", line 1295, in render
    self.environment.handle_exception()
  File "/usr/local/lib/python3.11/dist-packages/jinja2/environment.py", line 942, in handle_exception
    raise rewrite_traceback_stack(source=source)
  File "/home/oebn/Projet-Scan/templates/exploit_reports.html", line 64, in top-level template code
    </tr>
  File "/usr/local/lib/python3.11/dist-packages/jinja2/environment.py", line 490, in getattr
    return getattr(obj, attribute)
           ^^^^^^^^^^^^^^^^^^^^^^^
jinja2.exceptions.UndefinedError: 'report' is undefined
2025-05-09 11:34:42,685 - exploit_routes - ERROR - [exploit_routes.py:98] - Erreur lors de la récupération des rapports: 'report' is undefined
Traceback (most recent call last):
  File "/home/oebn/Projet-Scan/routes/exploit_routes.py", line 96, in list_reports
    # Debugger le contenu de 'reports' pour s'assurer qu'il est bien formaté
           ^^^^^^^^^^^^^^^^^^^^^^^^^^^^^^^^^^^^^^^^^^^^^^^^^^^^^^^^
  File "/usr/local/lib/python3.11/dist-packages/flask/templating.py", line 150, in render_template
    return _render(app, template, context)
           ^^^^^^^^^^^^^^^^^^^^^^^^^^^^^^^
  File "/usr/local/lib/python3.11/dist-packages/flask/templating.py", line 131, in _render
    rv = template.render(context)
         ^^^^^^^^^^^^^^^^^^^^^^^^
  File "/usr/local/lib/python3.11/dist-packages/jinja2/environment.py", line 1295, in render
    self.environment.handle_exception()
  File "/usr/local/lib/python3.11/dist-packages/jinja2/environment.py", line 942, in handle_exception
    raise rewrite_traceback_stack(source=source)
  File "/home/oebn/Projet-Scan/templates/exploit_reports.html", line 64, in top-level template code
    </tr>
  File "/usr/local/lib/python3.11/dist-packages/jinja2/environment.py", line 490, in getattr
    return getattr(obj, attribute)
           ^^^^^^^^^^^^^^^^^^^^^^^
jinja2.exceptions.UndefinedError: 'report' is undefined
2025-05-09 11:34:42,885 - exploit_routes - ERROR - [exploit_routes.py:98] - Erreur lors de la récupération des rapports: 'report' is undefined
Traceback (most recent call last):
  File "/home/oebn/Projet-Scan/routes/exploit_routes.py", line 96, in list_reports
    # Debugger le contenu de 'reports' pour s'assurer qu'il est bien formaté
           ^^^^^^^^^^^^^^^^^^^^^^^^^^^^^^^^^^^^^^^^^^^^^^^^^^^^^^^^
  File "/usr/local/lib/python3.11/dist-packages/flask/templating.py", line 150, in render_template
    return _render(app, template, context)
           ^^^^^^^^^^^^^^^^^^^^^^^^^^^^^^^
  File "/usr/local/lib/python3.11/dist-packages/flask/templating.py", line 131, in _render
    rv = template.render(context)
         ^^^^^^^^^^^^^^^^^^^^^^^^
  File "/usr/local/lib/python3.11/dist-packages/jinja2/environment.py", line 1295, in render
    self.environment.handle_exception()
  File "/usr/local/lib/python3.11/dist-packages/jinja2/environment.py", line 942, in handle_exception
    raise rewrite_traceback_stack(source=source)
  File "/home/oebn/Projet-Scan/templates/exploit_reports.html", line 64, in top-level template code
    </tr>
  File "/usr/local/lib/python3.11/dist-packages/jinja2/environment.py", line 490, in getattr
    return getattr(obj, attribute)
           ^^^^^^^^^^^^^^^^^^^^^^^
jinja2.exceptions.UndefinedError: 'report' is undefined
2025-05-09 11:34:43,383 - exploit_routes - ERROR - [exploit_routes.py:98] - Erreur lors de la récupération des rapports: 'report' is undefined
Traceback (most recent call last):
  File "/home/oebn/Projet-Scan/routes/exploit_routes.py", line 96, in list_reports
    # Debugger le contenu de 'reports' pour s'assurer qu'il est bien formaté
           ^^^^^^^^^^^^^^^^^^^^^^^^^^^^^^^^^^^^^^^^^^^^^^^^^^^^^^^^
  File "/usr/local/lib/python3.11/dist-packages/flask/templating.py", line 150, in render_template
    return _render(app, template, context)
           ^^^^^^^^^^^^^^^^^^^^^^^^^^^^^^^
  File "/usr/local/lib/python3.11/dist-packages/flask/templating.py", line 131, in _render
    rv = template.render(context)
         ^^^^^^^^^^^^^^^^^^^^^^^^
  File "/usr/local/lib/python3.11/dist-packages/jinja2/environment.py", line 1295, in render
    self.environment.handle_exception()
  File "/usr/local/lib/python3.11/dist-packages/jinja2/environment.py", line 942, in handle_exception
    raise rewrite_traceback_stack(source=source)
  File "/home/oebn/Projet-Scan/templates/exploit_reports.html", line 64, in top-level template code
    </tr>
  File "/usr/local/lib/python3.11/dist-packages/jinja2/environment.py", line 490, in getattr
    return getattr(obj, attribute)
           ^^^^^^^^^^^^^^^^^^^^^^^
jinja2.exceptions.UndefinedError: 'report' is undefined
2025-05-09 11:34:43,552 - exploit_routes - ERROR - [exploit_routes.py:98] - Erreur lors de la récupération des rapports: 'report' is undefined
Traceback (most recent call last):
  File "/home/oebn/Projet-Scan/routes/exploit_routes.py", line 96, in list_reports
    # Debugger le contenu de 'reports' pour s'assurer qu'il est bien formaté
           ^^^^^^^^^^^^^^^^^^^^^^^^^^^^^^^^^^^^^^^^^^^^^^^^^^^^^^^^
  File "/usr/local/lib/python3.11/dist-packages/flask/templating.py", line 150, in render_template
    return _render(app, template, context)
           ^^^^^^^^^^^^^^^^^^^^^^^^^^^^^^^
  File "/usr/local/lib/python3.11/dist-packages/flask/templating.py", line 131, in _render
    rv = template.render(context)
         ^^^^^^^^^^^^^^^^^^^^^^^^
  File "/usr/local/lib/python3.11/dist-packages/jinja2/environment.py", line 1295, in render
    self.environment.handle_exception()
  File "/usr/local/lib/python3.11/dist-packages/jinja2/environment.py", line 942, in handle_exception
    raise rewrite_traceback_stack(source=source)
  File "/home/oebn/Projet-Scan/templates/exploit_reports.html", line 64, in top-level template code
    </tr>
  File "/usr/local/lib/python3.11/dist-packages/jinja2/environment.py", line 490, in getattr
    return getattr(obj, attribute)
           ^^^^^^^^^^^^^^^^^^^^^^^
jinja2.exceptions.UndefinedError: 'report' is undefined
2025-05-09 11:34:43,726 - exploit_routes - ERROR - [exploit_routes.py:98] - Erreur lors de la récupération des rapports: 'report' is undefined
Traceback (most recent call last):
  File "/home/oebn/Projet-Scan/routes/exploit_routes.py", line 96, in list_reports
    # Debugger le contenu de 'reports' pour s'assurer qu'il est bien formaté
           ^^^^^^^^^^^^^^^^^^^^^^^^^^^^^^^^^^^^^^^^^^^^^^^^^^^^^^^^
  File "/usr/local/lib/python3.11/dist-packages/flask/templating.py", line 150, in render_template
    return _render(app, template, context)
           ^^^^^^^^^^^^^^^^^^^^^^^^^^^^^^^
  File "/usr/local/lib/python3.11/dist-packages/flask/templating.py", line 131, in _render
    rv = template.render(context)
         ^^^^^^^^^^^^^^^^^^^^^^^^
  File "/usr/local/lib/python3.11/dist-packages/jinja2/environment.py", line 1295, in render
    self.environment.handle_exception()
  File "/usr/local/lib/python3.11/dist-packages/jinja2/environment.py", line 942, in handle_exception
    raise rewrite_traceback_stack(source=source)
  File "/home/oebn/Projet-Scan/templates/exploit_reports.html", line 64, in top-level template code
    </tr>
  File "/usr/local/lib/python3.11/dist-packages/jinja2/environment.py", line 490, in getattr
    return getattr(obj, attribute)
           ^^^^^^^^^^^^^^^^^^^^^^^
jinja2.exceptions.UndefinedError: 'report' is undefined
2025-05-15 21:32:38,265 - exploit_routes - ERROR - [exploit_routes.py:58] - Metasploit n'est pas disponible sur le système. Veuillez installer Metasploit pour utiliser cette fonctionnalité.
2025-05-17 18:02:55,774 - exploit_routes - ERROR - [exploit_routes.py:58] - Metasploit n'est pas disponible sur le système. Veuillez installer Metasploit pour utiliser cette fonctionnalité.
2025-05-17 18:03:09,055 - exploit_routes - ERROR - [exploit_routes.py:58] - Metasploit n'est pas disponible sur le système. Veuillez installer Metasploit pour utiliser cette fonctionnalité.
2025-05-17 18:18:57,914 - exploit_routes - ERROR - [exploit_routes.py:130] - Erreur lors de la récupération du rapport: exploit_report.html
Traceback (most recent call last):
  File "/home/oebn/Projet-Scan/routes/exploit_routes.py", line 128, in get_report
    return render_template("exploit_report.html", report=report, filename=filename)
           ^^^^^^^^^^^^^^^^^^^^^^^^^^^^^^^^^^^^^^^^^^^^^^^^^^^^^^^^^^^^^^^^^^^^^^^^
  File "/home/oebn/Projet-Scan/venv/lib/python3.11/site-packages/flask/templating.py", line 149, in render_template
    template = app.jinja_env.get_or_select_template(template_name_or_list)
               ^^^^^^^^^^^^^^^^^^^^^^^^^^^^^^^^^^^^^^^^^^^^^^^^^^^^^^^^^^^
  File "/home/oebn/Projet-Scan/venv/lib/python3.11/site-packages/jinja2/environment.py", line 1087, in get_or_select_template
    return self.get_template(template_name_or_list, parent, globals)
           ^^^^^^^^^^^^^^^^^^^^^^^^^^^^^^^^^^^^^^^^^^^^^^^^^^^^^^^^^
  File "/home/oebn/Projet-Scan/venv/lib/python3.11/site-packages/jinja2/environment.py", line 1016, in get_template
    return self._load_template(name, globals)
           ^^^^^^^^^^^^^^^^^^^^^^^^^^^^^^^^^^
  File "/home/oebn/Projet-Scan/venv/lib/python3.11/site-packages/jinja2/environment.py", line 975, in _load_template
    template = self.loader.load(self, name, self.make_globals(globals))
               ^^^^^^^^^^^^^^^^^^^^^^^^^^^^^^^^^^^^^^^^^^^^^^^^^^^^^^^^
  File "/home/oebn/Projet-Scan/venv/lib/python3.11/site-packages/jinja2/loaders.py", line 126, in load
    source, filename, uptodate = self.get_source(environment, name)
                                 ^^^^^^^^^^^^^^^^^^^^^^^^^^^^^^^^^^
  File "/home/oebn/Projet-Scan/venv/lib/python3.11/site-packages/flask/templating.py", line 65, in get_source
    return self._get_source_fast(environment, template)
           ^^^^^^^^^^^^^^^^^^^^^^^^^^^^^^^^^^^^^^^^^^^^
  File "/home/oebn/Projet-Scan/venv/lib/python3.11/site-packages/flask/templating.py", line 99, in _get_source_fast
    raise TemplateNotFound(template)
jinja2.exceptions.TemplateNotFound: exploit_report.html
2025-05-17 18:19:11,234 - exploit_routes - ERROR - [exploit_routes.py:130] - Erreur lors de la récupération du rapport: exploit_report.html
Traceback (most recent call last):
  File "/home/oebn/Projet-Scan/routes/exploit_routes.py", line 128, in get_report
    return render_template("exploit_report.html", report=report, filename=filename)
           ^^^^^^^^^^^^^^^^^^^^^^^^^^^^^^^^^^^^^^^^^^^^^^^^^^^^^^^^^^^^^^^^^^^^^^^^
  File "/home/oebn/Projet-Scan/venv/lib/python3.11/site-packages/flask/templating.py", line 149, in render_template
    template = app.jinja_env.get_or_select_template(template_name_or_list)
               ^^^^^^^^^^^^^^^^^^^^^^^^^^^^^^^^^^^^^^^^^^^^^^^^^^^^^^^^^^^
  File "/home/oebn/Projet-Scan/venv/lib/python3.11/site-packages/jinja2/environment.py", line 1087, in get_or_select_template
    return self.get_template(template_name_or_list, parent, globals)
           ^^^^^^^^^^^^^^^^^^^^^^^^^^^^^^^^^^^^^^^^^^^^^^^^^^^^^^^^^
  File "/home/oebn/Projet-Scan/venv/lib/python3.11/site-packages/jinja2/environment.py", line 1016, in get_template
    return self._load_template(name, globals)
           ^^^^^^^^^^^^^^^^^^^^^^^^^^^^^^^^^^
  File "/home/oebn/Projet-Scan/venv/lib/python3.11/site-packages/jinja2/environment.py", line 975, in _load_template
    template = self.loader.load(self, name, self.make_globals(globals))
               ^^^^^^^^^^^^^^^^^^^^^^^^^^^^^^^^^^^^^^^^^^^^^^^^^^^^^^^^
  File "/home/oebn/Projet-Scan/venv/lib/python3.11/site-packages/jinja2/loaders.py", line 126, in load
    source, filename, uptodate = self.get_source(environment, name)
                                 ^^^^^^^^^^^^^^^^^^^^^^^^^^^^^^^^^^
  File "/home/oebn/Projet-Scan/venv/lib/python3.11/site-packages/flask/templating.py", line 65, in get_source
    return self._get_source_fast(environment, template)
           ^^^^^^^^^^^^^^^^^^^^^^^^^^^^^^^^^^^^^^^^^^^^
  File "/home/oebn/Projet-Scan/venv/lib/python3.11/site-packages/flask/templating.py", line 99, in _get_source_fast
    raise TemplateNotFound(template)
jinja2.exceptions.TemplateNotFound: exploit_report.html
2025-05-17 18:19:16,155 - exploit_routes - ERROR - [exploit_routes.py:130] - Erreur lors de la récupération du rapport: exploit_report.html
Traceback (most recent call last):
  File "/home/oebn/Projet-Scan/routes/exploit_routes.py", line 128, in get_report
    return render_template("exploit_report.html", report=report, filename=filename)
           ^^^^^^^^^^^^^^^^^^^^^^^^^^^^^^^^^^^^^^^^^^^^^^^^^^^^^^^^^^^^^^^^^^^^^^^^
  File "/home/oebn/Projet-Scan/venv/lib/python3.11/site-packages/flask/templating.py", line 149, in render_template
    template = app.jinja_env.get_or_select_template(template_name_or_list)
               ^^^^^^^^^^^^^^^^^^^^^^^^^^^^^^^^^^^^^^^^^^^^^^^^^^^^^^^^^^^
  File "/home/oebn/Projet-Scan/venv/lib/python3.11/site-packages/jinja2/environment.py", line 1087, in get_or_select_template
    return self.get_template(template_name_or_list, parent, globals)
           ^^^^^^^^^^^^^^^^^^^^^^^^^^^^^^^^^^^^^^^^^^^^^^^^^^^^^^^^^
  File "/home/oebn/Projet-Scan/venv/lib/python3.11/site-packages/jinja2/environment.py", line 1016, in get_template
    return self._load_template(name, globals)
           ^^^^^^^^^^^^^^^^^^^^^^^^^^^^^^^^^^
  File "/home/oebn/Projet-Scan/venv/lib/python3.11/site-packages/jinja2/environment.py", line 975, in _load_template
    template = self.loader.load(self, name, self.make_globals(globals))
               ^^^^^^^^^^^^^^^^^^^^^^^^^^^^^^^^^^^^^^^^^^^^^^^^^^^^^^^^
  File "/home/oebn/Projet-Scan/venv/lib/python3.11/site-packages/jinja2/loaders.py", line 126, in load
    source, filename, uptodate = self.get_source(environment, name)
                                 ^^^^^^^^^^^^^^^^^^^^^^^^^^^^^^^^^^
  File "/home/oebn/Projet-Scan/venv/lib/python3.11/site-packages/flask/templating.py", line 65, in get_source
    return self._get_source_fast(environment, template)
           ^^^^^^^^^^^^^^^^^^^^^^^^^^^^^^^^^^^^^^^^^^^^
  File "/home/oebn/Projet-Scan/venv/lib/python3.11/site-packages/flask/templating.py", line 99, in _get_source_fast
    raise TemplateNotFound(template)
jinja2.exceptions.TemplateNotFound: exploit_report.html
2025-05-17 18:21:43,836 - exploit_routes - ERROR - [exploit_routes.py:130] - Erreur lors de la récupération du rapport: exploit_report.html
Traceback (most recent call last):
  File "/home/oebn/Projet-Scan/routes/exploit_routes.py", line 128, in get_report
    return render_template("exploit_report.html", report=report, filename=filename)
           ^^^^^^^^^^^^^^^^^^^^^^^^^^^^^^^^^^^^^^^^^^^^^^^^^^^^^^^^^^^^^^^^^^^^^^^^
  File "/home/oebn/Projet-Scan/venv/lib/python3.11/site-packages/flask/templating.py", line 149, in render_template
    template = app.jinja_env.get_or_select_template(template_name_or_list)
               ^^^^^^^^^^^^^^^^^^^^^^^^^^^^^^^^^^^^^^^^^^^^^^^^^^^^^^^^^^^
  File "/home/oebn/Projet-Scan/venv/lib/python3.11/site-packages/jinja2/environment.py", line 1087, in get_or_select_template
    return self.get_template(template_name_or_list, parent, globals)
           ^^^^^^^^^^^^^^^^^^^^^^^^^^^^^^^^^^^^^^^^^^^^^^^^^^^^^^^^^
  File "/home/oebn/Projet-Scan/venv/lib/python3.11/site-packages/jinja2/environment.py", line 1016, in get_template
    return self._load_template(name, globals)
           ^^^^^^^^^^^^^^^^^^^^^^^^^^^^^^^^^^
  File "/home/oebn/Projet-Scan/venv/lib/python3.11/site-packages/jinja2/environment.py", line 975, in _load_template
    template = self.loader.load(self, name, self.make_globals(globals))
               ^^^^^^^^^^^^^^^^^^^^^^^^^^^^^^^^^^^^^^^^^^^^^^^^^^^^^^^^
  File "/home/oebn/Projet-Scan/venv/lib/python3.11/site-packages/jinja2/loaders.py", line 126, in load
    source, filename, uptodate = self.get_source(environment, name)
                                 ^^^^^^^^^^^^^^^^^^^^^^^^^^^^^^^^^^
  File "/home/oebn/Projet-Scan/venv/lib/python3.11/site-packages/flask/templating.py", line 65, in get_source
    return self._get_source_fast(environment, template)
           ^^^^^^^^^^^^^^^^^^^^^^^^^^^^^^^^^^^^^^^^^^^^
  File "/home/oebn/Projet-Scan/venv/lib/python3.11/site-packages/flask/templating.py", line 99, in _get_source_fast
    raise TemplateNotFound(template)
jinja2.exceptions.TemplateNotFound: exploit_report.html
2025-05-17 18:21:54,739 - exploit_routes - ERROR - [exploit_routes.py:130] - Erreur lors de la récupération du rapport: exploit_report.html
Traceback (most recent call last):
  File "/home/oebn/Projet-Scan/routes/exploit_routes.py", line 128, in get_report
    return render_template("exploit_report.html", report=report, filename=filename)
           ^^^^^^^^^^^^^^^^^^^^^^^^^^^^^^^^^^^^^^^^^^^^^^^^^^^^^^^^^^^^^^^^^^^^^^^^
  File "/home/oebn/Projet-Scan/venv/lib/python3.11/site-packages/flask/templating.py", line 149, in render_template
    template = app.jinja_env.get_or_select_template(template_name_or_list)
               ^^^^^^^^^^^^^^^^^^^^^^^^^^^^^^^^^^^^^^^^^^^^^^^^^^^^^^^^^^^
  File "/home/oebn/Projet-Scan/venv/lib/python3.11/site-packages/jinja2/environment.py", line 1087, in get_or_select_template
    return self.get_template(template_name_or_list, parent, globals)
           ^^^^^^^^^^^^^^^^^^^^^^^^^^^^^^^^^^^^^^^^^^^^^^^^^^^^^^^^^
  File "/home/oebn/Projet-Scan/venv/lib/python3.11/site-packages/jinja2/environment.py", line 1016, in get_template
    return self._load_template(name, globals)
           ^^^^^^^^^^^^^^^^^^^^^^^^^^^^^^^^^^
  File "/home/oebn/Projet-Scan/venv/lib/python3.11/site-packages/jinja2/environment.py", line 975, in _load_template
    template = self.loader.load(self, name, self.make_globals(globals))
               ^^^^^^^^^^^^^^^^^^^^^^^^^^^^^^^^^^^^^^^^^^^^^^^^^^^^^^^^
  File "/home/oebn/Projet-Scan/venv/lib/python3.11/site-packages/jinja2/loaders.py", line 126, in load
    source, filename, uptodate = self.get_source(environment, name)
                                 ^^^^^^^^^^^^^^^^^^^^^^^^^^^^^^^^^^
  File "/home/oebn/Projet-Scan/venv/lib/python3.11/site-packages/flask/templating.py", line 65, in get_source
    return self._get_source_fast(environment, template)
           ^^^^^^^^^^^^^^^^^^^^^^^^^^^^^^^^^^^^^^^^^^^^
  File "/home/oebn/Projet-Scan/venv/lib/python3.11/site-packages/flask/templating.py", line 99, in _get_source_fast
    raise TemplateNotFound(template)
jinja2.exceptions.TemplateNotFound: exploit_report.html
2025-05-17 18:22:06,150 - exploit_routes - ERROR - [exploit_routes.py:130] - Erreur lors de la récupération du rapport: exploit_report.html
Traceback (most recent call last):
  File "/home/oebn/Projet-Scan/routes/exploit_routes.py", line 128, in get_report
    return render_template("exploit_report.html", report=report, filename=filename)
           ^^^^^^^^^^^^^^^^^^^^^^^^^^^^^^^^^^^^^^^^^^^^^^^^^^^^^^^^^^^^^^^^^^^^^^^^
  File "/home/oebn/Projet-Scan/venv/lib/python3.11/site-packages/flask/templating.py", line 149, in render_template
    template = app.jinja_env.get_or_select_template(template_name_or_list)
               ^^^^^^^^^^^^^^^^^^^^^^^^^^^^^^^^^^^^^^^^^^^^^^^^^^^^^^^^^^^
  File "/home/oebn/Projet-Scan/venv/lib/python3.11/site-packages/jinja2/environment.py", line 1087, in get_or_select_template
    return self.get_template(template_name_or_list, parent, globals)
           ^^^^^^^^^^^^^^^^^^^^^^^^^^^^^^^^^^^^^^^^^^^^^^^^^^^^^^^^^
  File "/home/oebn/Projet-Scan/venv/lib/python3.11/site-packages/jinja2/environment.py", line 1016, in get_template
    return self._load_template(name, globals)
           ^^^^^^^^^^^^^^^^^^^^^^^^^^^^^^^^^^
  File "/home/oebn/Projet-Scan/venv/lib/python3.11/site-packages/jinja2/environment.py", line 975, in _load_template
    template = self.loader.load(self, name, self.make_globals(globals))
               ^^^^^^^^^^^^^^^^^^^^^^^^^^^^^^^^^^^^^^^^^^^^^^^^^^^^^^^^
  File "/home/oebn/Projet-Scan/venv/lib/python3.11/site-packages/jinja2/loaders.py", line 126, in load
    source, filename, uptodate = self.get_source(environment, name)
                                 ^^^^^^^^^^^^^^^^^^^^^^^^^^^^^^^^^^
  File "/home/oebn/Projet-Scan/venv/lib/python3.11/site-packages/flask/templating.py", line 65, in get_source
    return self._get_source_fast(environment, template)
           ^^^^^^^^^^^^^^^^^^^^^^^^^^^^^^^^^^^^^^^^^^^^
  File "/home/oebn/Projet-Scan/venv/lib/python3.11/site-packages/flask/templating.py", line 99, in _get_source_fast
    raise TemplateNotFound(template)
jinja2.exceptions.TemplateNotFound: exploit_report.html
2025-05-17 18:29:35,858 - exploit_routes - ERROR - [exploit_routes.py:130] - Erreur lors de la récupération du rapport: Could not build url for endpoint 'exploit_routes.exploit_reports'. Did you mean 'exploit.list_reports' instead?
Traceback (most recent call last):
  File "/home/oebn/Projet-Scan/routes/exploit_routes.py", line 128, in get_report
    return render_template("exploit_report.html", report=report, filename=filename)
           ^^^^^^^^^^^^^^^^^^^^^^^^^^^^^^^^^^^^^^^^^^^^^^^^^^^^^^^^^^^^^^^^^^^^^^^^
  File "/home/oebn/Projet-Scan/venv/lib/python3.11/site-packages/flask/templating.py", line 150, in render_template
    return _render(app, template, context)
           ^^^^^^^^^^^^^^^^^^^^^^^^^^^^^^^
  File "/home/oebn/Projet-Scan/venv/lib/python3.11/site-packages/flask/templating.py", line 131, in _render
    rv = template.render(context)
         ^^^^^^^^^^^^^^^^^^^^^^^^
  File "/home/oebn/Projet-Scan/venv/lib/python3.11/site-packages/jinja2/environment.py", line 1295, in render
    self.environment.handle_exception()
  File "/home/oebn/Projet-Scan/venv/lib/python3.11/site-packages/jinja2/environment.py", line 942, in handle_exception
    raise rewrite_traceback_stack(source=source)
  File "/home/oebn/Projet-Scan/templates/exploit_report.html", line 1, in top-level template code
    {% extends "base.html" %}
  File "/home/oebn/Projet-Scan/templates/base.html", line 66, in top-level template code
    {% block content %}
  File "/home/oebn/Projet-Scan/templates/exploit_report.html", line 19, in block 'content'
    <a href="{{ url_for('exploit_routes.exploit_reports') }}" class="btn btn-secondary">Retour aux Rapports</a>
    ^^^^^^^^^^^^^^^^^^^^^^^^^
  File "/home/oebn/Projet-Scan/venv/lib/python3.11/site-packages/flask/app.py", line 1121, in url_for
    return self.handle_url_build_error(error, endpoint, values)
           ^^^^^^^^^^^^^^^^^^^^^^^^^^^^^^^^^^^^^^^^^^^^^^^^^^^^
  File "/home/oebn/Projet-Scan/venv/lib/python3.11/site-packages/flask/app.py", line 1110, in url_for
    rv = url_adapter.build(  # type: ignore[union-attr]
         ^^^^^^^^^^^^^^^^^^^^^^^^^^^^^^^^^^^^^^^^^^^^^^
  File "/home/oebn/Projet-Scan/venv/lib/python3.11/site-packages/werkzeug/routing/map.py", line 924, in build
    raise BuildError(endpoint, values, method, self)
werkzeug.routing.exceptions.BuildError: Could not build url for endpoint 'exploit_routes.exploit_reports'. Did you mean 'exploit.list_reports' instead?
2025-05-17 18:29:45,293 - exploit_routes - ERROR - [exploit_routes.py:130] - Erreur lors de la récupération du rapport: Could not build url for endpoint 'exploit_routes.exploit_reports'. Did you mean 'exploit.list_reports' instead?
Traceback (most recent call last):
  File "/home/oebn/Projet-Scan/routes/exploit_routes.py", line 128, in get_report
    return render_template("exploit_report.html", report=report, filename=filename)
           ^^^^^^^^^^^^^^^^^^^^^^^^^^^^^^^^^^^^^^^^^^^^^^^^^^^^^^^^^^^^^^^^^^^^^^^^
  File "/home/oebn/Projet-Scan/venv/lib/python3.11/site-packages/flask/templating.py", line 150, in render_template
    return _render(app, template, context)
           ^^^^^^^^^^^^^^^^^^^^^^^^^^^^^^^
  File "/home/oebn/Projet-Scan/venv/lib/python3.11/site-packages/flask/templating.py", line 131, in _render
    rv = template.render(context)
         ^^^^^^^^^^^^^^^^^^^^^^^^
  File "/home/oebn/Projet-Scan/venv/lib/python3.11/site-packages/jinja2/environment.py", line 1295, in render
    self.environment.handle_exception()
  File "/home/oebn/Projet-Scan/venv/lib/python3.11/site-packages/jinja2/environment.py", line 942, in handle_exception
    raise rewrite_traceback_stack(source=source)
  File "/home/oebn/Projet-Scan/templates/exploit_report.html", line 1, in top-level template code
    {% extends "base.html" %}
  File "/home/oebn/Projet-Scan/templates/base.html", line 66, in top-level template code
    {% block content %}
  File "/home/oebn/Projet-Scan/templates/exploit_report.html", line 19, in block 'content'
    <a href="{{ url_for('exploit_routes.exploit_reports') }}" class="btn btn-secondary">Retour aux Rapports</a>
    ^^^^^^^^^^^^^^^^^^^^^^^^^
  File "/home/oebn/Projet-Scan/venv/lib/python3.11/site-packages/flask/app.py", line 1121, in url_for
    return self.handle_url_build_error(error, endpoint, values)
           ^^^^^^^^^^^^^^^^^^^^^^^^^^^^^^^^^^^^^^^^^^^^^^^^^^^^
  File "/home/oebn/Projet-Scan/venv/lib/python3.11/site-packages/flask/app.py", line 1110, in url_for
    rv = url_adapter.build(  # type: ignore[union-attr]
         ^^^^^^^^^^^^^^^^^^^^^^^^^^^^^^^^^^^^^^^^^^^^^^
  File "/home/oebn/Projet-Scan/venv/lib/python3.11/site-packages/werkzeug/routing/map.py", line 924, in build
    raise BuildError(endpoint, values, method, self)
werkzeug.routing.exceptions.BuildError: Could not build url for endpoint 'exploit_routes.exploit_reports'. Did you mean 'exploit.list_reports' instead?
2025-05-17 18:29:48,212 - exploit_routes - ERROR - [exploit_routes.py:130] - Erreur lors de la récupération du rapport: Could not build url for endpoint 'exploit_routes.exploit_reports'. Did you mean 'exploit.list_reports' instead?
Traceback (most recent call last):
  File "/home/oebn/Projet-Scan/routes/exploit_routes.py", line 128, in get_report
    return render_template("exploit_report.html", report=report, filename=filename)
           ^^^^^^^^^^^^^^^^^^^^^^^^^^^^^^^^^^^^^^^^^^^^^^^^^^^^^^^^^^^^^^^^^^^^^^^^
  File "/home/oebn/Projet-Scan/venv/lib/python3.11/site-packages/flask/templating.py", line 150, in render_template
    return _render(app, template, context)
           ^^^^^^^^^^^^^^^^^^^^^^^^^^^^^^^
  File "/home/oebn/Projet-Scan/venv/lib/python3.11/site-packages/flask/templating.py", line 131, in _render
    rv = template.render(context)
         ^^^^^^^^^^^^^^^^^^^^^^^^
  File "/home/oebn/Projet-Scan/venv/lib/python3.11/site-packages/jinja2/environment.py", line 1295, in render
    self.environment.handle_exception()
  File "/home/oebn/Projet-Scan/venv/lib/python3.11/site-packages/jinja2/environment.py", line 942, in handle_exception
    raise rewrite_traceback_stack(source=source)
  File "/home/oebn/Projet-Scan/templates/exploit_report.html", line 1, in top-level template code
    {% extends "base.html" %}
  File "/home/oebn/Projet-Scan/templates/base.html", line 66, in top-level template code
    {% block content %}
  File "/home/oebn/Projet-Scan/templates/exploit_report.html", line 19, in block 'content'
    <a href="{{ url_for('exploit_routes.exploit_reports') }}" class="btn btn-secondary">Retour aux Rapports</a>
    ^^^^^^^^^^^^^^^^^^^^^^^^^
  File "/home/oebn/Projet-Scan/venv/lib/python3.11/site-packages/flask/app.py", line 1121, in url_for
    return self.handle_url_build_error(error, endpoint, values)
           ^^^^^^^^^^^^^^^^^^^^^^^^^^^^^^^^^^^^^^^^^^^^^^^^^^^^
  File "/home/oebn/Projet-Scan/venv/lib/python3.11/site-packages/flask/app.py", line 1110, in url_for
    rv = url_adapter.build(  # type: ignore[union-attr]
         ^^^^^^^^^^^^^^^^^^^^^^^^^^^^^^^^^^^^^^^^^^^^^^
  File "/home/oebn/Projet-Scan/venv/lib/python3.11/site-packages/werkzeug/routing/map.py", line 924, in build
    raise BuildError(endpoint, values, method, self)
werkzeug.routing.exceptions.BuildError: Could not build url for endpoint 'exploit_routes.exploit_reports'. Did you mean 'exploit.list_reports' instead?
2025-05-17 18:44:42,292 - exploit_routes - ERROR - [exploit_routes.py:137] - Erreur lors de la récupération du rapport: 'now' is undefined
Traceback (most recent call last):
  File "/home/oebn/Projet-Scan/routes/exploit_routes.py", line 132, in get_report
    return render_template("exploit_report.html",
          ^^^^^^^^^^^^^^^^^^^^^^^^^^^^^^^^^^^^^^^
  File "/home/oebn/Projet-Scan/venv/lib/python3.11/site-packages/flask/templating.py", line 150, in render_template
    return _render(app, template, context)
           ^^^^^^^^^^^^^^^^^^^^^^^^^^^^^^^
  File "/home/oebn/Projet-Scan/venv/lib/python3.11/site-packages/flask/templating.py", line 131, in _render
    rv = template.render(context)
         ^^^^^^^^^^^^^^^^^^^^^^^^
  File "/home/oebn/Projet-Scan/venv/lib/python3.11/site-packages/jinja2/environment.py", line 1295, in render
    self.environment.handle_exception()
  File "/home/oebn/Projet-Scan/venv/lib/python3.11/site-packages/jinja2/environment.py", line 942, in handle_exception
    raise rewrite_traceback_stack(source=source)
  File "/home/oebn/Projet-Scan/templates/exploit_report.html", line 1, in top-level template code
    {% extends "base.html" %}
  File "/home/oebn/Projet-Scan/templates/base.html", line 66, in top-level template code
    {% block content %}
  File "/home/oebn/Projet-Scan/templates/exploit_report.html", line 6, in block 'content'
    <div class="timestamp">Généré le : {{ generated_on|default(now().strftime("%d/%m/%Y %H:%M:%S")) }}</div>
    ^^^^^^^^^^^^^^^^^^^^^^^^^
  File "/home/oebn/Projet-Scan/venv/lib/python3.11/site-packages/jinja2/utils.py", line 92, in from_obj
    if hasattr(obj, "jinja_pass_arg"):
       ^^^^^^^^^^^^^^^^^^^^^^^^^^^^^^
jinja2.exceptions.UndefinedError: 'now' is undefined
2025-05-17 18:44:46,608 - exploit_routes - ERROR - [exploit_routes.py:137] - Erreur lors de la récupération du rapport: 'now' is undefined
Traceback (most recent call last):
  File "/home/oebn/Projet-Scan/routes/exploit_routes.py", line 132, in get_report
    return render_template("exploit_report.html",
          ^^^^^^^^^^^^^^^^^^^^^^^^^^^^^^^^^^^^^^^
  File "/home/oebn/Projet-Scan/venv/lib/python3.11/site-packages/flask/templating.py", line 150, in render_template
    return _render(app, template, context)
           ^^^^^^^^^^^^^^^^^^^^^^^^^^^^^^^
  File "/home/oebn/Projet-Scan/venv/lib/python3.11/site-packages/flask/templating.py", line 131, in _render
    rv = template.render(context)
         ^^^^^^^^^^^^^^^^^^^^^^^^
  File "/home/oebn/Projet-Scan/venv/lib/python3.11/site-packages/jinja2/environment.py", line 1295, in render
    self.environment.handle_exception()
  File "/home/oebn/Projet-Scan/venv/lib/python3.11/site-packages/jinja2/environment.py", line 942, in handle_exception
    raise rewrite_traceback_stack(source=source)
  File "/home/oebn/Projet-Scan/templates/exploit_report.html", line 1, in top-level template code
    {% extends "base.html" %}
  File "/home/oebn/Projet-Scan/templates/base.html", line 66, in top-level template code
    {% block content %}
  File "/home/oebn/Projet-Scan/templates/exploit_report.html", line 6, in block 'content'
    <div class="timestamp">Généré le : {{ generated_on|default(now().strftime("%d/%m/%Y %H:%M:%S")) }}</div>
    ^^^^^^^^^^^^^^^^^^^^^^^^^
  File "/home/oebn/Projet-Scan/venv/lib/python3.11/site-packages/jinja2/utils.py", line 92, in from_obj
    if hasattr(obj, "jinja_pass_arg"):
       ^^^^^^^^^^^^^^^^^^^^^^^^^^^^^^
jinja2.exceptions.UndefinedError: 'now' is undefined
2025-05-17 18:47:25,049 - exploit_routes - ERROR - [exploit_routes.py:182] - Erreur lors de la génération du PDF: 'url_for' is undefined
Traceback (most recent call last):
  File "/home/oebn/Projet-Scan/routes/exploit_routes.py", line 174, in get_report_pdf
    pdf_path = generate_report("exploit", report_data, template_name="exploit_report.html", format="pdf")
               ^^^^^^^^^^^^^^^^^^^^^^^^^^^^^^^^^^^^^^^^^^^^^^^^^^^^^^^^^^^^^^^^^^^^^^^^^^^^^^^^^^^^^^^^^^
  File "/home/oebn/Projet-Scan/services/reporting_generator.py", line 64, in generate_report
    rendered = template.render(**data)
               ^^^^^^^^^^^^^^^^^^^^^^^
  File "/home/oebn/Projet-Scan/venv/lib/python3.11/site-packages/jinja2/environment.py", line 1295, in render
    self.environment.handle_exception()
  File "/home/oebn/Projet-Scan/venv/lib/python3.11/site-packages/jinja2/environment.py", line 942, in handle_exception
    raise rewrite_traceback_stack(source=source)
  File "templates/exploit_report.html", line 1, in top-level template code
    {% extends "base.html" %}
  File "templates/base.html", line 66, in top-level template code
    {% block content %}
  File "templates/exploit_report.html", line 154, in block 'content'
    <a href="{{ url_for('exploit.list_reports') }}" class="btn btn-secondary">
    ^^^^^^^^^^^^^^^^^^^^^^^^^
  File "/home/oebn/Projet-Scan/venv/lib/python3.11/site-packages/jinja2/utils.py", line 92, in from_obj
    if hasattr(obj, "jinja_pass_arg"):
       ^^^^^^^^^^^^^^^^^^^^^^^^^^^^^^
jinja2.exceptions.UndefinedError: 'url_for' is undefined
2025-05-17 18:54:27,784 - exploit_routes - ERROR - [exploit_routes.py:227] - Erreur lors de la génération du PDF: 'url_for' is undefined
Traceback (most recent call last):
  File "/home/oebn/Projet-Scan/routes/exploit_routes.py", line 219, in get_report_pdf
    pdf_path = generate_report("exploit", report_data, template_name="exploit_report.html", format="pdf")
               ^^^^^^^^^^^^^^^^^^^^^^^^^^^^^^^^^^^^^^^^^^^^^^^^^^^^^^^^^^^^^^^^^^^^^^^^^^^^^^^^^^^^^^^^^^
  File "/home/oebn/Projet-Scan/services/reporting_generator.py", line 64, in generate_report
    rendered = template.render(**data)
               ^^^^^^^^^^^^^^^^^^^^^^^
  File "/home/oebn/Projet-Scan/venv/lib/python3.11/site-packages/jinja2/environment.py", line 1295, in render
    self.environment.handle_exception()
  File "/home/oebn/Projet-Scan/venv/lib/python3.11/site-packages/jinja2/environment.py", line 942, in handle_exception
    raise rewrite_traceback_stack(source=source)
  File "templates/exploit_report.html", line 1, in top-level template code
    {% extends "base.html" %}
  File "templates/base.html", line 66, in top-level template code
    {% block content %}
  File "templates/exploit_report.html", line 154, in block 'content'
    <a href="{{ url_for('exploit.list_reports') }}" class="btn btn-secondary">
    ^^^^^^^^^^^^^^^^^^^^^^^^^
  File "/home/oebn/Projet-Scan/venv/lib/python3.11/site-packages/jinja2/utils.py", line 92, in from_obj
    if hasattr(obj, "jinja_pass_arg"):
       ^^^^^^^^^^^^^^^^^^^^^^^^^^^^^^
jinja2.exceptions.UndefinedError: 'url_for' is undefined
2025-05-17 18:54:45,015 - exploit_routes - ERROR - [exploit_routes.py:227] - Erreur lors de la génération du PDF: 'url_for' is undefined
Traceback (most recent call last):
  File "/home/oebn/Projet-Scan/routes/exploit_routes.py", line 219, in get_report_pdf
    pdf_path = generate_report("exploit", report_data, template_name="exploit_report.html", format="pdf")
               ^^^^^^^^^^^^^^^^^^^^^^^^^^^^^^^^^^^^^^^^^^^^^^^^^^^^^^^^^^^^^^^^^^^^^^^^^^^^^^^^^^^^^^^^^^
  File "/home/oebn/Projet-Scan/services/reporting_generator.py", line 64, in generate_report
    rendered = template.render(**data)
               ^^^^^^^^^^^^^^^^^^^^^^^
  File "/home/oebn/Projet-Scan/venv/lib/python3.11/site-packages/jinja2/environment.py", line 1295, in render
    self.environment.handle_exception()
  File "/home/oebn/Projet-Scan/venv/lib/python3.11/site-packages/jinja2/environment.py", line 942, in handle_exception
    raise rewrite_traceback_stack(source=source)
  File "templates/exploit_report.html", line 1, in top-level template code
    {% extends "base.html" %}
  File "templates/base.html", line 66, in top-level template code
    {% block content %}
  File "templates/exploit_report.html", line 154, in block 'content'
    <a href="{{ url_for('exploit.list_reports') }}" class="btn btn-secondary">
    ^^^^^^^^^^^^^^^^^^^^^^^^^
  File "/home/oebn/Projet-Scan/venv/lib/python3.11/site-packages/jinja2/utils.py", line 92, in from_obj
    if hasattr(obj, "jinja_pass_arg"):
       ^^^^^^^^^^^^^^^^^^^^^^^^^^^^^^
jinja2.exceptions.UndefinedError: 'url_for' is undefined
