2025-05-15 21:23:24,468 - reporting_generator - ERROR - [reporting_generator.py:86] - Erreur lors de la génération du rapport pdf: 'dict object' has no attribute 'file_size'
Traceback (most recent call last):
  File "/home/oebn/Projet-Scan/services/reporting_generator.py", line 64, in generate_report
    rendered = template.render(**data)
               ^^^^^^^^^^^^^^^^^^^^^^^
  File "/home/oebn/Projet-Scan/venv/lib/python3.11/site-packages/jinja2/environment.py", line 1295, in render
    self.environment.handle_exception()
  File "/home/oebn/Projet-Scan/venv/lib/python3.11/site-packages/jinja2/environment.py", line 942, in handle_exception
    raise rewrite_traceback_stack(source=source)
  File "templates/sniffer_report_template.html", line 42, in top-level template code
    <p><strong>Taille du fichier:</strong> {{ stats.file_size|filesizeformat }}</p>
    ^^^^^^^^^^^^^^^^^^^^^^^^^
  File "/home/oebn/Projet-Scan/venv/lib/python3.11/site-packages/jinja2/filters.py", line 710, in do_filesizeformat
    bytes = float(value)
            ^^^^^^^^^^^^
jinja2.exceptions.UndefinedError: 'dict object' has no attribute 'file_size'
2025-05-15 21:46:35,714 - reporting_generator - ERROR - [reporting_generator.py:86] - Erreur lors de la génération du rapport pdf: 'list object' has no attribute 'items'
Traceback (most recent call last):
  File "/home/oebn/Projet-Scan/services/reporting_generator.py", line 64, in generate_report
    rendered = template.render(**data)
               ^^^^^^^^^^^^^^^^^^^^^^^
  File "/home/oebn/Projet-Scan/venv/lib/python3.11/site-packages/jinja2/environment.py", line 1295, in render
    self.environment.handle_exception()
  File "/home/oebn/Projet-Scan/venv/lib/python3.11/site-packages/jinja2/environment.py", line 942, in handle_exception
    raise rewrite_traceback_stack(source=source)
  File "templates/sniffer_report_template.html", line 97, in top-level template code
    {% for protocol, count in stats.protocols.items() %}
    ^^^^^^^^^^^^^^^^^^^^^^^^^
  File "/home/oebn/Projet-Scan/venv/lib/python3.11/site-packages/jinja2/utils.py", line 92, in from_obj
    if hasattr(obj, "jinja_pass_arg"):
       ^^^^^^^^^^^^^^^^^^^^^^^^^^^^^^
jinja2.exceptions.UndefinedError: 'list object' has no attribute 'items'
